Workbook

Sheet For WH
A1: SKU | B1: ASIN | C1: FNSKU | D1: Item # | E1: Total EA (Transfer to WH06) | F1: Sellable Unit/Set/box to ship | G1: Box to pull | H1: Case to pull | I1: Sets per Box/Case | J1: Label | K1: Packing Instructions | L1: Supplies | M1: UoM | N1: BOX | O1: CASE | P1: Recommended Replenishment Qty | Q1: Current WH Inventory
D2: =VLOOKUP(Table1[[#This Row],[SKU]],Data1!A:B,2,0) -> #N/A | E2: =Table1[[#This Row],[UoM]]*Table1[[#This Row],[Recommended Replenishment Qty]] -> #N/A | F2: =Table1[[#This Row],[Total EA (Transfer to WH06)]]/Table1[[#This Row],[UoM]] -> #N/A | G2: =Table1[[#This Row],[Total EA (Transfer to WH06)]]/Table1[[#This Row],[BOX]] -> #N/A | H2: =Table1[[#This Row],[Total EA (Transfer to WH06)]]/Table1[[#This Row],[CASE]] -> #N/A | I2: =Table1[[#This Row],[Sellable Unit/Set/box to ship]]/Table1[[#This Row],[Case to pull]] -> #N/A | J2: =IF(ISNUMBER(SEARCH("FNSKU",K2)),"Labeling","") | K2: =VLOOKUP(Table1[[#This Row],[SKU]],Instruction!A:F,6,0) -> #N/A | L2: =VLOOKUP(Table1[[#This Row],[ASIN]],'[1]2024'!$A:$AB,28,0) -> #N/A | M2: =VLOOKUP(Table1[[#This Row],[SKU]],Data1!A:C,3,0) -> #N/A | N2: =VLOOKUP(Table1[[#This Row],[Item '#]],Data2!A:D,4,0) -> #N/A | O2: =VLOOKUP(Table1[[#This Row],[Item '#]],Data2!A:D,3,0) -> #N/A | P2: =VLOOKUP(Table1[[#This Row],[Item '#]],[2]Sheet1!$B:$D,3,0) -> #N/A | Q2: =[8]!Table1[[#This Row],[Current WH Inventory]]=VLOOKUP(Table1[[#This Row],[Item '#]],[2]Sheet1!$B:$D,3,0) -> #REF!
D3: =VLOOKUP(Table1[[#This Row],[SKU]],Data1!A:B,2,0) -> #N/A | E3: =Table1[[#This Row],[UoM]]*Table1[[#This Row],[Recommended Replenishment Qty]] -> #N/A | F3: =Table1[[#This Row],[Total EA (Transfer to WH06)]]/Table1[[#This Row],[UoM]] -> #N/A | G3: =Table1[[#This Row],[Total EA (Transfer to WH06)]]/Table1[[#This Row],[BOX]] -> #N/A | H3: =Table1[[#This Row],[Total EA (Transfer to WH06)]]/Table1[[#This Row],[CASE]] -> #N/A | I3: =Table1[[#This Row],[Sellable Unit/Set/box to ship]]/Table1[[#This Row],[Case to pull]] -> #N/A | J3: =IF(ISNUMBER(SEARCH("FNSKU",K3)),"Labeling","") | K3: =VLOOKUP(Table1[[#This Row],[SKU]],Instruction!A:F,6,0) -> #N/A | L3: =VLOOKUP(Table1[[#This Row],[ASIN]],'[1]2024'!$A:$AB,28,0) -> #N/A | M3: =VLOOKUP(Table1[[#This Row],[SKU]],Data1!A:C,3,0) -> #N/A | N3: =VLOOKUP(Table1[[#This Row],[Item '#]],Data2!A:D,4,0) -> #N/A | O3: =VLOOKUP(Table1[[#This Row],[Item '#]],Data2!A:D,3,0) -> #N/A | P3: =VLOOKUP(Table1[[#This Row],[Item '#]],[2]Sheet1!$B:$D,3,0) -> #N/A | Q3: =[8]!Table1[[#This Row],[Current WH Inventory]]=VLOOKUP(Table1[[#This Row],[Item '#]],[2]Sheet1!$B:$D,3,0) -> #REF!
D4: =VLOOKUP(Table1[[#This Row],[SKU]],Data1!A:B,2,0) -> #N/A | E4: =Table1[[#This Row],[UoM]]*Table1[[#This Row],[Recommended Replenishment Qty]] -> #N/A | F4: =Table1[[#This Row],[Total EA (Transfer to WH06)]]/Table1[[#This Row],[UoM]] -> #N/A | G4: =Table1[[#This Row],[Total EA (Transfer to WH06)]]/Table1[[#This Row],[BOX]] -> #N/A | H4: =Table1[[#This Row],[Total EA (Transfer to WH06)]]/Table1[[#This Row],[CASE]] -> #N/A | I4: =Table1[[#This Row],[Sellable Unit/Set/box to ship]]/Table1[[#This Row],[Case to pull]] -> #N/A | J4: =IF(ISNUMBER(SEARCH("FNSKU",K4)),"Labeling","") | K4: =VLOOKUP(Table1[[#This Row],[SKU]],Instruction!A:F,6,0) -> #N/A | L4: =VLOOKUP(Table1[[#This Row],[ASIN]],'[1]2024'!$A:$AB,28,0) -> #N/A | M4: =VLOOKUP(Table1[[#This Row],[SKU]],Data1!A:C,3,0) -> #N/A | N4: =VLOOKUP(Table1[[#This Row],[Item '#]],Data2!A:D,4,0) -> #N/A | O4: =VLOOKUP(Table1[[#This Row],[Item '#]],Data2!A:D,3,0) -> #N/A | P4: =VLOOKUP(Table1[[#This Row],[Item '#]],[2]Sheet1!$B:$D,3,0) -> #N/A | Q4: =[8]!Table1[[#This Row],[Current WH Inventory]]=VLOOKUP(Table1[[#This Row],[Item '#]],[2]Sheet1!$B:$D,3,0) -> #REF!
D5: =VLOOKUP(Table1[[#This Row],[SKU]],Data1!A:B,2,0) -> #N/A | E5: =Table1[[#This Row],[UoM]]*Table1[[#This Row],[Recommended Replenishment Qty]] -> #N/A | F5: =Table1[[#This Row],[Total EA (Transfer to WH06)]]/Table1[[#This Row],[UoM]] -> #N/A | G5: =Table1[[#This Row],[Total EA (Transfer to WH06)]]/Table1[[#This Row],[BOX]] -> #N/A | H5: =Table1[[#This Row],[Total EA (Transfer to WH06)]]/Table1[[#This Row],[CASE]] -> #N/A | I5: =Table1[[#This Row],[Sellable Unit/Set/box to ship]]/Table1[[#This Row],[Case to pull]] -> #N/A | J5: =IF(ISNUMBER(SEARCH("FNSKU",K5)),"Labeling","") | K5: =VLOOKUP(Table1[[#This Row],[SKU]],Instruction!A:F,6,0) -> #N/A | L5: =VLOOKUP(Table1[[#This Row],[ASIN]],'[1]2024'!$A:$AB,28,0) -> #N/A | M5: =VLOOKUP(Table1[[#This Row],[SKU]],Data1!A:C,3,0) -> #N/A | N5: =VLOOKUP(Table1[[#This Row],[Item '#]],Data2!A:D,4,0) -> #N/A | O5: =VLOOKUP(Table1[[#This Row],[Item '#]],Data2!A:D,3,0) -> #N/A | P5: =VLOOKUP(Table1[[#This Row],[Item '#]],[2]Sheet1!$B:$D,3,0) -> #N/A | Q5: =[8]!Table1[[#This Row],[Current WH Inventory]]=VLOOKUP(Table1[[#This Row],[Item '#]],[2]Sheet1!$B:$D,3,0) -> #REF!
D6: =VLOOKUP(Table1[[#This Row],[SKU]],Data1!A:B,2,0) -> #N/A | E6: =Table1[[#This Row],[UoM]]*Table1[[#This Row],[Recommended Replenishment Qty]] -> #N/A | F6: =Table1[[#This Row],[Total EA (Transfer to WH06)]]/Table1[[#This Row],[UoM]] -> #N/A | G6: =Table1[[#This Row],[Total EA (Transfer to WH06)]]/Table1[[#This Row],[BOX]] -> #N/A | H6: =Table1[[#This Row],[Total EA (Transfer to WH06)]]/Table1[[#This Row],[CASE]] -> #N/A | I6: =Table1[[#This Row],[Sellable Unit/Set/box to ship]]/Table1[[#This Row],[Case to pull]] -> #N/A | J6: =IF(ISNUMBER(SEARCH("FNSKU",K6)),"Labeling","") | K6: =VLOOKUP(Table1[[#This Row],[SKU]],Instruction!A:F,6,0) -> #N/A | L6: =VLOOKUP(Table1[[#This Row],[ASIN]],'[1]2024'!$A:$AB,28,0) -> #N/A | M6: =VLOOKUP(Table1[[#This Row],[SKU]],Data1!A:C,3,0) -> #N/A | N6: =VLOOKUP(Table1[[#This Row],[Item '#]],Data2!A:D,4,0) -> #N/A | O6: =VLOOKUP(Table1[[#This Row],[Item '#]],Data2!A:D,3,0) -> #N/A | P6: =VLOOKUP(Table1[[#This Row],[Item '#]],[2]Sheet1!$B:$D,3,0) -> #N/A | Q6: =[8]!Table1[[#This Row],[Current WH Inventory]]=VLOOKUP(Table1[[#This Row],[Item '#]],[2]Sheet1!$B:$D,3,0) -> #REF!
D7: =VLOOKUP(Table1[[#This Row],[SKU]],Data1!A:B,2,0) -> #N/A | E7: =Table1[[#This Row],[UoM]]*Table1[[#This Row],[Recommended Replenishment Qty]] -> #N/A | F7: =Table1[[#This Row],[Total EA (Transfer to WH06)]]/Table1[[#This Row],[UoM]] -> #N/A | G7: =Table1[[#This Row],[Total EA (Transfer to WH06)]]/Table1[[#This Row],[BOX]] -> #N/A | H7: =Table1[[#This Row],[Total EA (Transfer to WH06)]]/Table1[[#This Row],[CASE]] -> #N/A | I7: =Table1[[#This Row],[Sellable Unit/Set/box to ship]]/Table1[[#This Row],[Case to pull]] -> #N/A | J7: =IF(ISNUMBER(SEARCH("FNSKU",K7)),"Labeling","") | K7: =VLOOKUP(Table1[[#This Row],[SKU]],Instruction!A:F,6,0) -> #N/A | L7: =VLOOKUP(Table1[[#This Row],[ASIN]],'[1]2024'!$A:$AB,28,0) -> #N/A | M7: =VLOOKUP(Table1[[#This Row],[SKU]],Data1!A:C,3,0) -> #N/A | N7: =VLOOKUP(Table1[[#This Row],[Item '#]],Data2!A:D,4,0) -> #N/A | O7: =VLOOKUP(Table1[[#This Row],[Item '#]],Data2!A:D,3,0) -> #N/A | P7: =VLOOKUP(Table1[[#This Row],[Item '#]],[2]Sheet1!$B:$D,3,0) -> #N/A | Q7: =[8]!Table1[[#This Row],[Current WH Inventory]]=VLOOKUP(Table1[[#This Row],[Item '#]],[2]Sheet1!$B:$D,3,0) -> #REF!
D8: =VLOOKUP(Table1[[#This Row],[SKU]],Data1!A:B,2,0) -> #N/A | E8: =Table1[[#This Row],[UoM]]*Table1[[#This Row],[Recommended Replenishment Qty]] -> #N/A | F8: =Table1[[#This Row],[Total EA (Transfer to WH06)]]/Table1[[#This Row],[UoM]] -> #N/A | G8: =Table1[[#This Row],[Total EA (Transfer to WH06)]]/Table1[[#This Row],[BOX]] -> #N/A | H8: =Table1[[#This Row],[Total EA (Transfer to WH06)]]/Table1[[#This Row],[CASE]] -> #N/A | I8: =Table1[[#This Row],[Sellable Unit/Set/box to ship]]/Table1[[#This Row],[Case to pull]] -> #N/A | J8: =IF(ISNUMBER(SEARCH("FNSKU",K8)),"Labeling","") | K8: =VLOOKUP(Table1[[#This Row],[SKU]],Instruction!A:F,6,0) -> #N/A | L8: =VLOOKUP(Table1[[#This Row],[ASIN]],'[1]2024'!$A:$AB,28,0) -> #N/A | M8: =VLOOKUP(Table1[[#This Row],[SKU]],Data1!A:C,3,0) -> #N/A | N8: =VLOOKUP(Table1[[#This Row],[Item '#]],Data2!A:D,4,0) -> #N/A | O8: =VLOOKUP(Table1[[#This Row],[Item '#]],Data2!A:D,3,0) -> #N/A | P8: =VLOOKUP(Table1[[#This Row],[Item '#]],[2]Sheet1!$B:$D,3,0) -> #N/A | Q8: =[8]!Table1[[#This Row],[Current WH Inventory]]=VLOOKUP(Table1[[#This Row],[Item '#]],[2]Sheet1!$B:$D,3,0) -> #REF!
D9: =VLOOKUP(Table1[[#This Row],[SKU]],Data1!A:B,2,0) -> #N/A | E9: =Table1[[#This Row],[UoM]]*Table1[[#This Row],[Recommended Replenishment Qty]] -> #N/A | F9: =Table1[[#This Row],[Total EA (Transfer to WH06)]]/Table1[[#This Row],[UoM]] -> #N/A | G9: =Table1[[#This Row],[Total EA (Transfer to WH06)]]/Table1[[#This Row],[BOX]] -> #N/A | H9: =Table1[[#This Row],[Total EA (Transfer to WH06)]]/Table1[[#This Row],[CASE]] -> #N/A | I9: =Table1[[#This Row],[Sellable Unit/Set/box to ship]]/Table1[[#This Row],[Case to pull]] -> #N/A | J9: =IF(ISNUMBER(SEARCH("FNSKU",K9)),"Labeling","") | K9: =VLOOKUP(Table1[[#This Row],[SKU]],Instruction!A:F,6,0) -> #N/A | L9: =VLOOKUP(Table1[[#This Row],[ASIN]],'[1]2024'!$A:$AB,28,0) -> #N/A | M9: =VLOOKUP(Table1[[#This Row],[SKU]],Data1!A:C,3,0) -> #N/A | N9: =VLOOKUP(Table1[[#This Row],[Item '#]],Data2!A:D,4,0) -> #N/A | O9: =VLOOKUP(Table1[[#This Row],[Item '#]],Data2!A:D,3,0) -> #N/A | P9: =VLOOKUP(Table1[[#This Row],[Item '#]],[2]Sheet1!$B:$D,3,0) -> #N/A | Q9: =[8]!Table1[[#This Row],[Current WH Inventory]]=VLOOKUP(Table1[[#This Row],[Item '#]],[2]Sheet1!$B:$D,3,0) -> #REF!
D10: =VLOOKUP(Table1[[#This Row],[SKU]],Data1!A:B,2,0) -> #N/A | E10: =Table1[[#This Row],[UoM]]*Table1[[#This Row],[Recommended Replenishment Qty]] -> #N/A | F10: =Table1[[#This Row],[Total EA (Transfer to WH06)]]/Table1[[#This Row],[UoM]] -> #N/A | G10: =Table1[[#This Row],[Total EA (Transfer to WH06)]]/Table1[[#This Row],[BOX]] -> #N/A | H10: =Table1[[#This Row],[Total EA (Transfer to WH06)]]/Table1[[#This Row],[CASE]] -> #N/A | I10: =Table1[[#This Row],[Sellable Unit/Set/box to ship]]/Table1[[#This Row],[Case to pull]] -> #N/A | J10: =IF(ISNUMBER(SEARCH("FNSKU",K10)),"Labeling","") | K10: =VLOOKUP(Table1[[#This Row],[SKU]],Instruction!A:F,6,0) -> #N/A | L10: =VLOOKUP(Table1[[#This Row],[ASIN]],'[1]2024'!$A:$AB,28,0) -> #N/A | M10: =VLOOKUP(Table1[[#This Row],[SKU]],Data1!A:C,3,0) -> #N/A | N10: =VLOOKUP(Table1[[#This Row],[Item '#]],Data2!A:D,4,0) -> #N/A | O10: =VLOOKUP(Table1[[#This Row],[Item '#]],Data2!A:D,3,0) -> #N/A | P10: =VLOOKUP(Table1[[#This Row],[Item '#]],[2]Sheet1!$B:$D,3,0) -> #N/A | Q10: =[8]!Table1[[#This Row],[Current WH Inventory]]=VLOOKUP(Table1[[#This Row],[Item '#]],[2]Sheet1!$B:$D,3,0) -> #REF!
D11: =VLOOKUP(Table1[[#This Row],[SKU]],Data1!A:B,2,0) -> #N/A | E11: =Table1[[#This Row],[UoM]]*Table1[[#This Row],[Recommended Replenishment Qty]] -> #N/A | F11: =Table1[[#This Row],[Total EA (Transfer to WH06)]]/Table1[[#This Row],[UoM]] -> #N/A | G11: =Table1[[#This Row],[Total EA (Transfer to WH06)]]/Table1[[#This Row],[BOX]] -> #N/A | H11: =Table1[[#This Row],[Total EA (Transfer to WH06)]]/Table1[[#This Row],[CASE]] -> #N/A | I11: =Table1[[#This Row],[Sellable Unit/Set/box to ship]]/Table1[[#This Row],[Case to pull]] -> #N/A | J11: =IF(ISNUMBER(SEARCH("FNSKU",K11)),"Labeling","") | K11: =VLOOKUP(Table1[[#This Row],[SKU]],Instruction!A:F,6,0) -> #N/A | L11: =VLOOKUP(Table1[[#This Row],[ASIN]],'[1]2024'!$A:$AB,28,0) -> #N/A | M11: =VLOOKUP(Table1[[#This Row],[SKU]],Data1!A:C,3,0) -> #N/A | N11: =VLOOKUP(Table1[[#This Row],[Item '#]],Data2!A:D,4,0) -> #N/A | O11: =VLOOKUP(Table1[[#This Row],[Item '#]],Data2!A:D,3,0) -> #N/A | P11: =VLOOKUP(Table1[[#This Row],[Item '#]],[2]Sheet1!$B:$D,3,0) -> #N/A | Q11: =[8]!Table1[[#This Row],[Current WH Inventory]]=VLOOKUP(Table1[[#This Row],[Item '#]],[2]Sheet1!$B:$D,3,0) -> #REF!
D12: =VLOOKUP(Table1[[#This Row],[SKU]],Data1!A:B,2,0) -> #N/A | E12: =Table1[[#This Row],[UoM]]*Table1[[#This Row],[Recommended Replenishment Qty]] -> #N/A | F12: =Table1[[#This Row],[Total EA (Transfer to WH06)]]/Table1[[#This Row],[UoM]] -> #N/A | G12: =Table1[[#This Row],[Total EA (Transfer to WH06)]]/Table1[[#This Row],[BOX]] -> #N/A | H12: =Table1[[#This Row],[Total EA (Transfer to WH06)]]/Table1[[#This Row],[CASE]] -> #N/A | I12: =Table1[[#This Row],[Sellable Unit/Set/box to ship]]/Table1[[#This Row],[Box to pull]] -> #N/A | J12: =IF(ISNUMBER(SEARCH("FNSKU",K12)),"Labeling","") | K12: =VLOOKUP(Table1[[#This Row],[SKU]],Instruction!A:F,6,0) -> #N/A | L12: =VLOOKUP(Table1[[#This Row],[ASIN]],'[1]2024'!$A:$AB,28,0) -> #N/A | M12: =VLOOKUP(Table1[[#This Row],[SKU]],Data1!A:C,3,0) -> #N/A | N12: =VLOOKUP(Table1[[#This Row],[Item '#]],Data2!A:D,4,0) -> #N/A | O12: =VLOOKUP(Table1[[#This Row],[Item '#]],Data2!A:D,3,0) -> #N/A | P12: =VLOOKUP(Table1[[#This Row],[Item '#]],[2]Sheet1!$B:$D,3,0) -> #N/A | Q12: =[8]!Table1[[#This Row],[Current WH Inventory]]=VLOOKUP(Table1[[#This Row],[Item '#]],[2]Sheet1!$B:$D,3,0) -> #REF!
D13: =VLOOKUP(Table1[[#This Row],[SKU]],Data1!A:B,2,0) -> #N/A | E13: =Table1[[#This Row],[UoM]]*Table1[[#This Row],[Recommended Replenishment Qty]] -> #N/A | F13: =Table1[[#This Row],[Total EA (Transfer to WH06)]]/Table1[[#This Row],[UoM]] -> #N/A | G13: =Table1[[#This Row],[Total EA (Transfer to WH06)]]/Table1[[#This Row],[BOX]] -> #N/A | H13: =Table1[[#This Row],[Total EA (Transfer to WH06)]]/Table1[[#This Row],[CASE]] -> #N/A | I13: =Table1[[#This Row],[Sellable Unit/Set/box to ship]]/Table1[[#This Row],[Box to pull]] -> #N/A | J13: =IF(ISNUMBER(SEARCH("FNSKU",K13)),"Labeling","") | K13: =VLOOKUP(Table1[[#This Row],[SKU]],Instruction!A:F,6,0) -> #N/A | L13: =VLOOKUP(Table1[[#This Row],[ASIN]],'[1]2024'!$A:$AB,28,0) -> #N/A | M13: =VLOOKUP(Table1[[#This Row],[SKU]],Data1!A:C,3,0) -> #N/A | N13: =VLOOKUP(Table1[[#This Row],[Item '#]],Data2!A:D,4,0) -> #N/A | O13: =VLOOKUP(Table1[[#This Row],[Item '#]],Data2!A:D,3,0) -> #N/A | P13: =VLOOKUP(Table1[[#This Row],[Item '#]],[2]Sheet1!$B:$D,3,0) -> #N/A | Q13: =[8]!Table1[[#This Row],[Current WH Inventory]]=VLOOKUP(Table1[[#This Row],[Item '#]],[2]Sheet1!$B:$D,3,0) -> #REF!
D14: =VLOOKUP(Table1[[#This Row],[SKU]],Data1!A:B,2,0) -> #N/A | E14: =Table1[[#This Row],[UoM]]*Table1[[#This Row],[Recommended Replenishment Qty]] -> #N/A | F14: =Table1[[#This Row],[Total EA (Transfer to WH06)]]/Table1[[#This Row],[UoM]] -> #N/A | G14: =Table1[[#This Row],[Total EA (Transfer to WH06)]]/Table1[[#This Row],[BOX]] -> #N/A | H14: =Table1[[#This Row],[Total EA (Transfer to WH06)]]/Table1[[#This Row],[CASE]] -> #N/A | I14: =Table1[[#This Row],[Sellable Unit/Set/box to ship]]/Table1[[#This Row],[Case to pull]] -> #N/A | J14: =IF(ISNUMBER(SEARCH("FNSKU",K14)),"Labeling","") | K14: =VLOOKUP(Table1[[#This Row],[SKU]],Instruction!A:F,6,0) -> #N/A | L14: =VLOOKUP(Table1[[#This Row],[ASIN]],'[1]2024'!$A:$AB,28,0) -> #N/A | M14: =VLOOKUP(Table1[[#This Row],[SKU]],Data1!A:C,3,0) -> #N/A | N14: =VLOOKUP(Table1[[#This Row],[Item '#]],Data2!A:D,4,0) -> #N/A | O14: =VLOOKUP(Table1[[#This Row],[Item '#]],Data2!A:D,3,0) -> #N/A | P14: =VLOOKUP(Table1[[#This Row],[Item '#]],[2]Sheet1!$B:$D,3,0) -> #N/A | Q14: =[8]!Table1[[#This Row],[Current WH Inventory]]=VLOOKUP(Table1[[#This Row],[Item '#]],[2]Sheet1!$B:$D,3,0) -> #REF!
D15: =VLOOKUP(Table1[[#This Row],[SKU]],Data1!A:B,2,0) -> #N/A | E15: =Table1[[#This Row],[UoM]]*Table1[[#This Row],[Recommended Replenishment Qty]] -> #N/A | F15: =Table1[[#This Row],[Total EA (Transfer to WH06)]]/Table1[[#This Row],[UoM]] -> #N/A | G15: =Table1[[#This Row],[Total EA (Transfer to WH06)]]/Table1[[#This Row],[BOX]] -> #N/A | H15: =Table1[[#This Row],[Total EA (Transfer to WH06)]]/Table1[[#This Row],[CASE]] -> #N/A | I15: =Table1[[#This Row],[Sellable Unit/Set/box to ship]]/Table1[[#This Row],[Case to pull]] -> #N/A | J15: =IF(ISNUMBER(SEARCH("FNSKU",K15)),"Labeling","") | K15: =VLOOKUP(Table1[[#This Row],[SKU]],Instruction!A:F,6,0) -> #N/A | L15: =VLOOKUP(Table1[[#This Row],[ASIN]],'[1]2024'!$A:$AB,28,0) -> #N/A | M15: =VLOOKUP(Table1[[#This Row],[SKU]],Data1!A:C,3,0) -> #N/A | N15: =VLOOKUP(Table1[[#This Row],[Item '#]],Data2!A:D,4,0) -> #N/A | O15: =VLOOKUP(Table1[[#This Row],[Item '#]],Data2!A:D,3,0) -> #N/A | P15: =VLOOKUP(Table1[[#This Row],[Item '#]],[2]Sheet1!$B:$D,3,0) -> #N/A | Q15: =[8]!Table1[[#This Row],[Current WH Inventory]]=VLOOKUP(Table1[[#This Row],[Item '#]],[2]Sheet1!$B:$D,3,0) -> #REF!
D16: =VLOOKUP(Table1[[#This Row],[SKU]],Data1!A:B,2,0) -> #N/A | E16: =Table1[[#This Row],[UoM]]*Table1[[#This Row],[Recommended Replenishment Qty]] -> #N/A | F16: =Table1[[#This Row],[Total EA (Transfer to WH06)]]/Table1[[#This Row],[UoM]] -> #N/A | G16: =Table1[[#This Row],[Total EA (Transfer to WH06)]]/Table1[[#This Row],[BOX]] -> #N/A | H16: =Table1[[#This Row],[Total EA (Transfer to WH06)]]/Table1[[#This Row],[CASE]] -> #N/A | I16: =Table1[[#This Row],[Sellable Unit/Set/box to ship]]/Table1[[#This Row],[Case to pull]] -> #N/A | J16: =IF(ISNUMBER(SEARCH("FNSKU",K16)),"Labeling","") | K16: =VLOOKUP(Table1[[#This Row],[SKU]],Instruction!A:F,6,0) -> #N/A | L16: =VLOOKUP(Table1[[#This Row],[ASIN]],'[1]2024'!$A:$AB,28,0) -> #N/A | M16: =VLOOKUP(Table1[[#This Row],[SKU]],Data1!A:C,3,0) -> #N/A | N16: =VLOOKUP(Table1[[#This Row],[Item '#]],Data2!A:D,4,0) -> #N/A | O16: =VLOOKUP(Table1[[#This Row],[Item '#]],Data2!A:D,3,0) -> #N/A | P16: =VLOOKUP(Table1[[#This Row],[Item '#]],[2]Sheet1!$B:$D,3,0) -> #N/A | Q16: =[8]!Table1[[#This Row],[Current WH Inventory]]=VLOOKUP(Table1[[#This Row],[Item '#]],[2]Sheet1!$B:$D,3,0) -> #REF!
D17: =VLOOKUP(Table1[[#This Row],[SKU]],Data1!A:B,2,0) -> #N/A | E17: =Table1[[#This Row],[UoM]]*Table1[[#This Row],[Recommended Replenishment Qty]] -> #N/A | F17: =Table1[[#This Row],[Total EA (Transfer to WH06)]]/Table1[[#This Row],[UoM]] -> #N/A | G17: =Table1[[#This Row],[Total EA (Transfer to WH06)]]/Table1[[#This Row],[BOX]] -> #N/A | H17: =Table1[[#This Row],[Total EA (Transfer to WH06)]]/Table1[[#This Row],[CASE]] -> #N/A | I17: =Table1[[#This Row],[Sellable Unit/Set/box to ship]]/Table1[[#This Row],[Case to pull]] -> #N/A | J17: =IF(ISNUMBER(SEARCH("FNSKU",K17)),"Labeling","") | K17: =VLOOKUP(Table1[[#This Row],[SKU]],Instruction!A:F,6,0) -> #N/A | L17: =VLOOKUP(Table1[[#This Row],[ASIN]],'[1]2024'!$A:$AB,28,0) -> #N/A | M17: =VLOOKUP(Table1[[#This Row],[SKU]],Data1!A:C,3,0) -> #N/A | N17: =VLOOKUP(Table1[[#This Row],[Item '#]],Data2!A:D,4,0) -> #N/A | O17: =VLOOKUP(Table1[[#This Row],[Item '#]],Data2!A:D,3,0) -> #N/A | P17: =VLOOKUP(Table1[[#This Row],[Item '#]],[2]Sheet1!$B:$D,3,0) -> #N/A | Q17: =[8]!Table1[[#This Row],[Current WH Inventory]]=VLOOKUP(Table1[[#This Row],[Item '#]],[2]Sheet1!$B:$D,3,0) -> #REF!
D18: =VLOOKUP(Table1[[#This Row],[SKU]],Data1!A:B,2,0) -> #N/A | E18: =Table1[[#This Row],[UoM]]*Table1[[#This Row],[Recommended Replenishment Qty]] -> #N/A | F18: =Table1[[#This Row],[Total EA (Transfer to WH06)]]/Table1[[#This Row],[UoM]] -> #N/A | G18: =Table1[[#This Row],[Total EA (Transfer to WH06)]]/Table1[[#This Row],[BOX]] -> #N/A | H18: =Table1[[#This Row],[Total EA (Transfer to WH06)]]/Table1[[#This Row],[CASE]] -> #N/A | I18: =Table1[[#This Row],[Sellable Unit/Set/box to ship]]/Table1[[#This Row],[Case to pull]] -> #N/A | J18: =IF(ISNUMBER(SEARCH("FNSKU",K18)),"Labeling","") | K18: =VLOOKUP(Table1[[#This Row],[SKU]],Instruction!A:F,6,0) -> #N/A | L18: =VLOOKUP(Table1[[#This Row],[ASIN]],'[1]2024'!$A:$AB,28,0) -> #N/A | M18: =VLOOKUP(Table1[[#This Row],[SKU]],Data1!A:C,3,0) -> #N/A | N18: =VLOOKUP(Table1[[#This Row],[Item '#]],Data2!A:D,4,0) -> #N/A | O18: =VLOOKUP(Table1[[#This Row],[Item '#]],Data2!A:D,3,0) -> #N/A | P18: =VLOOKUP(Table1[[#This Row],[Item '#]],[2]Sheet1!$B:$D,3,0) -> #N/A | Q18: =[8]!Table1[[#This Row],[Current WH Inventory]]=VLOOKUP(Table1[[#This Row],[Item '#]],[2]Sheet1!$B:$D,3,0) -> #REF!
D19: =VLOOKUP(Table1[[#This Row],[SKU]],Data1!A:B,2,0) -> #N/A | E19: =Table1[[#This Row],[UoM]]*Table1[[#This Row],[Recommended Replenishment Qty]] -> #N/A | F19: =Table1[[#This Row],[Total EA (Transfer to WH06)]]/Table1[[#This Row],[UoM]] -> #N/A | G19: =Table1[[#This Row],[Total EA (Transfer to WH06)]]/Table1[[#This Row],[BOX]] -> #N/A | H19: =Table1[[#This Row],[Total EA (Transfer to WH06)]]/Table1[[#This Row],[CASE]] -> #N/A | I19: =Table1[[#This Row],[Sellable Unit/Set/box to ship]]/Table1[[#This Row],[Case to pull]] -> #N/A | J19: =IF(ISNUMBER(SEARCH("FNSKU",K19)),"Labeling","") | K19: =VLOOKUP(Table1[[#This Row],[SKU]],Instruction!A:F,6,0) -> #N/A | L19: =VLOOKUP(Table1[[#This Row],[ASIN]],'[1]2024'!$A:$AB,28,0) -> #N/A | M19: =VLOOKUP(Table1[[#This Row],[SKU]],Data1!A:C,3,0) -> #N/A | N19: =VLOOKUP(Table1[[#This Row],[Item '#]],Data2!A:D,4,0) -> #N/A | O19: =VLOOKUP(Table1[[#This Row],[Item '#]],Data2!A:D,3,0) -> #N/A | P19: =VLOOKUP(Table1[[#This Row],[Item '#]],[2]Sheet1!$B:$D,3,0) -> #N/A | Q19: =[8]!Table1[[#This Row],[Current WH Inventory]]=VLOOKUP(Table1[[#This Row],[Item '#]],[2]Sheet1!$B:$D,3,0) -> #REF!
D20: =VLOOKUP(Table1[[#This Row],[SKU]],Data1!A:B,2,0) -> #N/A | E20: =Table1[[#This Row],[UoM]]*Table1[[#This Row],[Recommended Replenishment Qty]] -> #N/A | F20: =Table1[[#This Row],[Total EA (Transfer to WH06)]]/Table1[[#This Row],[UoM]] -> #N/A | G20: =Table1[[#This Row],[Total EA (Transfer to WH06)]]/Table1[[#This Row],[BOX]] -> #N/A | H20: =Table1[[#This Row],[Total EA (Transfer to WH06)]]/Table1[[#This Row],[CASE]] -> #N/A | I20: =Table1[[#This Row],[Sellable Unit/Set/box to ship]]/Table1[[#This Row],[Case to pull]] -> #N/A | J20: =IF(ISNUMBER(SEARCH("FNSKU",K20)),"Labeling","") | K20: =VLOOKUP(Table1[[#This Row],[SKU]],Instruction!A:F,6,0) -> #N/A | L20: =VLOOKUP(Table1[[#This Row],[ASIN]],'[1]2024'!$A:$AB,28,0) -> #N/A | M20: =VLOOKUP(Table1[[#This Row],[SKU]],Data1!A:C,3,0) -> #N/A | N20: =VLOOKUP(Table1[[#This Row],[Item '#]],Data2!A:D,4,0) -> #N/A | O20: =VLOOKUP(Table1[[#This Row],[Item '#]],Data2!A:D,3,0) -> #N/A | P20: =VLOOKUP(Table1[[#This Row],[Item '#]],[2]Sheet1!$B:$D,3,0) -> #N/A | Q20: =[8]!Table1[[#This Row],[Current WH Inventory]]=VLOOKUP(Table1[[#This Row],[Item '#]],[2]Sheet1!$B:$D,3,0) -> #REF!
D21: =VLOOKUP(Table1[[#This Row],[SKU]],Data1!A:B,2,0) -> #N/A | E21: =Table1[[#This Row],[UoM]]*Table1[[#This Row],[Recommended Replenishment Qty]] -> #N/A | F21: =Table1[[#This Row],[Total EA (Transfer to WH06)]]/Table1[[#This Row],[UoM]] -> #N/A | G21: =Table1[[#This Row],[Total EA (Transfer to WH06)]]/Table1[[#This Row],[BOX]] -> #N/A | H21: =Table1[[#This Row],[Total EA (Transfer to WH06)]]/Table1[[#This Row],[CASE]] -> #N/A | I21: =Table1[[#This Row],[Sellable Unit/Set/box to ship]]/Table1[[#This Row],[Case to pull]] -> #N/A | J21: =IF(ISNUMBER(SEARCH("FNSKU",K21)),"Labeling","") | K21: =VLOOKUP(Table1[[#This Row],[SKU]],Instruction!A:F,6,0) -> #N/A | L21: =VLOOKUP(Table1[[#This Row],[ASIN]],'[1]2024'!$A:$AB,28,0) -> #N/A | M21: =VLOOKUP(Table1[[#This Row],[SKU]],Data1!A:C,3,0) -> #N/A | N21: =VLOOKUP(Table1[[#This Row],[Item '#]],Data2!A:D,4,0) -> #N/A | O21: =VLOOKUP(Table1[[#This Row],[Item '#]],Data2!A:D,3,0) -> #N/A | P21: =VLOOKUP(Table1[[#This Row],[Item '#]],[2]Sheet1!$B:$D,3,0) -> #N/A | Q21: =[8]!Table1[[#This Row],[Current WH Inventory]]=VLOOKUP(Table1[[#This Row],[Item '#]],[2]Sheet1!$B:$D,3,0) -> #REF!
D22: =VLOOKUP(Table1[[#This Row],[SKU]],Data1!A:B,2,0) -> #N/A | E22: =Table1[[#This Row],[UoM]]*Table1[[#This Row],[Recommended Replenishment Qty]] -> #N/A | F22: =Table1[[#This Row],[Total EA (Transfer to WH06)]]/Table1[[#This Row],[UoM]] -> #N/A | G22: =Table1[[#This Row],[Total EA (Transfer to WH06)]]/Table1[[#This Row],[BOX]] -> #N/A | H22: =Table1[[#This Row],[Total EA (Transfer to WH06)]]/Table1[[#This Row],[CASE]] -> #N/A | I22: =Table1[[#This Row],[Sellable Unit/Set/box to ship]]/Table1[[#This Row],[Case to pull]] -> #N/A | J22: =IF(ISNUMBER(SEARCH("FNSKU",K22)),"Labeling","") | K22: =VLOOKUP(Table1[[#This Row],[SKU]],Instruction!A:F,6,0) -> #N/A | L22: =VLOOKUP(Table1[[#This Row],[ASIN]],'[1]2024'!$A:$AB,28,0) -> #N/A | M22: =VLOOKUP(Table1[[#This Row],[SKU]],Data1!A:C,3,0) -> #N/A | N22: =VLOOKUP(Table1[[#This Row],[Item '#]],Data2!A:D,4,0) -> #N/A | O22: =VLOOKUP(Table1[[#This Row],[Item '#]],Data2!A:D,3,0) -> #N/A | P22: =VLOOKUP(Table1[[#This Row],[Item '#]],[2]Sheet1!$B:$D,3,0) -> #N/A | Q22: =[8]!Table1[[#This Row],[Current WH Inventory]]=VLOOKUP(Table1[[#This Row],[Item '#]],[2]Sheet1!$B:$D,3,0) -> #REF!
D23: =VLOOKUP(Table1[[#This Row],[SKU]],Data1!A:B,2,0) -> #N/A | E23: =Table1[[#This Row],[UoM]]*Table1[[#This Row],[Recommended Replenishment Qty]] -> #N/A | F23: =Table1[[#This Row],[Total EA (Transfer to WH06)]]/Table1[[#This Row],[UoM]] -> #N/A | G23: =Table1[[#This Row],[Total EA (Transfer to WH06)]]/Table1[[#This Row],[BOX]] -> #N/A | H23: =Table1[[#This Row],[Total EA (Transfer to WH06)]]/Table1[[#This Row],[CASE]] -> #N/A | I23: =Table1[[#This Row],[Sellable Unit/Set/box to ship]]/Table1[[#This Row],[Case to pull]] -> #N/A | J23: =IF(ISNUMBER(SEARCH("FNSKU",K23)),"Labeling","") | K23: =VLOOKUP(Table1[[#This Row],[SKU]],Instruction!A:F,6,0) -> #N/A | L23: =VLOOKUP(Table1[[#This Row],[ASIN]],'[1]2024'!$A:$AB,28,0) -> #N/A | M23: =VLOOKUP(Table1[[#This Row],[SKU]],Data1!A:C,3,0) -> #N/A | N23: =VLOOKUP(Table1[[#This Row],[Item '#]],Data2!A:D,4,0) -> #N/A | O23: =VLOOKUP(Table1[[#This Row],[Item '#]],Data2!A:D,3,0) -> #N/A | P23: =VLOOKUP(Table1[[#This Row],[Item '#]],[2]Sheet1!$B:$D,3,0) -> #N/A | Q23: =[8]!Table1[[#This Row],[Current WH Inventory]]=VLOOKUP(Table1[[#This Row],[Item '#]],[2]Sheet1!$B:$D,3,0) -> #REF!
D24: =VLOOKUP(Table1[[#This Row],[SKU]],Data1!A:B,2,0) -> #N/A | E24: =Table1[[#This Row],[UoM]]*Table1[[#This Row],[Recommended Replenishment Qty]] -> #N/A | F24: =Table1[[#This Row],[Total EA (Transfer to WH06)]]/Table1[[#This Row],[UoM]] -> #N/A | G24: =Table1[[#This Row],[Total EA (Transfer to WH06)]]/Table1[[#This Row],[BOX]] -> #N/A | H24: =Table1[[#This Row],[Total EA (Transfer to WH06)]]/Table1[[#This Row],[CASE]] -> #N/A | I24: =Table1[[#This Row],[Sellable Unit/Set/box to ship]]/Table1[[#This Row],[Case to pull]] -> #N/A | J24: =IF(ISNUMBER(SEARCH("FNSKU",K24)),"Labeling","") | K24: =VLOOKUP(Table1[[#This Row],[SKU]],Instruction!A:F,6,0) -> #N/A | L24: =VLOOKUP(Table1[[#This Row],[ASIN]],'[1]2024'!$A:$AB,28,0) -> #N/A | M24: =VLOOKUP(Table1[[#This Row],[SKU]],Data1!A:C,3,0) -> #N/A | N24: =VLOOKUP(Table1[[#This Row],[Item '#]],Data2!A:D,4,0) -> #N/A | O24: =VLOOKUP(Table1[[#This Row],[Item '#]],Data2!A:D,3,0) -> #N/A | P24: =VLOOKUP(Table1[[#This Row],[Item '#]],[2]Sheet1!$B:$D,3,0) -> #N/A | Q24: =[8]!Table1[[#This Row],[Current WH Inventory]]=VLOOKUP(Table1[[#This Row],[Item '#]],[2]Sheet1!$B:$D,3,0) -> #REF!
D25: =VLOOKUP(Table1[[#This Row],[SKU]],Data1!A:B,2,0) -> #N/A | E25: =Table1[[#This Row],[UoM]]*Table1[[#This Row],[Recommended Replenishment Qty]] -> #N/A | F25: =Table1[[#This Row],[Total EA (Transfer to WH06)]]/Table1[[#This Row],[UoM]] -> #N/A | G25: =Table1[[#This Row],[Total EA (Transfer to WH06)]]/Table1[[#This Row],[BOX]] -> #N/A | H25: =Table1[[#This Row],[Total EA (Transfer to WH06)]]/Table1[[#This Row],[CASE]] -> #N/A | I25: =Table1[[#This Row],[Sellable Unit/Set/box to ship]]/Table1[[#This Row],[Case to pull]] -> #N/A | J25: =IF(ISNUMBER(SEARCH("FNSKU",K25)),"Labeling","") | K25: =VLOOKUP(Table1[[#This Row],[SKU]],Instruction!A:F,6,0) -> #N/A | L25: =VLOOKUP(Table1[[#This Row],[ASIN]],'[1]2024'!$A:$AB,28,0) -> #N/A | M25: =VLOOKUP(Table1[[#This Row],[SKU]],Data1!A:C,3,0) -> #N/A | N25: =VLOOKUP(Table1[[#This Row],[Item '#]],Data2!A:D,4,0) -> #N/A | O25: =VLOOKUP(Table1[[#This Row],[Item '#]],Data2!A:D,3,0) -> #N/A | P25: =VLOOKUP(Table1[[#This Row],[Item '#]],[2]Sheet1!$B:$D,3,0) -> #N/A | Q25: =[8]!Table1[[#This Row],[Current WH Inventory]]=VLOOKUP(Table1[[#This Row],[Item '#]],[2]Sheet1!$B:$D,3,0) -> #REF!
... D33: =VLOOKUP(Table1[[#This Row],[SKU]],Data1!A:B,2,0) -> #N/A | E33: =Table1[[#This Row],[UoM]]*Table1[[#This Row],[Recommended Replenishment Qty]] -> #N/A | F33: =Table1[[#This Row],[Total EA (Transfer to WH06)]]/Table1[[#This Row],[UoM]] -> #N/A | G33: =Table1[[#This Row],[Total EA (Transfer to WH06)]]/Table1[[#This Row],[BOX]] -> #N/A | H33: =Table1[[#This Row],[Total EA (Transfer to WH06)]]/Table1[[#This Row],[CASE]] -> #N/A | I33: =Table1[[#This Row],[Sellable Unit/Set/box to ship]]/Table1[[#This Row],[Case to pull]] -> #N/A | J33: =IF(ISNUMBER(SEARCH("FNSKU",K33)),"Labeling","") | K33: =VLOOKUP(Table1[[#This Row],[SKU]],Instruction!A:F,6,0) -> #N/A | L33: =VLOOKUP(Table1[[#This Row],[ASIN]],'[1]2024'!$A:$AB,28,0) -> #N/A | M33: =VLOOKUP(Table1[[#This Row],[SKU]],Data1!A:C,3,0) -> #N/A | N33: =VLOOKUP(Table1[[#This Row],[Item '#]],Data2!A:D,4,0) -> #N/A | O33: =VLOOKUP(Table1[[#This Row],[Item '#]],Data2!A:D,3,0) -> #N/A | P33: =VLOOKUP(Table1[[#This Row],[Item '#]],[2]Sheet1!$B:$D,3,0) -> #N/A | Q33: =[8]!Table1[[#This Row],[Current WH Inventory]]=VLOOKUP(Table1[[#This Row],[Item '#]],[2]Sheet1!$B:$D,3,0) -> #REF!
D34: =VLOOKUP(Table1[[#This Row],[SKU]],Data1!A:B,2,0) -> #N/A | E34: =Table1[[#This Row],[UoM]]*Table1[[#This Row],[Recommended Replenishment Qty]] -> #N/A | F34: =Table1[[#This Row],[Total EA (Transfer to WH06)]]/Table1[[#This Row],[UoM]] -> #N/A | G34: =Table1[[#This Row],[Total EA (Transfer to WH06)]]/Table1[[#This Row],[BOX]] -> #N/A | H34: =Table1[[#This Row],[Total EA (Transfer to WH06)]]/Table1[[#This Row],[CASE]] -> #N/A | I34: =Table1[[#This Row],[Sellable Unit/Set/box to ship]]/Table1[[#This Row],[Box to pull]] -> #N/A | J34: =IF(ISNUMBER(SEARCH("FNSKU",K34)),"Labeling","") | K34: =VLOOKUP(Table1[[#This Row],[SKU]],Instruction!A:F,6,0) -> #N/A | L34: =VLOOKUP(Table1[[#This Row],[ASIN]],'[1]2024'!$A:$AB,28,0) -> #N/A | M34: =VLOOKUP(Table1[[#This Row],[SKU]],Data1!A:C,3,0) -> #N/A | N34: =VLOOKUP(Table1[[#This Row],[Item '#]],Data2!A:D,4,0) -> #N/A | O34: =VLOOKUP(Table1[[#This Row],[Item '#]],Data2!A:D,3,0) -> #N/A | P34: =VLOOKUP(Table1[[#This Row],[Item '#]],[2]Sheet1!$B:$D,3,0) -> #N/A | Q34: =[8]!Table1[[#This Row],[Current WH Inventory]]=VLOOKUP(Table1[[#This Row],[Item '#]],[2]Sheet1!$B:$D,3,0) -> #REF!
D35: =VLOOKUP(Table1[[#This Row],[SKU]],Data1!A:B,2,0) -> #N/A | E35: =Table1[[#This Row],[UoM]]*Table1[[#This Row],[Recommended Replenishment Qty]] -> #N/A | F35: =Table1[[#This Row],[Total EA (Transfer to WH06)]]/Table1[[#This Row],[UoM]] -> #N/A | G35: =Table1[[#This Row],[Total EA (Transfer to WH06)]]/Table1[[#This Row],[BOX]] -> #N/A | H35: =Table1[[#This Row],[Total EA (Transfer to WH06)]]/Table1[[#This Row],[CASE]] -> #N/A | I35: =Table1[[#This Row],[Sellable Unit/Set/box to ship]]/Table1[[#This Row],[Box to pull]] -> #N/A | J35: =IF(ISNUMBER(SEARCH("FNSKU",K35)),"Labeling","") | K35: =VLOOKUP(Table1[[#This Row],[SKU]],Instruction!A:F,6,0) -> #N/A | L35: =VLOOKUP(Table1[[#This Row],[ASIN]],'[1]2024'!$A:$AB,28,0) -> #N/A | M35: =VLOOKUP(Table1[[#This Row],[SKU]],Data1!A:C,3,0) -> #N/A | N35: =VLOOKUP(Table1[[#This Row],[Item '#]],Data2!A:D,4,0) -> #N/A | O35: =VLOOKUP(Table1[[#This Row],[Item '#]],Data2!A:D,3,0) -> #N/A | P35: =VLOOKUP(Table1[[#This Row],[Item '#]],[2]Sheet1!$B:$D,3,0) -> #N/A | Q35: =[8]!Table1[[#This Row],[Current WH Inventory]]=VLOOKUP(Table1[[#This Row],[Item '#]],[2]Sheet1!$B:$D,3,0) -> #REF!
D36: =VLOOKUP(Table1[[#This Row],[SKU]],Data1!A:B,2,0) -> #N/A | E36: =Table1[[#This Row],[UoM]]*Table1[[#This Row],[Recommended Replenishment Qty]] -> #N/A | F36: =Table1[[#This Row],[Total EA (Transfer to WH06)]]/Table1[[#This Row],[UoM]] -> #N/A | G36: =Table1[[#This Row],[Total EA (Transfer to WH06)]]/Table1[[#This Row],[BOX]] -> #N/A | H36: =Table1[[#This Row],[Total EA (Transfer to WH06)]]/Table1[[#This Row],[CASE]] -> #N/A | I36: =Table1[[#This Row],[Sellable Unit/Set/box to ship]]/Table1[[#This Row],[Case to pull]] -> #N/A | J36: =IF(ISNUMBER(SEARCH("FNSKU",K36)),"Labeling","") | K36: =VLOOKUP(Table1[[#This Row],[SKU]],Instruction!A:F,6,0) -> #N/A | L36: =VLOOKUP(Table1[[#This Row],[ASIN]],'[1]2024'!$A:$AB,28,0) -> #N/A | M36: =VLOOKUP(Table1[[#This Row],[SKU]],Data1!A:C,3,0) -> #N/A | N36: =VLOOKUP(Table1[[#This Row],[Item '#]],Data2!A:D,4,0) -> #N/A | O36: =VLOOKUP(Table1[[#This Row],[Item '#]],Data2!A:D,3,0) -> #N/A | P36: =VLOOKUP(Table1[[#This Row],[Item '#]],[2]Sheet1!$B:$D,3,0) -> #N/A | Q36: =[8]!Table1[[#This Row],[Current WH Inventory]]=VLOOKUP(Table1[[#This Row],[Item '#]],[2]Sheet1!$B:$D,3,0) -> #REF!
D37: =VLOOKUP(Table1[[#This Row],[SKU]],Data1!A:B,2,0) -> #N/A | E37: =Table1[[#This Row],[UoM]]*Table1[[#This Row],[Recommended Replenishment Qty]] -> #N/A | F37: =Table1[[#This Row],[Total EA (Transfer to WH06)]]/Table1[[#This Row],[UoM]] -> #N/A | G37: =Table1[[#This Row],[Total EA (Transfer to WH06)]]/Table1[[#This Row],[BOX]] -> #N/A | H37: =Table1[[#This Row],[Total EA (Transfer to WH06)]]/Table1[[#This Row],[CASE]] -> #N/A | I37: =Table1[[#This Row],[Sellable Unit/Set/box to ship]]/Table1[[#This Row],[Box to pull]] -> #N/A | J37: =IF(ISNUMBER(SEARCH("FNSKU",K37)),"Labeling","") | K37: =VLOOKUP(Table1[[#This Row],[SKU]],Instruction!A:F,6,0) -> #N/A | L37: =VLOOKUP(Table1[[#This Row],[ASIN]],'[1]2024'!$A:$AB,28,0) -> #N/A | M37: =VLOOKUP(Table1[[#This Row],[SKU]],Data1!A:C,3,0) -> #N/A | N37: =VLOOKUP(Table1[[#This Row],[Item '#]],Data2!A:D,4,0) -> #N/A | O37: =VLOOKUP(Table1[[#This Row],[Item '#]],Data2!A:D,3,0) -> #N/A | P37: =VLOOKUP(Table1[[#This Row],[Item '#]],[2]Sheet1!$B:$D,3,0) -> #N/A | Q37: =[8]!Table1[[#This Row],[Current WH Inventory]]=VLOOKUP(Table1[[#This Row],[Item '#]],[2]Sheet1!$B:$D,3,0) -> #REF!
D38: =VLOOKUP(Table1[[#This Row],[SKU]],Data1!A:B,2,0) -> #N/A | E38: =Table1[[#This Row],[UoM]]*Table1[[#This Row],[Recommended Replenishment Qty]] -> #N/A | F38: =Table1[[#This Row],[Total EA (Transfer to WH06)]]/Table1[[#This Row],[UoM]] -> #N/A | G38: =Table1[[#This Row],[Total EA (Transfer to WH06)]]/Table1[[#This Row],[BOX]] -> #N/A | H38: =Table1[[#This Row],[Total EA (Transfer to WH06)]]/Table1[[#This Row],[CASE]] -> #N/A | I38: =Table1[[#This Row],[Sellable Unit/Set/box to ship]]/Table1[[#This Row],[Box to pull]] -> #N/A | J38: =IF(ISNUMBER(SEARCH("FNSKU",K38)),"Labeling","") | K38: =VLOOKUP(Table1[[#This Row],[SKU]],Instruction!A:F,6,0) -> #N/A | L38: =VLOOKUP(Table1[[#This Row],[ASIN]],'[1]2024'!$A:$AB,28,0) -> #N/A | M38: =VLOOKUP(Table1[[#This Row],[SKU]],Data1!A:C,3,0) -> #N/A | N38: =VLOOKUP(Table1[[#This Row],[Item '#]],Data2!A:D,4,0) -> #N/A | O38: =VLOOKUP(Table1[[#This Row],[Item '#]],Data2!A:D,3,0) -> #N/A | P38: =VLOOKUP(Table1[[#This Row],[Item '#]],[2]Sheet1!$B:$D,3,0) -> #N/A | Q38: =[8]!Table1[[#This Row],[Current WH Inventory]]=VLOOKUP(Table1[[#This Row],[Item '#]],[2]Sheet1!$B:$D,3,0) -> #REF!
D39: =VLOOKUP(Table1[[#This Row],[SKU]],Data1!A:B,2,0) -> #N/A | E39: =Table1[[#This Row],[UoM]]*Table1[[#This Row],[Recommended Replenishment Qty]] -> #N/A | F39: =Table1[[#This Row],[Total EA (Transfer to WH06)]]/Table1[[#This Row],[UoM]] -> #N/A | G39: =Table1[[#This Row],[Total EA (Transfer to WH06)]]/Table1[[#This Row],[BOX]] -> #N/A | H39: =Table1[[#This Row],[Total EA (Transfer to WH06)]]/Table1[[#This Row],[CASE]] -> #N/A | I39: =Table1[[#This Row],[Sellable Unit/Set/box to ship]]/Table1[[#This Row],[Case to pull]] -> #N/A | J39: =IF(ISNUMBER(SEARCH("FNSKU",K39)),"Labeling","") | K39: =VLOOKUP(Table1[[#This Row],[SKU]],Instruction!A:F,6,0) -> #N/A | L39: =VLOOKUP(Table1[[#This Row],[ASIN]],'[1]2024'!$A:$AB,28,0) -> #N/A | M39: =VLOOKUP(Table1[[#This Row],[SKU]],Data1!A:C,3,0) -> #N/A | N39: =VLOOKUP(Table1[[#This Row],[Item '#]],Data2!A:D,4,0) -> #N/A | O39: =VLOOKUP(Table1[[#This Row],[Item '#]],Data2!A:D,3,0) -> #N/A | P39: =VLOOKUP(Table1[[#This Row],[Item '#]],[2]Sheet1!$B:$D,3,0) -> #N/A | Q39: =[8]!Table1[[#This Row],[Current WH Inventory]]=VLOOKUP(Table1[[#This Row],[Item '#]],[2]Sheet1!$B:$D,3,0) -> #REF!
D40: =VLOOKUP(Table1[[#This Row],[SKU]],Data1!A:B,2,0) -> #N/A | E40: =Table1[[#This Row],[UoM]]*Table1[[#This Row],[Recommended Replenishment Qty]] -> #N/A | F40: =Table1[[#This Row],[Total EA (Transfer to WH06)]]/Table1[[#This Row],[UoM]] -> #N/A | G40: =Table1[[#This Row],[Total EA (Transfer to WH06)]]/Table1[[#This Row],[BOX]] -> #N/A | H40: =Table1[[#This Row],[Total EA (Transfer to WH06)]]/Table1[[#This Row],[CASE]] -> #N/A | I40: =Table1[[#This Row],[Sellable Unit/Set/box to ship]]/Table1[[#This Row],[Case to pull]] -> #N/A | J40: =IF(ISNUMBER(SEARCH("FNSKU",K40)),"Labeling","") | K40: =VLOOKUP(Table1[[#This Row],[SKU]],Instruction!A:F,6,0) -> #N/A | L40: =VLOOKUP(Table1[[#This Row],[ASIN]],'[1]2024'!$A:$AB,28,0) -> #N/A | M40: =VLOOKUP(Table1[[#This Row],[SKU]],Data1!A:C,3,0) -> #N/A | N40: =VLOOKUP(Table1[[#This Row],[Item '#]],Data2!A:D,4,0) -> #N/A | O40: =VLOOKUP(Table1[[#This Row],[Item '#]],Data2!A:D,3,0) -> #N/A | P40: =VLOOKUP(Table1[[#This Row],[Item '#]],[2]Sheet1!$B:$D,3,0) -> #N/A | Q40: =[8]!Table1[[#This Row],[Current WH Inventory]]=VLOOKUP(Table1[[#This Row],[Item '#]],[2]Sheet1!$B:$D,3,0) -> #REF!
D41: =VLOOKUP(Table1[[#This Row],[SKU]],Data1!A:B,2,0) -> #N/A | E41: =Table1[[#This Row],[UoM]]*Table1[[#This Row],[Recommended Replenishment Qty]] -> #N/A | F41: =Table1[[#This Row],[Total EA (Transfer to WH06)]]/Table1[[#This Row],[UoM]] -> #N/A | G41: =Table1[[#This Row],[Total EA (Transfer to WH06)]]/Table1[[#This Row],[BOX]] -> #N/A | H41: =Table1[[#This Row],[Total EA (Transfer to WH06)]]/Table1[[#This Row],[CASE]] -> #N/A | I41: =Table1[[#This Row],[Sellable Unit/Set/box to ship]]/Table1[[#This Row],[Case to pull]] -> #N/A | J41: =IF(ISNUMBER(SEARCH("FNSKU",K41)),"Labeling","") | K41: =VLOOKUP(Table1[[#This Row],[SKU]],Instruction!A:F,6,0) -> #N/A | L41: =VLOOKUP(Table1[[#This Row],[ASIN]],'[1]2024'!$A:$AB,28,0) -> #N/A | M41: =VLOOKUP(Table1[[#This Row],[SKU]],Data1!A:C,3,0) -> #N/A | N41: =VLOOKUP(Table1[[#This Row],[Item '#]],Data2!A:D,4,0) -> #N/A | O41: =VLOOKUP(Table1[[#This Row],[Item '#]],Data2!A:D,3,0) -> #N/A | P41: =VLOOKUP(Table1[[#This Row],[Item '#]],[2]Sheet1!$B:$D,3,0) -> #N/A | Q41: =[8]!Table1[[#This Row],[Current WH Inventory]]=VLOOKUP(Table1[[#This Row],[Item '#]],[2]Sheet1!$B:$D,3,0) -> #REF!
D42: =VLOOKUP(Table1[[#This Row],[SKU]],Data1!A:B,2,0) -> #N/A | E42: =Table1[[#This Row],[UoM]]*Table1[[#This Row],[Recommended Replenishment Qty]] -> #N/A | F42: =Table1[[#This Row],[Total EA (Transfer to WH06)]]/Table1[[#This Row],[UoM]] -> #N/A | G42: =Table1[[#This Row],[Total EA (Transfer to WH06)]]/Table1[[#This Row],[BOX]] -> #N/A | H42: =Table1[[#This Row],[Total EA (Transfer to WH06)]]/Table1[[#This Row],[CASE]] -> #N/A | I42: =Table1[[#This Row],[Sellable Unit/Set/box to ship]]/Table1[[#This Row],[Case to pull]] -> #N/A | J42: =IF(ISNUMBER(SEARCH("FNSKU",K42)),"Labeling","") | K42: =VLOOKUP(Table1[[#This Row],[SKU]],Instruction!A:F,6,0) -> #N/A | L42: =VLOOKUP(Table1[[#This Row],[ASIN]],'[1]2024'!$A:$AB,28,0) -> #N/A | M42: =VLOOKUP(Table1[[#This Row],[SKU]],Data1!A:C,3,0) -> #N/A | N42: =VLOOKUP(Table1[[#This Row],[Item '#]],Data2!A:D,4,0) -> #N/A | O42: =VLOOKUP(Table1[[#This Row],[Item '#]],Data2!A:D,3,0) -> #N/A | P42: =VLOOKUP(Table1[[#This Row],[Item '#]],[2]Sheet1!$B:$D,3,0) -> #N/A | Q42: =[8]!Table1[[#This Row],[Current WH Inventory]]=VLOOKUP(Table1[[#This Row],[Item '#]],[2]Sheet1!$B:$D,3,0) -> #REF!
D43: =VLOOKUP(Table1[[#This Row],[SKU]],Data1!A:B,2,0) -> #N/A | E43: =Table1[[#This Row],[UoM]]*Table1[[#This Row],[Recommended Replenishment Qty]] -> #N/A | F43: =Table1[[#This Row],[Total EA (Transfer to WH06)]]/Table1[[#This Row],[UoM]] -> #N/A | G43: =Table1[[#This Row],[Total EA (Transfer to WH06)]]/Table1[[#This Row],[BOX]] -> #N/A | H43: =Table1[[#This Row],[Total EA (Transfer to WH06)]]/Table1[[#This Row],[CASE]] -> #N/A | I43: =Table1[[#This Row],[Sellable Unit/Set/box to ship]]/Table1[[#This Row],[Case to pull]] -> #N/A | J43: =IF(ISNUMBER(SEARCH("FNSKU",K43)),"Labeling","") | K43: =VLOOKUP(Table1[[#This Row],[SKU]],Instruction!A:F,6,0) -> #N/A | L43: =VLOOKUP(Table1[[#This Row],[ASIN]],'[1]2024'!$A:$AB,28,0) -> #N/A | M43: =VLOOKUP(Table1[[#This Row],[SKU]],Data1!A:C,3,0) -> #N/A | N43: =VLOOKUP(Table1[[#This Row],[Item '#]],Data2!A:D,4,0) -> #N/A | O43: =VLOOKUP(Table1[[#This Row],[Item '#]],Data2!A:D,3,0) -> #N/A | P43: =VLOOKUP(Table1[[#This Row],[Item '#]],[2]Sheet1!$B:$D,3,0) -> #N/A | Q43: =[8]!Table1[[#This Row],[Current WH Inventory]]=VLOOKUP(Table1[[#This Row],[Item '#]],[2]Sheet1!$B:$D,3,0) -> #REF!
D44: =VLOOKUP(Table1[[#This Row],[SKU]],Data1!A:B,2,0) -> #N/A | E44: =Table1[[#This Row],[UoM]]*Table1[[#This Row],[Recommended Replenishment Qty]] -> #N/A | F44: =Table1[[#This Row],[Total EA (Transfer to WH06)]]/Table1[[#This Row],[UoM]] -> #N/A | G44: =Table1[[#This Row],[Total EA (Transfer to WH06)]]/Table1[[#This Row],[BOX]] -> #N/A | H44: =Table1[[#This Row],[Total EA (Transfer to WH06)]]/Table1[[#This Row],[CASE]] -> #N/A | I44: =Table1[[#This Row],[Sellable Unit/Set/box to ship]]/Table1[[#This Row],[Case to pull]] -> #N/A | J44: =IF(ISNUMBER(SEARCH("FNSKU",K44)),"Labeling","") | K44: =VLOOKUP(Table1[[#This Row],[SKU]],Instruction!A:F,6,0) -> #N/A | L44: =VLOOKUP(Table1[[#This Row],[ASIN]],'[1]2024'!$A:$AB,28,0) -> #N/A | M44: =VLOOKUP(Table1[[#This Row],[SKU]],Data1!A:C,3,0) -> #N/A | N44: =VLOOKUP(Table1[[#This Row],[Item '#]],Data2!A:D,4,0) -> #N/A | O44: =VLOOKUP(Table1[[#This Row],[Item '#]],Data2!A:D,3,0) -> #N/A | P44: =VLOOKUP(Table1[[#This Row],[Item '#]],[2]Sheet1!$B:$D,3,0) -> #N/A | Q44: =[8]!Table1[[#This Row],[Current WH Inventory]]=VLOOKUP(Table1[[#This Row],[Item '#]],[2]Sheet1!$B:$D,3,0) -> #REF!
D45: =VLOOKUP(Table1[[#This Row],[SKU]],Data1!A:B,2,0) -> #N/A | E45: =Table1[[#This Row],[UoM]]*Table1[[#This Row],[Recommended Replenishment Qty]] -> #N/A | F45: =Table1[[#This Row],[Total EA (Transfer to WH06)]]/Table1[[#This Row],[UoM]] -> #N/A | G45: =Table1[[#This Row],[Total EA (Transfer to WH06)]]/Table1[[#This Row],[BOX]] -> #N/A | H45: =Table1[[#This Row],[Total EA (Transfer to WH06)]]/Table1[[#This Row],[CASE]] -> #N/A | I45: =Table1[[#This Row],[Sellable Unit/Set/box to ship]]/Table1[[#This Row],[Case to pull]] -> #N/A | J45: =IF(ISNUMBER(SEARCH("FNSKU",K45)),"Labeling","") | K45: =VLOOKUP(Table1[[#This Row],[SKU]],Instruction!A:F,6,0) -> #N/A | L45: =VLOOKUP(Table1[[#This Row],[ASIN]],'[1]2024'!$A:$AB,28,0) -> #N/A | M45: =VLOOKUP(Table1[[#This Row],[SKU]],Data1!A:C,3,0) -> #N/A | N45: =VLOOKUP(Table1[[#This Row],[Item '#]],Data2!A:D,4,0) -> #N/A | O45: =VLOOKUP(Table1[[#This Row],[Item '#]],Data2!A:D,3,0) -> #N/A | P45: =VLOOKUP(Table1[[#This Row],[Item '#]],[2]Sheet1!$B:$D,3,0) -> #N/A | Q45: =[8]!Table1[[#This Row],[Current WH Inventory]]=VLOOKUP(Table1[[#This Row],[Item '#]],[2]Sheet1!$B:$D,3,0) -> #REF!
D46: =VLOOKUP(Table1[[#This Row],[SKU]],Data1!A:B,2,0) -> #N/A | E46: =Table1[[#This Row],[UoM]]*Table1[[#This Row],[Recommended Replenishment Qty]] -> #N/A | F46: =Table1[[#This Row],[Total EA (Transfer to WH06)]]/Table1[[#This Row],[UoM]] -> #N/A | G46: =Table1[[#This Row],[Total EA (Transfer to WH06)]]/Table1[[#This Row],[BOX]] -> #N/A | H46: =Table1[[#This Row],[Total EA (Transfer to WH06)]]/Table1[[#This Row],[CASE]] -> #N/A | I46: =Table1[[#This Row],[Sellable Unit/Set/box to ship]]/Table1[[#This Row],[Case to pull]] -> #N/A | J46: =IF(ISNUMBER(SEARCH("FNSKU",K46)),"Labeling","") | K46: =VLOOKUP(Table1[[#This Row],[SKU]],Instruction!A:F,6,0) -> #N/A | L46: =VLOOKUP(Table1[[#This Row],[ASIN]],'[1]2024'!$A:$AB,28,0) -> #N/A | M46: =VLOOKUP(Table1[[#This Row],[SKU]],Data1!A:C,3,0) -> #N/A | N46: =VLOOKUP(Table1[[#This Row],[Item '#]],Data2!A:D,4,0) -> #N/A | O46: =VLOOKUP(Table1[[#This Row],[Item '#]],Data2!A:D,3,0) -> #N/A | P46: =VLOOKUP(Table1[[#This Row],[Item '#]],[2]Sheet1!$B:$D,3,0) -> #N/A | Q46: =[8]!Table1[[#This Row],[Current WH Inventory]]=VLOOKUP(Table1[[#This Row],[Item '#]],[2]Sheet1!$B:$D,3,0) -> #REF!
D47: =VLOOKUP(Table1[[#This Row],[SKU]],Data1!A:B,2,0) -> #N/A | E47: =Table1[[#This Row],[UoM]]*Table1[[#This Row],[Recommended Replenishment Qty]] -> #N/A | F47: =Table1[[#This Row],[Total EA (Transfer to WH06)]]/Table1[[#This Row],[UoM]] -> #N/A | G47: =Table1[[#This Row],[Total EA (Transfer to WH06)]]/Table1[[#This Row],[BOX]] -> #N/A | H47: =Table1[[#This Row],[Total EA (Transfer to WH06)]]/Table1[[#This Row],[CASE]] -> #N/A | I47: =Table1[[#This Row],[Sellable Unit/Set/box to ship]]/Table1[[#This Row],[Box to pull]] -> #N/A | J47: =IF(ISNUMBER(SEARCH("FNSKU",K47)),"Labeling","") | K47: =VLOOKUP(Table1[[#This Row],[SKU]],Instruction!A:F,6,0) -> #N/A | L47: =VLOOKUP(Table1[[#This Row],[ASIN]],'[1]2024'!$A:$AB,28,0) -> #N/A | M47: =VLOOKUP(Table1[[#This Row],[SKU]],Data1!A:C,3,0) -> #N/A | N47: =VLOOKUP(Table1[[#This Row],[Item '#]],Data2!A:D,4,0) -> #N/A | O47: =VLOOKUP(Table1[[#This Row],[Item '#]],Data2!A:D,3,0) -> #N/A | P47: =VLOOKUP(Table1[[#This Row],[Item '#]],[2]Sheet1!$B:$D,3,0) -> #N/A | Q47: =[8]!Table1[[#This Row],[Current WH Inventory]]=VLOOKUP(Table1[[#This Row],[Item '#]],[2]Sheet1!$B:$D,3,0) -> #REF!
...

Sheet SO
F1: ATTENTION: AWD removal | G1: Qty | H1: Used
B2: Item# | C2: BOX | D2: CASE | F2: 5027-CASE | G2: 10 | H2: 1
B3: 203 | C3: 1
B4: 534 | C4: 1
B5: 713 | C5: 1
B6: 2012 | C6: 1
B7: 2225 | C7: 1
B8: 609 | C8: 2
B9: 767 | C9: 2
B10: 1293 | C10: 2
B11: 2204 | C11: 2
B12: 2043 | C12: 3
B13: 5074 | C13: 3
B14: S-2 | C14: 4
B15: 837 | C15: 5
B16: 508 | D16: 1
B17: 530 | D17: 1
B18: 569 | D18: 1
B19: 1286 | D19: 1
B20: 2405 | D20: 1
B21: 4151 | D21: 1
B22: 5053 | D22: 1
B23: 5087 | D23: 1
B24: 5173 | D24: 1
B25: 6303 | D25: 1
B26: 533 | D26: 2
B27: 608 | D27: 2
... B46: 4122 | D46: 4
B47: 942-A | D47: 4
B48: 560 | D48: 5
B49: 609 | D49: 5
B50: 5027 | D50: 5
B51: 5043 | D51: 5
B52: 4576436 | D52: 5
B53: 3459-A | D53: 5
B54: 532 | D54: 6
B55: 39200 | D55: 6
B56: 3451 | D56: 8
B57: 3191 | D57: 9
B58: 3467 | D58: 9
...

Sheet Sheet1
A1: Workflow name | B1: wf9547a679-894d-4f41-afc0-a2dbe4aa3f05
A2: Shipment ID | B2: STAR-VKFAPNKKS6S4A
A3: Shipment name | B3: To be assigned
A4: Ship to | B4: NORTH EAST, MD
A5: Boxes | B5: 241
A6: SKUs | B6: 72
A7: Units | B7: 4352
A9: Case packed (241 boxes)
A10: SKU | B10: Title | C10: ASIN | D10: FNSKU | E10: Case pack template name | F10: Condition | G10: Who preps units? | H10: Who labels units? | I10: Prep type | J10: Box weight (lb) | K10: Box length (inch) | L10: Box width (inch) | M10: Box height (inch) | N10: Units per box | O10: Total boxes | P10: Total units | Q10: Box ID
A11: FBA_533-BOX | B11: BAZIC Subtraction Flash Cards, Numbers Math Flashcards Game at School Home, Problem Solving (36/Pack), 24-Packs | C11: B07XQLGMSV | D11: X0044RLXAR | E11: Case (3 boxes) | F11: New | G11: By seller | H11: By seller | I11: No prep needed | J11: 16.4 | K11: 7 | L11: 12 | M11: 11 | N11: 3 | O11: 2 | P11: 6 | Q11: To be assigned
A12: FBA_508-EACH | B12: BAZIC Composition Book Wide Ruled 100 Sheet Black Marble Notebook, Writing Journal Comp Lined Notebooks for School, 1-Pack | C12: B001E75OY0 | D12: B001E75OY0 | E12: ASDN_DEFAULT_CONFIG | F12: New | G12: By seller | H12: - | I12: No prep needed | J12: 31.8 | K12: 15.5 | L12: 10 | M12: 8.5 | N12: 48 | O12: 1 | P12: 48 | Q12: To be assigned
A13: FBA_3107-BOX | B13: BAZIC Binder Dividers w/ 10 Color Tabs 8. 5" x 11", 11 Hole Punch Plastic Index Divider with Tab for 3 Ring Binders, (10/Pack), 24-Packs | C13: B07XQJZL28 | D13: X0045A6VWX | E13: Case (6 boxes) | F13: New | G13: By seller | H13: By seller | I13: No prep needed | J13: 37.6 | K13: 10 | L13: 15 | M13: 13 | N13: 6 | O13: 2 | P13: 12 | Q13: To be assigned
A14: FBA_942-A-EA-BL | B14: BAZIC Desktop Tape Dispenser w/Tape Refill 3/4" x 250", 1" Core Weighted Non-Skid Base, Sharpe Blade Tapes Holder, Blue Color, 1-Pack | C14: B0CV2WM9FJ | D14: X0044KCA65 | E14: Case (12) | F14: New | G14: By seller | H14: By seller | I14: No prep needed | J14: 20 | K14: 8 | L14: 12 | M14: 11 | N14: 12 | O14: 1 | P14: 12 | Q14: To be assigned
A15: FBA_3191-CASE | B15: BAZIC 3 Ring Binder 1" Economy View Binders Organizer - Blue, Round Ring, Hold 175 Sheets Paper, for School Office Home, 12-Count | C15: B07QF5ZS6P | D15: X003SBSJJN | E15: 1 Case | F15: New | G15: By seller | H15: By seller | I15: No prep needed | J15: 8.64 | K15: 6 | L15: 13.25 | M15: 12.25 | N15: 1 | O15: 9 | P15: 9 | Q15: To be assigned
A16: FBA_3467-EACH | B16: BAZIC Glitter Glue Tube Classic Color, Non-Toxic Washable Glitter Glue for Slime Paints DIY Art Crafts Party (120ml/Pack), 1-Pack | C16: B01HDJMKBM | D16: B01HDJMKBM | E16: Case (72) | F16: New | G16: By seller | H16: - | I16: No prep needed | J16: 30.58 | K16: 12 | L16: 13.5 | M16: 13.25 | N16: 72 | O16: 4 | P16: 288 | Q16: To be assigned
A17: FBA_3167-SET4 | B17: BAZIC 3 Ring Binder 1" Economy View Binders Organizer - Pastel Color, Round Ring, Hold 175 Sheets Paper, for School Office Home, 4-Count | C17: B08LP2FGJM | D17: X003BVZHKJ | E17: Case Pack (10 Sets) | F17: New | G17: - | H17: By seller | I17: No prep needed | J17: 28 | K17: 13 | L17: 19 | M17: 13 | N17: 10 | O17: 10 | P17: 100 | Q17: To be assigned
A18: FBA_609-PACK4 | B18: BAZIC Staples Standard (26/6) Metallic Color 3000/Pack, Stapler Refill Standard Size Staple, Assorted Colors, 4-Packs | C18: B09C2QNFTV | D18: X0044RLX89 | E18: Case (18) | F18: New | G18: By seller | H18: By seller | I18: No prep needed | J18: 17.08 | K18: 5 | L18: 14 | M18: 8 | N18: 18 | O18: 3 | P18: 54 | Q18: To be assigned
A19: FBA_5414-PACK3 | B19: BAZIC Poster Board Glitter Color 11" X 14", Sparkling Frame Colored Poster Board Paper for Christmas Wedding Birthday Craft Project (5/Pack), 3-Packs | C19: B08FZR2GLR | D19: X00468H3EJ | E19: ASDN_DEFAULT_CONFIG | F19: New | G19: By seller | H19: By seller | I19: No prep needed | J19: 19 | K19: 16 | L19: 15 | M19: 6 | N19: 16 | O19: 2 | P19: 32 | Q19: To be assigned
A20: FBA_4577036-SET2 | B20: Disney Princess Coloring Book 2 Titles, Fun Game Workbook for Learning Drawing Coloring, Gift for Kids Toddler Activity at Classroom Home, 80 Pages, 2-Pack | C20: B0897CBHTZ | D20: X004BHUY9L | E20: Case (18 Sets) | F20: New | G20: - | H20: By seller | I20: No prep needed | J20: 10.6 | K20: 4 | L20: 16 | M20: 11 | N20: 18 | O20: 2 | P20: 36 | Q20: To be assigned
A21: FBA_5043-PACK2 | B21: BAZIC Sketch Pad 50 Sheet 6" X 8", Top Bound Spiral Sketchbook Drawing Pads, Sketching Paper Coloring Book for Artist School, 2-Pack | C21: B08DFJW6V4 | D21: X0040DSNM1 | E21: Case (24) | F21: New | G21: By seller | H21: By seller | I21: No prep needed | J21: 22 | K21: 9.75 | L21: 12.75 | M21: 10 | N21: 24 | O21: 3 | P21: 72 | Q21: To be assigned
A22: FBA_2405-EACH | B22: BAZIC White Chalk, Standard Size Blackboard Chalkboard Chalks, Great Game Activity for Kids, Art Teacher Office School Home (24/Pack), 1-Pack | C22: B003BUK0UG | D22: B003BUK0UG | E22: ASDN_DEFAULT_CONFIG | F22: New | G22: By seller | H22: - | I22: No prep needed | J22: 15 | K22: 8 | L22: 6 | M22: 4 | N22: 24 | O22: 1 | P22: 24 | Q22: To be assigned
... A82: FBA_560-PACK6 | B82: BAZIC Writing Pad 100 Sheets 6" X 9", Lined Ruled Memo Writing Notebook, Easy Tear Note Paper for Office School Home, 6-Pack [unknown_binding] | C82: B08FBQM8VF | D82: X003SFDOWB | E82: ASDN_DEFAULT_CONFIG | F82: New | G82: By seller | H82: By seller | I82: No prep needed | J82: 30 | K82: 12 | L82: 13 | M82: 16 | N82: 8 | O82: 5 | P82: 40 | Q82: To be assigned

Sheet AWD Return
A1: SKU | B1: Item | C1: Qty (EA)
A2: 5027-EACH | B2: 5027 | C2: 480
A3: 560-EACH | B3: 560 | C3: =263-96 -> 167
A4: 3001-EACH | B4: 3001 | C4: 24

Sheet For WH Single
A1: SKU | B1: ASIN | C1: FNSKU | D1: Item | E1: Total EA (Transfer to WH06) | F1: Sellable Unit/Set/box to ship | G1: Box 1 units | H1: Box 2 units | I1: Label | J1: Packing Instructions | K1: Supplies | L1: UoM | M1: -- | N1: --2 | O1: Recommended Replenishment Qty | P1: Current WH Inventory
A2: 4403-SET6 | B2: B0BRNSWP12 | C2: X0043V3DCZ | D2: =VLOOKUP(A2,Data1!A:B,2,0) -> 4403 | E2: =L2*O2 -> 12 | F2: =O2 -> 2 | G2: 2 | I2: Labeling | J2: =VLOOKUP(A2,Instruction!A:F,7,0) -> #REF! | L2: =VLOOKUP(A2,Data1!A:C,3,0) -> 6 | O2: 2 | P2: =VLOOKUP(D2,[3]Sheet1!$B:$D,3,0) -> 10343
A3: 4400-SET2 | B3: B07SFT7P7X | C3: X0043UN7EF | D3: =VLOOKUP(A3,Data1!A:B,2,0) -> 4400 | E3: =L3*O3 -> 8 | F3: =O3 -> 4 | G3: 4 | I3: Labeling | J3: =VLOOKUP(A3,Instruction!A:F,7,0) -> #REF! | L3: =VLOOKUP(A3,Data1!A:C,3,0) -> 2 | O3: 4 | P3: =VLOOKUP(D3,[3]Sheet1!$B:$D,3,0) -> 28720
A4: 17036-EACH | B4: B0CQ66C7RL | C4: X0043UNGZ5 | D4: =VLOOKUP(A4,Data1!A:B,2,0) -> 17036 | E4: =L4*O4 -> 6 | F4: =O4 -> 6 | G4: 6 | I4: Labeling | J4: =VLOOKUP(A4,Instruction!A:F,7,0) -> #REF! | L4: =VLOOKUP(A4,Data1!A:C,3,0) -> 1 | O4: 6 | P4: =VLOOKUP(D4,[3]Sheet1!$B:$D,3,0) -> 19554
A5: 709-EACH | B5: B0CGW5J3SV | C5: X0043V3OBP | D5: =VLOOKUP(A5,Data1!A:B,2,0) -> 709 | E5: =L5*O5 -> 6 | F5: =O5 -> 6 | G5: 6 | I5: Labeling | J5: =VLOOKUP(A5,Instruction!A:F,7,0) -> #REF! | L5: =VLOOKUP(A5,Data1!A:C,3,0) -> 1 | O5: 6 | P5: =VLOOKUP(D5,[3]Sheet1!$B:$D,3,0) -> 2396
A6: 17035-EACH | B6: B0CQ67CVM7 | C6: X0043UZRXT | D6: =VLOOKUP(A6,Data1!A:B,2,0) -> 17035 | E6: =L6*O6 -> 6 | F6: =O6 -> 6 | G6: 6 | I6: Labeling | J6: =VLOOKUP(A6,Instruction!A:F,7,0) -> #REF! | L6: =VLOOKUP(A6,Data1!A:C,3,0) -> 1 | O6: 6 | P6: =VLOOKUP(D6,[3]Sheet1!$B:$D,3,0) -> 33166
A7: 914-EACH | B7: B07SKF1B25 | C7: X00446K72N | D7: =VLOOKUP(A7,Data1!A:B,2,0) -> 914 | E7: =L7*O7 -> 4 | F7: =O7 -> 4 | H7: 4 | I7: Labeling | J7: =VLOOKUP(A7,Instruction!A:F,7,0) -> #REF! | L7: =VLOOKUP(A7,Data1!A:C,3,0) -> 1 | O7: 4 | P7: =VLOOKUP(D7,[3]Sheet1!$B:$D,3,0) -> 32063
A8: 905-EACH | B8: B07SKD994F | C8: X0043UN5TH | D8: =VLOOKUP(A8,Data1!A:B,2,0) -> 905 | E8: =L8*O8 -> 4 | F8: =O8 -> 4 | H8: 4 | I8: Labeling | J8: =VLOOKUP(A8,Instruction!A:F,7,0) -> #REF! | L8: =VLOOKUP(A8,Data1!A:C,3,0) -> 1 | O8: 4 | P8: =VLOOKUP(D8,[3]Sheet1!$B:$D,3,0) -> 86003
A9: 1215-EACH | B9: B0CJMRSK5J | C9: X0043UN4H5 | D9: =VLOOKUP(A9,Data1!A:B,2,0) -> 1215 | E9: =L9*O9 -> 6 | F9: =O9 -> 6 | H9: 6 | I9: Labeling | J9: =VLOOKUP(A9,Instruction!A:F,7,0) -> #REF! | L9: =VLOOKUP(A9,Data1!A:C,3,0) -> 1 | O9: 6 | P9: =VLOOKUP(D9,[3]Sheet1!$B:$D,3,0) -> 10438
A10: 1227-EACH | B10: B08WPW8T92 | C10: X0043V3IBL | D10: =VLOOKUP(A10,Data1!A:B,2,0) -> 1227 | E10: =L10*O10 -> 6 | F10: =O10 -> 6 | H10: 6 | I10: Labeling | J10: =VLOOKUP(A10,Instruction!A:F,7,0) -> #REF! | L10: =VLOOKUP(A10,Data1!A:C,3,0) -> 1 | O10: 6 | P10: =VLOOKUP(D10,[3]Sheet1!$B:$D,3,0) -> 4391
A11: 992-EACH | B11: B08R6JJP2L | C11: X0043V3CT9 | D11: =VLOOKUP(A11,Data1!A:B,2,0) -> 992 | E11: =L11*O11 -> 4 | F11: =O11 -> 4 | H11: 4 | I11: Labeling | J11: =VLOOKUP(A11,Instruction!A:F,7,0) -> #REF! | L11: =VLOOKUP(A11,Data1!A:C,3,0) -> 1 | O11: 4 | P11: =VLOOKUP(D11,[3]Sheet1!$B:$D,3,0) -> 3003
A12: 6041-EACH | B12: B072LP49MC | C12: B072LP49MC | D12: =VLOOKUP(A12,Data1!A:B,2,0) -> 6041 | E12: =L12*O12 -> 4 | F12: =O12 -> 4 | G12: 4 | J12: =VLOOKUP(A12,Instruction!A:F,7,0) -> #REF! | L12: =VLOOKUP(A12,Data1!A:C,3,0) -> 1 | O12: 4 | P12: =VLOOKUP(D12,[3]Sheet1!$B:$D,3,0) -> 4235
A13: 2561-EACH | B13: B09QD62R6R | C13: B09QD62R6R | D13: =VLOOKUP(A13,Data1!A:B,2,0) -> 2561 | E13: =L13*O13 -> 6 | F13: =O13 -> 6 | G13: 6 | J13: =VLOOKUP(A13,Instruction!A:F,7,0) -> #REF! | L13: =VLOOKUP(A13,Data1!A:C,3,0) -> 1 | O13: 6 | P13: =VLOOKUP(D13,[3]Sheet1!$B:$D,3,0) -> 30774
A14: 768-EACH | B14: B005KQ9316 | C14: B005KQ9316 | D14: =VLOOKUP(A14,Data1!A:B,2,0) -> 768 | E14: =L14*O14 -> 4 | F14: =O14 -> 4 | G14: 4 | J14: =VLOOKUP(A14,Instruction!A:F,7,0) -> #REF! | L14: =VLOOKUP(A14,Data1!A:C,3,0) -> 1 | O14: 4 | P14: =VLOOKUP(D14,[3]Sheet1!$B:$D,3,0) -> 22194
A15: 1277-EACH | B15: B0B9P3TD4K | C15: B0B9P3TD4K | D15: =VLOOKUP(A15,Data1!A:B,2,0) -> 1277 | E15: =L15*O15 -> 6 | F15: =O15 -> 6 | G15: 6 | J15: =VLOOKUP(A15,Instruction!A:F,7,0) -> #REF! | L15: =VLOOKUP(A15,Data1!A:C,3,0) -> 1 | O15: 6 | P15: =VLOOKUP(D15,[3]Sheet1!$B:$D,3,0) -> 10417
A16: 120-EACH | B16: B003BS9G44 | C16: B003BS9G44 | D16: =VLOOKUP(A16,Data1!A:B,2,0) -> 120 | E16: =L16*O16 -> 6 | F16: =O16 -> 6 | H16: 6 | J16: =VLOOKUP(A16,Instruction!A:F,7,0) -> #REF! | L16: =VLOOKUP(A16,Data1!A:C,3,0) -> 1 | O16: 6 | P16: =VLOOKUP(D16,[3]Sheet1!$B:$D,3,0) -> 22529
A17: 3301-EACH | B17: B0CPRBHWH9 | C17: B0CPRBHWH9 | D17: =VLOOKUP(A17,Data1!A:B,2,0) -> 3301 | E17: =L17*O17 -> 4 | F17: =O17 -> 4 | H17: 4 | J17: =VLOOKUP(A17,Instruction!A:F,7,0) -> #REF! | L17: =VLOOKUP(A17,Data1!A:C,3,0) -> 1 | O17: 4 | P17: =VLOOKUP(D17,[3]Sheet1!$B:$D,3,0) -> 281
A18: 715-EACH | B18: B07S6D1VMB | C18: B07S6D1VMB | D18: =VLOOKUP(A18,Data1!A:B,2,0) -> 715 | E18: =L18*O18 -> 3 | F18: =O18 -> 3 | H18: 3 | J18: =VLOOKUP(A18,Instruction!A:F,7,0) -> #REF! | L18: =VLOOKUP(A18,Data1!A:C,3,0) -> 1 | O18: 3 | P18: =VLOOKUP(D18,[3]Sheet1!$B:$D,3,0) -> 1789
A19: 3300-EACH | B19: B0CPRPLLFH | C19: B0CPRPLLFH | D19: =VLOOKUP(A19,Data1!A:B,2,0) -> 3300 | E19: =L19*O19 -> 4 | F19: =O19 -> 4 | H19: 4 | J19: =VLOOKUP(A19,Instruction!A:F,7,0) -> #REF! | L19: =VLOOKUP(A19,Data1!A:C,3,0) -> 1 | O19: 4 | P19: =VLOOKUP(D19,[3]Sheet1!$B:$D,3,0) -> 832

Sheet AWD
A1: SKU | B1: ASIN | C1: FNSKU | D1: Item # | E1: Total EA (Transfer to WH06) | F1: Sellable Unit/Set/box to ship | G1: Box to pull | H1: Case to pull | I1: Sets per Box/Case | J1: Label | K1: Packing Instructions | L1: AWD Special | M1: Supplies | N1: UoM | O1: BOX | P1: CASE | Q1: Recommended Replenishment Qty | R1: Current WH Inventory
A2: 4147-EACH | B2: B07Q8SQSQF | C2: X003SBSJBL | D2: =VLOOKUP(Table13[[#This Row],[SKU]],Data1!A:B,2,0) -> 4147 | E2: =Table13[[#This Row],[UoM]]*Table13[[#This Row],[Recommended Replenishment Qty]] -> 156 | F2: =Table13[[#This Row],[Total EA (Transfer to WH06)]]/Table13[[#This Row],[UoM]] -> 156 | H2: =Table13[[#This Row],[Total EA (Transfer to WH06)]]/Table13[[#This Row],[CASE]] -> 13 | I2: =Table13[[#This Row],[Sellable Unit/Set/box to ship]]/Table13[[#This Row],[Case to pull]] -> 12 | J2: =IF(ISNUMBER(SEARCH("FNSKU",K2)),"Labeling","") -> Labeling | K2: =VLOOKUP(Table13[[#This Row],[SKU]],Instruction!A:F,6,0) -> • Use FNSKU to label each item (cover barcode). Apply outer box/case label accordingly to match item# (Cover all existing barcodes on the box/case) | L2: =VLOOKUP(Table13[[#This Row],[SKU]],Instruction!A:G,7,0) -> 0 | M2: =VLOOKUP(Table13[[#This Row],[ASIN]],'[1]2024'!$A:$AB,28,0) -> No Supplies | N2: =VLOOKUP(Table13[[#This Row],[SKU]],Data1!A:C,3,0) -> 1 | O2: =VLOOKUP(Table13[[#This Row],[Item '#]],Data2!A:D,4,0) -> 0 | P2: =VLOOKUP(Table13[[#This Row],[Item '#]],Data2!A:D,3,0) -> 12 | Q2: 156 | R2: =VLOOKUP(Table13[[#This Row],[Item '#]],[2]Sheet1!$B:$D,3,0) -> 5414
A3: 2306-EACH-1 | B3: B008ZHNN68 | C3: B008ZHNN68 | D3: =VLOOKUP(Table13[[#This Row],[SKU]],Data1!A:B,2,0) -> 2306 | E3: =Table13[[#This Row],[UoM]]*Table13[[#This Row],[Recommended Replenishment Qty]] -> 1440 | F3: =Table13[[#This Row],[Total EA (Transfer to WH06)]]/Table13[[#This Row],[UoM]] -> 1440 | H3: =Table13[[#This Row],[Total EA (Transfer to WH06)]]/Table13[[#This Row],[CASE]] -> 10 | I3: =Table13[[#This Row],[Sellable Unit/Set/box to ship]]/Table13[[#This Row],[Case to pull]] -> 144 | J3: =IF(ISNUMBER(SEARCH("FNSKU",K3)),"Labeling","") | K3: =VLOOKUP(Table13[[#This Row],[SKU]],Instruction!A:F,6,0) -> Cover inner box barcode. Apply outer case label accordingly to match item# (Cover barcodes on the case) | L3: =VLOOKUP(Table13[[#This Row],[SKU]],Instruction!A:G,7,0) -> 0 | M3: =VLOOKUP(Table13[[#This Row],[ASIN]],'[1]2024'!$A:$AB,28,0) -> No Supplies | N3: =VLOOKUP(Table13[[#This Row],[SKU]],Data1!A:C,3,0) -> 1 | O3: =VLOOKUP(Table13[[#This Row],[Item '#]],Data2!A:D,4,0) -> 24 | P3: =VLOOKUP(Table13[[#This Row],[Item '#]],Data2!A:D,3,0) -> 144 | Q3: 1440 | R3: =VLOOKUP(Table13[[#This Row],[Item '#]],[2]Sheet1!$B:$D,3,0) -> 10915
