Workbook

Sheet Inventory to Send
A1: Country | B1: Product Name | C1: FNSKU | D1: Merchant SKU | E1: ASIN | F1: Available | G1: Last 12 Month (30 day pace) | H1: Last 45 (30 day pacing) | I1: Last 14 (30 day pacing) | J1: Estimated 60 Day | K1: AWD Units Available | L1: New Inventory Required to Send | M1: Inventory to Send | N1: Inventory to Send from AWD | O1: FBA Days Remaining | P1: Do Not Send
A2: US | B2: BAZIC Products Date Stamper with Black Ink Pads for Stamping, 12 Years of Adjustable Dates, Ideal for Office, Shipping, Receiving, Accounting, Expiration Date Stamp, Due Dates - 1 Pack | C2: B08P3W6YN6 | D2: FBA_6301-EACH | E2: B08P3W6YN6 | F2: 6 | G2: 306.16776 | H2: 376.66685 | I2: 81.32 | J2: 753.33371 | K2: 0 | L2: 747.33371 | M2: 747.33371 | N2: 0 | O2: 0.31858391 | P2: =IFERROR(VLOOKUP(E2,'Do Not Send'!A:B,2,FALSE),"-") -> -
A3: US | B3: BAZIC Colored (12 Pcs) + White (12 Pcs) Chalk + Premium Chalkboard Eraser Bundle, Non-Toxic Kids Art Office Classroom Store Home, 1-Pack | C3: B003BUI01W | D3: FBA_2402-EACH | E3: B003BUI01W | F3: 213 | G3: 69.983553 | H3: 374.66685 | I3: 243.96 | J3: 749.33371 | K3: 0 | L3: 536.33371 | M3: 536.33371 | N3: 0 | O3: 11.370101 | P3: =IFERROR(VLOOKUP(E3,'Do Not Send'!A:B,2,FALSE),"-") -> -
A4: US | B4: BAZIC Ballpoint Pen Spencer Red Retractable Pen Soft Barrel Grip Pens, 1.0 mm Bold Point Smooth Writing, for Office School Teacher (5/Pack), 1-Pack | C4: B00FBOMTA4 | D4: FBA_17049-EACH | E4: B00FBOMTA4 | F4: 43 | G4: 100.65789 | H4: 234.00012 | I4: 391.62 | J4: 468.00023 | K4: 0 | L4: 425.00023 | M4: 425.00023 | N4: 0 | O4: 3.6752118 | P4: =IFERROR(VLOOKUP(E4,'Do Not Send'!A:B,2,FALSE),"-") -> -
A5: US | B5: BAZIC Mechanical Pencil Lead Refills HB 0.7mm (160 Count/Pack), Pencil Lead Refill, 1-Pack | C5: B00FBOIJMG | D5: FBA_781-EACH | E5: B00FBOIJMG | F5: 14 | G5: 53.865132 | H5: 212.66677 | I5: 250.38 | J5: 425.33355 | K5: 0 | L5: 411.33355 | M5: 411.33355 | N5: 0 | O5: 1.3166138 | P5: =IFERROR(VLOOKUP(E5,'Do Not Send'!A:B,2,FALSE),"-") -> -
A6: US | B6: BAZIC Products Plastic Ruler 6" 15 cm, Transparent Assorted Color Measuring Tool with Inches & Centimeters, Durable Plastic Rulers for, School, Office, and Home, 3/Pack, 1-Pack | C6: B07S4BSLL5 | D6: FBA_338-EACH | E6: B07S4BSLL5 | F6: 24 | G6: 66.036184 | H6: 189.33343 | I6: 94.16 | J6: 378.66686 | K6: 0 | L6: 354.66686 | M6: 354.66686 | N6: 0 | O6: 2.53521 | P6: =IFERROR(VLOOKUP(E6,'Do Not Send'!A:B,2,FALSE),"-") -> -
A7: US | B7: BAZIC Products Wooden Ruler 12" (30cm), Singel Metal Edge, Inches Centimeter Metric Measuring Drafting Rulers, for Students School Supplies (3/Pack), 1-Pack | C7: B003BMX6SC | D7: FBA_306-EACH | E7: B003BMX6SC | F7: 49 | G7: 67.105263 | H7: 196.0001 | I7: 147.66 | J7: 392.0002 | K7: 0 | L7: 343.0002 | M7: 343.0002 | N7: 0 | O7: 4.9999975 | P7: =IFERROR(VLOOKUP(E7,'Do Not Send'!A:B,2,FALSE),"-") -> -
A8: US | B8: BAZIC Staples Standard (26/6) Metallic Color 3000/Pack, Stapler Refill Standard Size Staple, Assorted Colors, 1-Pack | C8: B00ESWRD10 | D8: FBA_609-EACH | E8: B00ESWRD10 | F8: 225 | G8: 46.052632 | H8: 266.00013 | I8: 368.08 | J8: 532.00027 | K8: 0 | L8: 307.00027 | M8: 307.00027 | N8: 0 | O8: 16.917285 | P8: =IFERROR(VLOOKUP(E8,'Do Not Send'!A:B,2,FALSE),"-") -> -
A9: US | B9: BAZIC Products Book Wrap - Clear Book Cover Self Adhesive Book Protector for Book Covers for Paperbacks, Plastic Cover for Books, Clear Contact Paper Peel and Stick, 17.5" x 1.7 Yard Roll, 1-Roll | C9: B076F13SG5 | D9: FBA_2901-EACH | E9: B076F13SG5 | F9: 455 | G9: 310.77303 | H9: 380.66686 | I9: 346.68 | J9: 761.33371 | K9: 0 | L9: 306.33371 | M9: 306.33371 | N9: 0 | O9: 23.905417 | P9: =IFERROR(VLOOKUP(E9,'Do Not Send'!A:B,2,FALSE),"-") -> -
A10: US | B10: BAZIC Products Paid Self-Inking Stamp with Red Ink for Office, Business, and Documents, Easy Refillable Pad, Crisp & Clear Impressions, 1-Pack | C10: B08P3WZTXG | D10: FBA_6303-EACH | E10: B08P3WZTXG | F10: 144 | G10: 96.134868 | H10: 189.33343 | I10: 53.5 | J10: 378.66686 | K10: 0 | L10: 234.66686 | M10: 234.66686 | N10: 0 | O10: 15.21126 | P10: =IFERROR(VLOOKUP(E10,'Do Not Send'!A:B,2,FALSE),"-") -> -
A11: US | B11: BAZIC Products Open Closed Signs for Business, Double-sided Vinyl Open Signs for Business Window With Will Return Clock Sign, Be Back Sign With Clock, Ideal for Businesses, Shop, Office & More, 7.5"X9" 1-pack | C11: X003GYE2EX | D11: FBA_4398-EACH | E11: B07SFKBQ7F | F11: 3 | G11: 181.82566 | H11: 100.66672 | I11: 21.4 | J11: 201.33343 | K11: 0 | L11: 198.33343 | M11: 198.33343 | N11: 0 | O11: 0.59602619 | P11: =IFERROR(VLOOKUP(E11,'Do Not Send'!A:B,2,FALSE),"-") -> -
A12: US | B12: BAZIC Invisible Tape w/Dispenser 3/4" X 500", Matte Finish Stationery Tapes Rolls, for Arts Craft Photo Gift Wrapping, (3/Pack), 1-Pack | C12: B0018ML7KG | D12: FBA_903-EACH | E12: B0018ML7KG | F12: 291 | G12: 135.85526 | H12: 240.00012 | I12: 64.2 | J12: 480.00024 | K12: 0 | L12: 189.00024 | M12: 189.00024 | N12: 0 | O12: 24.249988 | P12: =IFERROR(VLOOKUP(E12,'Do Not Send'!A:B,2,FALSE),"-") -> -
A13: US | B13: BAZIC Products Assorted Color Gel Pencil Grip Pen Grip, Finger Grip Pencil Holder, Style May Vary (8/Pack), Pack of 1 | C13: B002WFI620 | D13: FBA_1502-EACH | E13: B002WFI620 | F13: 470 | G13: 49.506579 | H13: 325.3335 | I13: 524.3 | J13: 650.66699 | K13: 0 | L13: 180.66699 | M13: 180.66699 | N13: 0 | O13: 28.893428 | P13: =IFERROR(VLOOKUP(E13,'Do Not Send'!A:B,2,FALSE),"-") -> -
... A162: US | B162: BAZIC Products Chalk Board Eraser, Wood Felt Blackboard and White Board Eraser – Durable Cleaner for Classroom, Office, or Home Use, 4-Packs | C162: X003L8SD9T | D162: FBA_6003-PACK4 | E162: B08JHHM6KN | F162: 11 | G162: 3.125 | H162: 9.333338 | I162: 10.7 | J162: 18.666676 | K162: 36 | L162: 7.666676 | M162: 0 | N162: 7.666676 | O162: 23.571417 | P162: =IFERROR(VLOOKUP(E162,'Do Not Send'!A:B,2,FALSE),"-") -> -

Sheet BoxCase Inventory to Send
A1: Country | B1: Product Name | C1: FNSKU | D1: Merchant SKU | E1: ASIN | F1: Available | G1: Last 12 Month (30 day pace) | H1: Last 45 (30 day pacing) | I1: Last 14 (30 day pacing) | J1: Estimated 60 Day | K1: AWD Units Available | L1: New Inventory Required to Send | M1: Inventory to Send | N1: Inventory to Send from AWD | O1: FBA Days Remaining | P1: Do Not Send
A2: US | B2: BAZIC Products Composition Notebook Wide Ruled - 20 Sheets, Manila Color Composition Notebook with Durable Cover, Non-Spiral and Lined Paper for Journaling, School, Home, or Office, 24-Packs | C2: X003GHJQB9 | D2: FBA_5096-BOX | E2: B07XL4V3N1 | F2: 6 | G2: 42.680921 | H2: 44.000022 | I2: 27.82 | J2: 88.000044 | K2: 0 | L2: 82.000044 | M2: 82.000044 | N2: 0 | O2: 2.7272714 | P2: BOX/CASE PACK - TEMORARY DON'T SEND
A3: US | B3: BAZIC Products Multiplication Flash Cards, Numbers Elementary Math Flashcards Game at School, Problem Solving (36/Pack), 24-Packs | C3: X0044RLX07 | D3: FBA_534-BOX | E3: B07XQKHYRP | F3: 0 | G3: 49.588816 | H3: 38.000019 | I3: 55.64 | J3: 76.000038 | K3: 0 | L3: 76.000038 | M3: 76.000038 | N3: 0 | O3: 0 | P3: BOX/CASE PACK - TEMORARY DON'T SEND
A4: US | B4: BAZIC Products Composition Notebook 100 Sheet 5" x 7" Poly Cover Spiral Notebook, Writing Journal Notebook Mini Pocket Notebooks Assorted Color, 36-Pack | C4: X0040DSASN | D4: FBA_5476-CASE | E4: B0964J2MQ5 | F4: 0 | G4: 17.023026 | H4: 38.000019 | I4: 44.94 | J4: 76.000038 | K4: 0 | L4: 76.000038 | M4: 76.000038 | N4: 0 | O4: 0 | P4: BOX/CASE PACK - TEMORARY DON'T SEND
A5: US | B5: BAZIC Products Subtraction Flash Cards, Numbers Math Flashcards Game at School Home, Problem Solving (36/Pack), 24-Packs | C5: X0044RLXAR | D5: FBA_533-BOX | E5: B07XQLGMSV | F5: 0 | G5: 32.8125 | H5: 33.33335 | I5: 49.22 | J5: 66.6667 | K5: 0 | L5: 66.6667 | M5: 66.6667 | N5: 0 | O5: 0 | P5: BOX/CASE PACK - TEMORARY DON'T SEND
A6: US | B6: BAZIC Products Multiplication Flash Cards, Numbers Elementary Math Flashcards Game at School, Problem Solving (36/Pack), 72-Packs | C6: X0044R3MNN | D6: FBA_534-CASE | E6: B09NMXGBYP | F6: 0 | G6: 21.052632 | H6: 32.000016 | I6: 47.08 | J6: 64.000032 | K6: 0 | L6: 64.000032 | M6: 64.000032 | N6: 0 | O6: 0 | P6: BOX/CASE PACK - TEMORARY DON'T SEND
A7: US | B7: BAZIC Products Composition Notebook Wide Ruled - 20 Sheets, Manila Color Composition Notebook with Durable Cover, Non-Spiral and Lined Paper for Journaling, School, Home, or Office, 24-Packs | C7: B00GKINMJ2 | D7: FBA_5096-BOX-1 | E7: B00GKINMJ2 | F7: 0 | G7: 49.671053 | H7: 29.333348 | I7: 19.26 | J7: 58.666696 | K7: 0 | L7: 58.666696 | M7: 58.666696 | N7: 0 | O7: 0 | P7: BOX/CASE PACK - TEMORARY DON'T SEND
A8: US | B8: BAZIC 1" Matte Color Poly 3-Ring Binder w/ Pocket for School, Home, or Office (Case of 48) (3132-48) | C8: B00275E9XU | D8: FBA_3132-CASE-B | E8: B00275E9XU | F8: 1 | G8: 10.279605 | H8: 20.666677 | I8: 40.66 | J8: 41.333354 | K8: 0 | L8: 40.333354 | M8: 40.333354 | N8: 0 | O8: 0.96774145 | P8: BOX/CASE PACK - TEMORARY DON'T SEND
A9: US | B9: BAZIC Products Trifold Poster Board – White Corrugated Cardboard Display Board for school projects, science fairs, photos, charts, and classroom presentations, 28" x 40", 30-Pack | C9: B07X576XMT | D9: FBA_5086-CASE | E9: B07X576XMT | F9: 0 | G9: 32.894737 | H9: 20.00001 | I9: 53.5 | J9: 40.00002 | K9: 0 | L9: 40.00002 | M9: 40.00002 | N9: 0 | O9: 0 | P9: BOX/CASE PACK - TEMORARY DON'T SEND
A10: US | B10: BAZIC Products Poster Board Green 22" X 28", Colored Poster Board Paper, Bulk Boards for School Craft Project Presentation Drawing Graphic Display, 25-Pack | C10: X003SC1YHV | D10: FBA_5017-CASE | E10: B07X22QHGF | F10: 0 | G10: 13.240132 | H10: 19.333343 | I10: 12.84 | J10: 38.666686 | K10: 0 | L10: 38.666686 | M10: 38.666686 | N10: 0 | O10: 0 | P10: BOX/CASE PACK - TEMORARY DON'T SEND
A11: US | B11: BAZIC Products 3 Ring Binder 1/2" Economy View Binders Organizer - Red, Round Ring, Hold 100 Sheets Paper, for School Office Home, 12-Count | C11: X0044RLTGZ | D11: FBA_4103-CASE | E11: B07QC4VQ8V | F11: 1 | G11: 16.282895 | H11: 17.333342 | I11: 0 | J11: 34.666684 | K11: 0 | L11: 33.666684 | M11: 33.666684 | N11: 0 | O11: 1.1538456 | P11: BOX/CASE PACK - TEMORARY DON'T SEND
A12: US | B12: BAZIC Products Purchase Order Book, 30 Sets 8 3/8" x 10 11/16" 2-Part Carbonless, White & Bound Wraparound Cover (50 Sets/Pack), 12-Packs | C12: X003SBSK29 | D12: FBA_5077-A-CASE | E12: B07XJZDPL5 | F12: 0 | G12: 10.9375 | H12: 16.000008 | I12: 23.54 | J12: 32.000016 | K12: 0 | L12: 32.000016 | M12: 32.000016 | N12: 0 | O12: 0 | P12: BOX/CASE PACK - TEMORARY DON'T SEND
A13: US | B13: BAZIC Products Addition Flash Cards, Numbers Math Flashcards Game at School Home, Problem Solving (36/Pack), 24-Packs | C13: X0044R3MFV | D13: FBA_532-BOX | E13: B07XQGFLTT | F13: 61 | G13: 43.256579 | H13: 44.000022 | I13: 77.04 | J13: 88.000044 | K13: 0 | L13: 27.000044 | M13: 27.000044 | N13: 0 | O13: 27.727259 | P13: BOX/CASE PACK - TEMORARY DON'T SEND
... A80: US | B80: BAZIC Products 3 Ring Binder 1" Economy View Binders Organizer - Purple, Round Ring, Hold 175 Sheets Paper, for School Office Home, 12-Count | C80: X003SC97LB | D80: FBA_4127-CASE | E80: B07QF61WN3 | F80: 2 | G80: 4.9342105 | H80: 1.333334 | I80: 2.14 | J80: 2.666668 | K80: 0 | L80: 0.666668 | M80: 0.666668 | N80: 0 | O80: 29.999985 | P80: BOX/CASE PACK - TEMORARY DON'T SEND

Sheet Do Not Send
A1: Asin | B1: NOTE
A2: B08FK9Z656 | B2: BOX/CASE PACK - TEMORARY DON'T SEND
A3: B07QF4V3CC | B3: BOX/CASE PACK - TEMORARY DON'T SEND
A4: B07XL4V3N1 | B4: BOX/CASE PACK - TEMORARY DON'T SEND
A5: B07XQJFXT3 | B5: BOX/CASE PACK - TEMORARY DON'T SEND
A6: B09NMSV1KG | B6: BOX/CASE PACK - TEMORARY DON'T SEND
A7: B07XQP9HMF | B7: BOX/CASE PACK - TEMORARY DON'T SEND
A8: B07SF72V1F | B8: BOX/CASE PACK - TEMORARY DON'T SEND
A9: B07YL8HJQL | B9: BOX/CASE PACK - TEMORARY DON'T SEND
A10: B07YL8PNHY | B10: BOX/CASE PACK - TEMORARY DON'T SEND
A11: B07SD8LDKN | B11: BOX/CASE PACK - TEMORARY DON'T SEND
A12: B07YL75NTZ | B12: BOX/CASE PACK - TEMORARY DON'T SEND
... A360: FBA_1263-EACH | B360: Dangerous Goods

Sheet Proposed FBA Skus
A1: (Child) ASIN | B1: FBA Sku Exists? | C1: Monthly Units Last 45 days | D1: AWD Inventory | E1: Total Inventory to Send | F1: Inventory to Send | G1: Inventory to Send from AWD | H1: Do Not Send
A2: B01HTYG3LE | B2: =IF(COUNTIF('FBA Inventory'!E:E, A2)>0,"Yes","No") -> Yes | C2: =IFERROR(VLOOKUP(A2,'2025 Pivot'!A:B,2,FALSE),0)*0.666667 -> 187.33343 | D2: =IFERROR(VLOOKUP(A2,AWD!D:G,4,FALSE),0) -> 0 | E2: =IF(H2="-", IF(B2="yes", "-", (IF(C2>4.99999,C2*2,"-"))), "-") -> - | F2: =IF(E2="-","-",E2-G2) -> - | G2: =IF(E2="-","-", IF(E2>D2,D2,E2)) -> - | H2: =IFERROR(VLOOKUP(A2,'Do Not Send'!A:B,2,FALSE),"-") -> -
A3: B0BG14KCKZ | B3: =IF(COUNTIF('FBA Inventory'!E:E, A3)>0,"Yes","No") -> Yes | C3: =IFERROR(VLOOKUP(A3,'2025 Pivot'!A:B,2,FALSE),0)*0.666667 -> 3490.0017 | D3: =IFERROR(VLOOKUP(A3,AWD!D:G,4,FALSE),0) -> 0 | E3: =IF(H3="-", IF(B3="yes", "-", (IF(C3>4.99999,C3*2,"-"))), "-") -> - | F3: =IF(E3="-","-",E3-G3) -> - | G3: =IF(E3="-","-", IF(E3>D3,D3,E3)) -> - | H3: =IFERROR(VLOOKUP(A3,'Do Not Send'!A:B,2,FALSE),"-") -> BTS ITEM - DON'T SEND
A4: B08P3W6YN6 | B4: =IF(COUNTIF('FBA Inventory'!E:E, A4)>0,"Yes","No") -> Yes | C4: =IFERROR(VLOOKUP(A4,'2025 Pivot'!A:B,2,FALSE),0)*0.666667 -> 706.66702 | D4: =IFERROR(VLOOKUP(A4,AWD!D:G,4,FALSE),0) -> 0 | E4: =IF(H4="-", IF(B4="yes", "-", (IF(C4>4.99999,C4*2,"-"))), "-") -> - | F4: =IF(E4="-","-",E4-G4) -> - | G4: =IF(E4="-","-", IF(E4>D4,D4,E4)) -> - | H4: =IFERROR(VLOOKUP(A4,'Do Not Send'!A:B,2,FALSE),"-") -> -
A5: B001BNW7QA | B5: =IF(COUNTIF('FBA Inventory'!E:E, A5)>0,"Yes","No") -> Yes | C5: =IFERROR(VLOOKUP(A5,'2025 Pivot'!A:B,2,FALSE),0)*0.666667 -> 2038.6677 | D5: =IFERROR(VLOOKUP(A5,AWD!D:G,4,FALSE),0) -> 0 | E5: =IF(H5="-", IF(B5="yes", "-", (IF(C5>4.99999,C5*2,"-"))), "-") -> - | F5: =IF(E5="-","-",E5-G5) -> - | G5: =IF(E5="-","-", IF(E5>D5,D5,E5)) -> - | H5: =IFERROR(VLOOKUP(A5,'Do Not Send'!A:B,2,FALSE),"-") -> DUPLICATE ASIN - MERGE BEFORE SENDING
A6: B07SFKBQ7F | B6: =IF(COUNTIF('FBA Inventory'!E:E, A6)>0,"Yes","No") -> Yes | C6: =IFERROR(VLOOKUP(A6,'2025 Pivot'!A:B,2,FALSE),0)*0.666667 -> 412.00021 | D6: =IFERROR(VLOOKUP(A6,AWD!D:G,4,FALSE),0) -> 0 | E6: =IF(H6="-", IF(B6="yes", "-", (IF(C6>4.99999,C6*2,"-"))), "-") -> - | F6: =IF(E6="-","-",E6-G6) -> - | G6: =IF(E6="-","-", IF(E6>D6,D6,E6)) -> - | H6: =IFERROR(VLOOKUP(A6,'Do Not Send'!A:B,2,FALSE),"-") -> -
A7: B076F13SG5 | B7: =IF(COUNTIF('FBA Inventory'!E:E, A7)>0,"Yes","No") -> Yes | C7: =IFERROR(VLOOKUP(A7,'2025 Pivot'!A:B,2,FALSE),0)*0.666667 -> 531.3336 | D7: =IFERROR(VLOOKUP(A7,AWD!D:G,4,FALSE),0) -> 0 | E7: =IF(H7="-", IF(B7="yes", "-", (IF(C7>4.99999,C7*2,"-"))), "-") -> - | F7: =IF(E7="-","-",E7-G7) -> - | G7: =IF(E7="-","-", IF(E7>D7,D7,E7)) -> - | H7: =IFERROR(VLOOKUP(A7,'Do Not Send'!A:B,2,FALSE),"-") -> -
A8: B01HDJMKBM | B8: =IF(COUNTIF('FBA Inventory'!E:E, A8)>0,"Yes","No") -> Yes | C8: =IFERROR(VLOOKUP(A8,'2025 Pivot'!A:B,2,FALSE),0)*0.666667 -> 156.00008 | D8: =IFERROR(VLOOKUP(A8,AWD!D:G,4,FALSE),0) -> 0 | E8: =IF(H8="-", IF(B8="yes", "-", (IF(C8>4.99999,C8*2,"-"))), "-") -> - | F8: =IF(E8="-","-",E8-G8) -> - | G8: =IF(E8="-","-", IF(E8>D8,D8,E8)) -> - | H8: =IFERROR(VLOOKUP(A8,'Do Not Send'!A:B,2,FALSE),"-") -> -
A9: B003BMX65A | B9: =IF(COUNTIF('FBA Inventory'!E:E, A9)>0,"Yes","No") -> Yes | C9: =IFERROR(VLOOKUP(A9,'2025 Pivot'!A:B,2,FALSE),0)*0.666667 -> 628.00031 | D9: =IFERROR(VLOOKUP(A9,AWD!D:G,4,FALSE),0) -> 0 | E9: =IF(H9="-", IF(B9="yes", "-", (IF(C9>4.99999,C9*2,"-"))), "-") -> - | F9: =IF(E9="-","-",E9-G9) -> - | G9: =IF(E9="-","-", IF(E9>D9,D9,E9)) -> - | H9: =IFERROR(VLOOKUP(A9,'Do Not Send'!A:B,2,FALSE),"-") -> -
A10: B0018ML7KG | B10: =IF(COUNTIF('FBA Inventory'!E:E, A10)>0,"Yes","No") -> Yes | C10: =IFERROR(VLOOKUP(A10,'2025 Pivot'!A:B,2,FALSE),0)*0.666667 -> 20.666677 | D10: =IFERROR(VLOOKUP(A10,AWD!D:G,4,FALSE),0) -> 0 | E10: =IF(H10="-", IF(B10="yes", "-", (IF(C10>4.99999,C10*2,"-"))), "-") -> - | F10: =IF(E10="-","-",E10-G10) -> - | G10: =IF(E10="-","-", IF(E10>D10,D10,E10)) -> - | H10: =IFERROR(VLOOKUP(A10,'Do Not Send'!A:B,2,FALSE),"-") -> -
A11: B0BCL7XWNT | B11: =IF(COUNTIF('FBA Inventory'!E:E, A11)>0,"Yes","No") -> Yes | C11: =IFERROR(VLOOKUP(A11,'2025 Pivot'!A:B,2,FALSE),0)*0.666667 -> 469.33357 | D11: =IFERROR(VLOOKUP(A11,AWD!D:G,4,FALSE),0) -> 0 | E11: =IF(H11="-", IF(B11="yes", "-", (IF(C11>4.99999,C11*2,"-"))), "-") -> - | F11: =IF(E11="-","-",E11-G11) -> - | G11: =IF(E11="-","-", IF(E11>D11,D11,E11)) -> - | H11: =IFERROR(VLOOKUP(A11,'Do Not Send'!A:B,2,FALSE),"-") -> -
A12: B0BCL6MSMS | B12: =IF(COUNTIF('FBA Inventory'!E:E, A12)>0,"Yes","No") -> Yes | C12: =IFERROR(VLOOKUP(A12,'2025 Pivot'!A:B,2,FALSE),0)*0.666667 -> 357.33351 | D12: =IFERROR(VLOOKUP(A12,AWD!D:G,4,FALSE),0) -> 0 | E12: =IF(H12="-", IF(B12="yes", "-", (IF(C12>4.99999,C12*2,"-"))), "-") -> - | F12: =IF(E12="-","-",E12-G12) -> - | G12: =IF(E12="-","-", IF(E12>D12,D12,E12)) -> - | H12: =IFERROR(VLOOKUP(A12,'Do Not Send'!A:B,2,FALSE),"-") -> -
A13: B00ZPRYV0I | B13: =IF(COUNTIF('FBA Inventory'!E:E, A13)>0,"Yes","No") -> Yes | C13: =IFERROR(VLOOKUP(A13,'2025 Pivot'!A:B,2,FALSE),0)*0.666667 -> 69.333368 | D13: =IFERROR(VLOOKUP(A13,AWD!D:G,4,FALSE),0) -> 0 | E13: =IF(H13="-", IF(B13="yes", "-", (IF(C13>4.99999,C13*2,"-"))), "-") -> - | F13: =IF(E13="-","-",E13-G13) -> - | G13: =IF(E13="-","-", IF(E13>D13,D13,E13)) -> - | H13: =IFERROR(VLOOKUP(A13,'Do Not Send'!A:B,2,FALSE),"-") -> -
... A2205: B0FTKWXTHX | B2205: =IF(COUNTIF('FBA Inventory'!E:E, A2205)>0,"Yes","No") -> Yes | C2205: =IFERROR(VLOOKUP(A2205,'2025 Pivot'!A:B,2,FALSE),0)*0.666667 -> 0 | D2205: =IFERROR(VLOOKUP(A2205,AWD!D:G,4,FALSE),0) -> 0 | E2205: =IF(H2205="-", IF(B2205="yes", "-", (IF(C2205>4.99999,C2205*2,"-"))), "-") -> - | F2205: =IF(E2205="-","-",E2205-G2205) -> - | G2205: =IF(E2205="-","-", IF(E2205>D2205,D2205,E2205)) -> - | H2205: =IFERROR(VLOOKUP(A2205,'Do Not Send'!A:B,2,FALSE),"-") -> -

Sheet Working Sheet
A1: Country | B1: Product Name | C1: Merchant SKU | D1: ASIN | E1: FNSKU | F1: Available | G1: 2024 BTS Units Sold | H1: 2025 BTS Units Sold | I1: Last 2 Months Units Sold | K1: Estimated Units Needed for 2026 BTS | L1: Est Inv on hand at BTS Start | M1: Total Inv to send | N1: AWD Units Available | O1: Inv to Send from AWD | P1: Inv to Send from Warehouse | Q1: 2025 BTS Sales as % of 2024 BTS Unit Sales | R1: New Inventory Required to Send | S1: Inventory to Send to FBA | T1: Inventory to Send from AWD | U1: FBA Days Remaining | V1: Condition | W1: Supplier | X1: Supplier part no. | Y1: Currency code | Z1: Price | AA1: Sales last 30 days | AB1: Units Sold Last 30 Days | AC1: Total Units | AD1: Inbound | AE1: Available | AF1: FC transfer | AG1: FC Processing | AH1: Customer Order | AI1: Unfulfillable | AJ1: Working | AK1: Shipped | AL1: Receiving | AM1: Fulfilled by | AN1: Total Days of Supply (including units from open shipments) | AO1: Days of Supply at Amazon Fulfillment Network | AP1: Alert | AQ1: Recommended replenishment qty | AR1: Recommended ship date | AS1: Recommended action | AT1: Unit storage size | AU1: Last 2 months sales as % of Estimated Need for 2026 BTS
A2: US | B2: BAZIC PRODUCTS Middle & High School Kit Supply Box, 65-Count Student Set for Grades 7–12, Complete School Supply Kit with Middle School Supplies, Organized Supply Box for Highschool, 1-Pack | C2: FBA_8006-CASE | D2: B0BG14KCKZ | E2: X003XE2C7F | F2: 0 | G2: 5151 | H2: 5235 | I2: 6 | J2: 15 | K2: 5235 | L2: 0 | M2: 5235 | N2: 0 | O2: 0 | P2: 5235 | Q2: 1.0163075 | R2: 5235 | S2: 5235 | T2: 0 | U2: 0 | V2: New | W2: BAZIC Products | Y2: USD | Z2: 42.89 | AA2: 0 | AB2: 0 | AC2: 0 | AD2: 0 | AE2: 0 | AF2: 0 | AG2: 0 | AH2: 0 | AI2: 0 | AJ2: 0 | AK2: 0 | AL2: 0 | AM2: Amazon | AN2: 0 | AO2: 0 | AP2: out_of_stock | AQ2: 80 | AR2: 46048 | AS2: Create shipping plan | AT2: 0.2911 ft3
A3: US | B3: BAZIC Products Pink Eraser, Latex Free Bevel Block Erasers, Large Size for Classroom, Office, and Art Use, Smooth Pencil Correction for Writing, Sketching, & Daily Tasks, 4/Pack, 1-Pack | C3: FBA_2227-EACH-UPC | D3: B001BNW7QA | E3: B001BNW7QA | F3: 8 | G3: 2399 | H3: 3058 | I3: 21 | J3: 52.5 | K3: 3058 | L3: 0 | M3: 3058 | N3: 0 | O3: 0 | P3: 3058 | Q3: 1.2746978 | R3: 3050 | S3: 3050 | T3: 0 | U3: 0.10464356 | V3: New | W3: BAZIC Products | Y3: USD | Z3: 3.69 | AA3: 0 | AB3: 0 | AC3: 10 | AD3: 0 | AE3: 10 | AF3: 0 | AG3: 0 | AH3: 0 | AI3: 0 | AJ3: 0 | AK3: 0 | AL3: 0 | AM3: Amazon | AQ3: 0 | AR3: none | AS3: No action required | AT3: 0.006 ft3
A4: US | B4: BAZIC Eraser Top, Latex Free Pencil Tops Erasers (20/Pack), Neon Color Arrowhead Caps Erasers for Kids Student Art Drawing School Supplies, 1-Pack | C4: FBA_2202-EACH | D4: B003BNZVI4 | E4: B003BNZVI4 | F4: 268 | G4: 1697 | H4: 1190 | I4: 66 | J4: 165 | K4: 1697 | L4: 103 | M4: 1594 | N4: 0 | O4: 0 | P4: 1594 | Q4: 0.70123748 | R4: 1429 | S4: 1429 | T4: 0 | U4: 6.3170301 | V4: New | W4: BAZIC Products | Y4: USD | Z4: 4.59 | AA4: 210.74 | AB4: 46 | AC4: 325 | AD4: 0 | AE4: 322 | AF4: 1 | AG4: 2 | AH4: 0 | AI4: 0 | AJ4: 0 | AK4: 0 | AL4: 0 | AM4: Amazon | AN4: 120 | AO4: 119 | AQ4: 0 | AR4: none | AS4: No action required | AT4: 0.009 ft3 | AU4: 0.038892163
A5: US | B5: BAZIC Pencil Pouch 3 Ring Binder Pouch w/Rivet Enforced Rings Hole, Black Mesh Window Zipper Pouches, 1-Count | C5: FBA_808-EACH | D5: B09DP3TR4F | E5: B09DP3TR4F | F5: 505 | G5: 1902 | H5: 1244 | I5: 45 | J5: 112.5 | K5: 1902 | L5: 392.5 | M5: 1509.5 | N5: 0 | O5: 0 | P5: 1509.5 | Q5: 0.65404837 | R5: 1397 | S5: 1397 | T5: 0 | U5: 10.6204 | V5: New | W5: BAZIC Products | Y5: USD | Z5: 4.09 | AA5: 118.61 | AB5: 29 | AC5: 548 | AD5: 0 | AE5: 546 | AF5: 2 | AG5: 0 | AH5: 0 | AI5: 0 | AJ5: 0 | AK5: 0 | AL5: 0 | AM5: Amazon | AN5: 184 | AO5: 184 | AQ5: 0 | AR5: none | AS5: No action required | AT5: 0.0344 ft3 | AU5: 0.023659306
A6: US | B6: BAZIC Products Sketch Pad, Spiral Sketchbook for Artists & Students, Drawing Pad with Thick Paper, Sketching & Drawing for Kids, Teens & Adults, 50 Sheets, 6" x 8", 1-Pack | C6: FBA_5043-EACH | D6: B00H9Z198Q | E6: B00H9Z198Q | F6: 522 | G6: 1650 | H6: 42 | I6: 333 | J6: 832.5 | K6: 1650 | L6: 0 | M6: 1650 | N6: 336 | O6: 336 | P6: 1314 | Q6: 0.025454545 | R6: 1128 | S6: 792 | T6: 336 | U6: 12.654545 | V6: New | W6: BAZIC Products | Y6: USD | Z6: 4.46 | AA6: 1234.8 | AB6: 260 | AC6: 755 | AD6: 480 | AE6: 122 | AF6: 114 | AG6: 3 | AH6: 36 | AI6: 2 | AJ6: 0 | AK6: 480 | AL6: 0 | AM6: Amazon | AN6: 142 | AO6: 134 | AQ6: 0 | AR6: none | AS6: No action required | AT6: 0.0054 ft3 | AU6: 0.20181818
C7: FBA_510-EACH-B | D7: B0018MN4RA | F7: 0 | G7: 3751 | H7: 89 | I7: 1 | J7: 2.5 | K7: 1280.3333 | L7: 0 | M7: 1280.3333 | N7: 0 | O7: 0 | P7: 1280.3333 | Q7: 0.023727006 | R7: 1280.3333 | S7: 1280.3333 | T7: 0 | U7: 0 | AU7: 0.0007810466
B8: BAZIC Products Blank Paper Copy & Multipurpose Paper | C8: FBA_510-EACH-B | D8: B0018MN4RA | F8: 0 | G8: 3751 | H8: 89 | I8: 1 | J8: 1280 | K8: 1280 | L8: 0 | M8: 1280 | N8: 0 | O8: 0 | P8: 1280 | Q8: 0.0237 | R8: 0.0008 | AU8: 0.0008
A9: US | B9: BAZIC Products Binder Dividers, 8.5 x 11 Plastic Index, 11 Hole Punch for 3 Ring Binders, Organizer, Ideal for School, Office, Home Organization, 10 Tab, 10/Pack, 1-Pack | C9: FBA_3107-EACH | D9: B07S4GZW7L | E9: X003BBR0T5 | F9: 27 | G9: 910 | H9: 1277 | I9: 13 | J9: 32.5 | K9: 1277 | L9: 0 | M9: 1277 | N9: 0 | O9: 0 | P9: 1277 | Q9: 1.4032967 | R9: 1250 | S9: 1250 | T9: 0 | U9: 0.84573218 | V9: New | W9: BAZIC Products | Y9: USD | Z9: 5.69 | AA9: 19.12 | AB9: 4 | AC9: 48 | AD9: 48 | AE9: 0 | AF9: 0 | AG9: 0 | AH9: 0 | AI9: 0 | AJ9: 0 | AK9: 48 | AL9: 0 | AM9: Amazon | AN9: 64 | AO9: 64 | AQ9: 0 | AR9: none | AS9: No action required | AT9: 0.0156 ft3
A10: US | B10: BAZIC Manila File Folder 1/3 Cut Letter Size, Left Right Center Tabs Positions, for Organizing Filing Document Storage, Total 12-Count | C10: FBA_3100-EACH | D10: B00ZPRYV0I | E10: B00ZPRYV0I | F10: 969 | G10: 1245 | H10: 104 | I10: 660 | J10: 1650 | K10: 1245 | L10: 0 | M10: 1245 | N10: 0 | O10: 0 | P10: 1245 | Q10: 0.083534137 | R10: 276 | S10: 276 | T10: 0 | U10: 31.13253 | V10: New | W10: BAZIC Products | Y10: USD | Z10: 4.59 | AA10: 1964.52 | AB10: 428 | AC10: 732 | AD10: 48 | AE10: 503 | AF10: 136 | AG10: 19 | AH10: 26 | AI10: 0 | AJ10: 0 | AK10: 48 | AL10: 0 | AM10: Amazon | AN10: 52 | AO10: 49 | AQ10: 48 | AR10: 46055 | AS10: Create shipping plan | AT10: 0.0331 ft3 | AU10: 0.53012048
A11: US | B11: BAZIC PRODUCTS Primary Journal Composition Book Marble, Primary Journal, Writing Journal, Notebooks for Kids, Drawing & Writing Notebook for Kindergarten School Use, Grades K-2, 100 Sheets, 2-Pack | C11: FBA_5053-SET2 | D11: B07S64FRBG | E11: X003AUSTNN | F11: 58 | G11: 1193 | H11: 1041 | I11: 16 | J11: 40 | K11: 1193 | L11: 18 | M11: 1175 | N11: 0 | O11: 0 | P11: 1175 | Q11: 0.87259011 | R11: 1135 | S11: 1135 | T11: 0 | U11: 1.9446773 | V11: New | W11: BAZIC Products | Y11: USD | Z11: 9.59 | AA11: 269.18 | AB11: 28 | AC11: 20 | AD11: 0 | AE11: 19 | AF11: 0 | AG11: 0 | AH11: 1 | AI11: 0 | AJ11: 0 | AK11: 0 | AL11: 0 | AM11: Amazon | AN11: 28 | AO11: 26 | AQ11: 72 | AR11: 46054 | AS11: Create shipping plan | AT11: 0.0354 ft3
A12: US | B12: BAZIC PRODUCTS Elementary School Supply Kit, 86-count Student Set for Elementary Students Grades 3-6, Complete School Supplies With Fully Organized Supply Box, 1-pack | C12: FBA_8005-CASE-B | D12: B0BB8R9HGQ | E12: B0BB8R9HGQ | F12: 80 | G12: 1167 | H12: 946 | I12: 0 | J12: 0 | K12: 1167 | L12: 80 | M12: 1087 | N12: 0 | O12: 0 | P12: 1087 | Q12: 0.81062554 | R12: 1087 | S12: 1087 | T12: 0 | U12: 2.7420737 | V12: New | W12: BAZIC Products | Y12: USD | Z12: 32.89 | AA12: 32.89 | AB12: 1 | AC12: 80 | AD12: 0 | AE12: 73 | AF12: 1 | AG12: 6 | AH12: 0 | AI12: 0 | AJ12: 0 | AK12: 0 | AL12: 0 | AM12: Amazon | AN12: 171 | AO12: 170 | AQ12: 0 | AR12: none | AS12: No action required | AT12: 0.311 ft3
A13: US | B13: BAZIC Products Mini Highlighter Pen Assorted Color, Chisel Tip Broad Fine Line Highlighters Coloring Marker (5/Pack), 1-Pack | C13: FBA_2306-EACH-1 | D13: B008ZHNN68 | E13: B008ZHNN68 | F13: 107 | G13: 1087 | H13: 16 | I13: 513 | J13: 1282.5 | K13: 1087 | L13: 0 | M13: 1087 | N13: 0 | O13: 0 | P13: 1087 | Q13: 0.014719411 | R13: 980 | S13: 980 | T13: 0 | U13: 3.9374425 | V13: New | W13: BAZIC Products | Y13: USD | Z13: 3.99 | AA13: 1125.18 | AB13: 282 | AC13: 490 | AD13: 0 | AE13: 325 | AF13: 126 | AG13: 20 | AH13: 19 | AI13: 1 | AJ13: 0 | AK13: 0 | AL13: 0 | AM13: Amazon | AN13: 26 | AO13: 24 | AQ13: 552 | AR13: 46055 | AS13: Create shipping plan | AT13: 0.0069 ft3 | AU13: 0.47194112
A14: US | B14: BAZIC Products 3 Ring Binder 1/2" Economy View Binders Organizer - Fuchsia, Round Ring, Hold 100 Sheets Paper, for School Office Home, 1-Count | C14: FBA_4106-EACH | D14: B07Q5VPWCP | E14: X003SC97LL | F14: 84 | G14: 1060 | H14: 1068 | I14: 42 | J14: 105 | K14: 1068 | L14: 0 | M14: 1068 | N14: 0 | O14: 0 | P14: 1068 | Q14: 1.0075472 | R14: 984 | S14: 984 | T14: 0 | U14: 3.1460674 | V14: New | W14: BAZIC Products | Y14: USD | Z14: 8.29 | AA14: 190.05 | AB14: 23 | AC14: 23 | AD14: 0 | AE14: 18 | AF14: 3 | AG14: 0 | AH14: 2 | AI14: 0 | AJ14: 0 | AK14: 0 | AL14: 0 | AM14: Amazon | AN14: 18 | AO14: 16 | AQ14: 24 | AR14: 46055 | AS14: Create shipping plan | AT14: 0.0761 ft3
A15: US | B15: BAZIC PRODUCTS Wide Ruled 1-Subject Notebook, Non-Spiral Composition Style, Easy-Tear Wireless Pages, 3-Hole Punched, 80 Sheets, Assorted Colors, for School, Office & Home, 6-Pack | C15: FBA_582-SET6 | D15: B07S964BMT | E15: X003SC1YG7 | F15: 44 | G15: 846 | H15: 1049 | I15: 17 | J15: 42.5 | K15: 1049 | L15: 1.5 | M15: 1047.5 | N15: 0 | O15: 0 | P15: 1047.5 | Q15: 1.2399527 | R15: 1005 | S15: 1005 | T15: 0 | U15: 1.6777884 | V15: New | W15: BAZIC Products | Y15: USD | Z15: 21.76 | AA15: 268.32 | AB15: 13 | AC15: 10 | AD15: 0 | AE15: 7 | AF15: 0 | AG15: 2 | AH15: 1 | AI15: 0 | AJ15: 0 | AK15: 0 | AL15: 0 | AM15: Amazon | AN15: 15 | AO15: 10 | AP15: low_stock | AQ15: 20 | AR15: 46055 | AS15: Create shipping plan | AT15: 0.1415 ft3
A16: US | B16: BAZIC Products Multiplication & Division Flash Cards, Educational Flash Cards for Kids, Math Flash Cards, Ideal for Math Learning Practice at Home or School, 36 Cards, 2-Pack | C16: FBA_534-EA+535-EA | D16: B08DHKDQ7J | E16: X003Z1GPEH | F16: 0 | G16: 453 | H16: 1017 | I16: 0 | J16: 0 | K16: 1017 | L16: 0 | M16: 1017 | N16: 0 | O16: 0 | P16: 1017 | Q16: 2.2450331 | R16: 1017 | S16: 1017 | T16: 0 | U16: 0 | V16: New | W16: BAZIC Products | Y16: USD | Z16: 7.39 | AA16: 0 | AB16: 0 | AC16: 0 | AD16: 0 | AE16: 0 | AF16: 0 | AG16: 0 | AH16: 0 | AI16: 0 | AJ16: 0 | AK16: 0 | AL16: 0 | AM16: Amazon | AP16: out_of_stock | AQ16: 0 | AR16: none | AS16: No action required | AT16: 0.0239 ft3
A17: US | B17: BAZIC Jeweltones Color Plastic Ruler 12" (30cm), Inches Centimeter Metric Measuring Rulers (4/Pack) | C17: FBA_336-EACH | D17: B003BMX65A | E17: X003TIPAXN | F17: 106 | G17: 1000 | H17: 942 | I17: 62 | J17: 155 | K17: 1000 | L17: 0 | M17: 1000 | N17: 0 | O17: 0 | P17: 1000 | Q17: 0.942 | R17: 894 | S17: 894 | T17: 0 | U17: 4.24 | V17: New | W17: BAZIC Products | Y17: USD | Z17: 4.89 | AA17: 156.48 | AB17: 32 | AC17: 170 | AD17: 0 | AE17: 169 | AF17: 1 | AG17: 0 | AH17: 0 | AI17: 0 | AJ17: 0 | AK17: 0 | AL17: 0 | AM17: Amazon | AN17: 151 | AO17: 151 | AQ17: 0 | AR17: none | AS17: No action required | AT17: 0.0158 ft3
A18: US | B18: BAZIC Products 3 Ring Binder 1.5" Economy View Binders Organizer - Fuchsia, Round Ring, Hold 280 Sheets Paper, for School Office Home, 1-Count | C18: FBA_4146-EACH | D18: B07Q97RZJC | E18: X003L8UNND | F18: 83 | G18: 983 | H18: 806 | I18: 181 | J18: 452.5 | K18: 983 | L18: 0 | M18: 983 | N18: 0 | O18: 0 | P18: 983 | Q18: 0.81993896 | R18: 900 | S18: 900 | T18: 0 | U18: 3.3774161 | V18: New | W18: BAZIC Products | Y18: USD | Z18: 11.29 | AA18: 225.76 | AB18: 20 | AC18: 314 | AD18: 0 | AE18: 295 | AF18: 14 | AG18: 1 | AH18: 4 | AI18: 1 | AJ18: 0 | AK18: 0 | AL18: 0 | AM18: Amazon | AN18: 189 | AO18: 189 | AQ18: 0 | AR18: none | AS18: No action required | AT18: 0.1439 ft3
A19: US | B19: BAZIC Products Sketch Pad, Spiral Sketchbook for Artists & Students, Drawing Pad with Thick Paper, Sketching & Drawing for Kids, Teens & Adults, 30 Sheets, 8.5" X 11", 1-Pack | C19: FBA_5045-EACH | D19: B07S94M6P6 | E19: X003DE6G1X | F19: 80 | G19: 928 | H19: 1017 | I19: 8 | J19: 20 | K19: 1017 | L19: 60 | M19: 957 | N19: 0 | O19: 0 | P19: 957 | Q19: 1.0959052 | R19: 937 | S19: 937 | T19: 0 | U19: 3.1465093 | V19: New | W19: BAZIC Products | Y19: USD | Z19: 5.69 | AA19: 181.56 | AB19: 34 | AC19: 97 | AD19: 96 | AE19: 0 | AF19: 0 | AG19: 0 | AH19: 1 | AI19: 1 | AJ19: 48 | AK19: 48 | AL19: 0 | AM19: Amazon | AN19: 94 | AO19: 51 | AQ19: 0 | AR19: none | AS19: No action required | AT19: 0.036 ft3
A20: US | B20: BAZIC Products 3 Ring Binder 1/2" Economy View Binders Organizer - Purple, Round Ring, Hold 100 Sheets Paper, for School Office Home, 1-Count | C20: FBA_4107-EACH | D20: B07Q84RJLP | E20: X003L8W44J | F20: 104 | G20: 791 | H20: 889 | I20: 29 | J20: 72.5 | K20: 889 | L20: 31.5 | M20: 857.5 | N20: 0 | O20: 0 | P20: 857.5 | Q20: 1.1238938 | R20: 785 | S20: 785 | T20: 0 | U20: 4.6794151 | V20: New | W20: BAZIC Products | Y20: USD | Z20: 9.09 | AA20: 74.1 | AB20: 10 | AC20: 159 | AD20: 156 | AE20: 0 | AF20: 0 | AG20: 2 | AH20: 1 | AI20: 0 | AJ20: 60 | AK20: 96 | AL20: 0 | AM20: Amazon | AN20: 63 | AO20: 43 | AQ20: 36 | AR20: 46055 | AS20: Create shipping plan | AT20: 0.049 ft3
A21: US | B21: BAZIC Products 2 Pocket Paper Folder, Letter Size Document Organizer for School, Office, Business Use, Camouflage Design Portfolio Folder for Homework, Reports & Forms, Assorted Colors, 6 Pack | C21: FBA_2170-SET6 | D21: B07S165T2T | E21: X003SBSK1F | F21: 27 | G21: 607 | H21: 812 | I21: 19 | J21: 47.5 | K21: 812 | L21: 0 | M21: 812 | N21: 0 | O21: 0 | P21: 812 | Q21: 1.3377265 | R21: 785 | S21: 785 | T21: 0 | U21: 1.3300493 | V21: New | W21: BAZIC Products | Y21: USD | Z21: 11.39 | AA21: 113.9 | AB21: 10 | AC21: 22 | AD21: 16 | AE21: 3 | AF21: 1 | AG21: 1 | AH21: 1 | AI21: 0 | AJ21: 0 | AK21: 16 | AL21: 0 | AM21: Amazon | AN21: 51 | AO21: 46 | AQ21: 8 | AR21: 46055 | AS21: Create shipping plan | AT21: 0.0737 ft3
A22: US | B22: BAZIC Products Open Closed Signs for Business, Double-sided Vinyl Open Signs for Business Window With Will Return Clock Sign, Be Back Sign With Clock, Ideal for Businesses, Shop, Office & More, 7.5"X9" 1-pack | C22: FBA_4398-EACH | D22: B07SFKBQ7F | E22: X003GYE2EX | F22: 288 | G22: 943 | H22: 618 | I22: 35 | J22: 87.5 | K22: 943 | L22: 200.5 | M22: 742.5 | N22: 0 | O22: 0 | P22: 742.5 | Q22: 0.65535525 | R22: 655 | S22: 655 | T22: 0 | U22: 12.216331 | V22: New | W22: BAZIC Products | Y22: USD | Z22: 4.79 | AA22: 73.73 | AB22: 17 | AC22: 291 | AD22: 291 | AE22: 0 | AF22: 0 | AG22: 0 | AH22: 0 | AI22: 0 | AJ22: 288 | AK22: 0 | AL22: 3 | AM22: Amazon | AN22: 365+ | AO22: 8 | AP22: low_stock | AQ22: 0 | AR22: none | AS22: No action required | AT22: 0.0078 ft3 | AU22: 0.037115589
A23: US | B23: BAZIC Products Blank Paper Copy & Multipurpose Paper 8.5" x 11" – 25 Sheets Pastel Color Printer Paper for Inkjet, Laser, and Fax Machines – Printing Paper for Office, School, and Crafts, 2-Packs | C23: FBA_5190-PACK2 | D23: B0BCL7XWNT | E23: X003SFUYF1 | F23: 22 | G23: 645 | H23: 704 | I23: 26 | J23: 65 | K23: 704 | L23: 0 | M23: 704 | N23: 0 | O23: 0 | P23: 704 | Q23: 1.0914729 | R23: 682 | S23: 682 | T23: 0 | U23: 1.25 | V23: New | W23: BAZIC Products | Y23: USD | Z23: 6.49 | AA23: 58.41 | AB23: 9 | AC23: 70 | AD23: 0 | AE23: 70 | AF23: 0 | AG23: 0 | AH23: 0 | AI23: 1 | AJ23: 0 | AK23: 0 | AL23: 0 | AM23: Amazon | AN23: 161 | AO23: 161 | AQ23: 0 | AR23: none | AS23: No action required | AT23: 0.0416 ft3
A24: US | B24: BAZIC Products Book Wrap - Clear Book Cover Self Adhesive Book Protector for Book Covers for Paperbacks, Plastic Cover for Books, Clear Contact Paper Peel and Stick, 17.5" x 1.7 Yard Roll, 1-Roll | C24: FBA_2901-EACH | D24: B076F13SG5 | E24: B076F13SG5 | F24: 629 | G24: 2487 | H24: 797 | I24: 70 | J24: 175 | K24: 1118 | L24: 454 | M24: 664 | N24: 0 | O24: 0 | P24: 664 | Q24: 0.32046643 | R24: 489 | S24: 489 | T24: 0 | U24: 22.504472 | V24: New | W24: BAZIC Products | Y24: USD | Z24: 5.4 | AA24: 1341.54 | AB24: 286 | AC24: 764 | AD24: 720 | AE24: 0 | AF24: 10 | AG24: 22 | AH24: 12 | AI24: 1 | AJ24: 384 | AK24: 336 | AL24: 0 | AM24: Amazon | AN24: 93 | AO24: 41 | AQ24: 0 | AR24: none | AS24: No action required | AT24: 0.0161 ft3 | AU24: 0.062611807
A25: US | B25: BAZIC Products Black Rubber Bands – Assorted Sizes, Heavy Duty Elastic Bands For Money, Office, School, Home Organization, Crafts, Durable Stretch Rubber Bands, 2 Oz (56.7 g), 1-Pack | C25: FBA_6120-EACH | D25: B09DJVP3DS | E25: B09DJVP3DS | F25: 440 | G25: 679 | H25: 4 | I25: 253 | J25: 632.5 | K25: 679 | L25: 0 | M25: 679 | N25: 36 | O25: 36 | P25: 643 | Q25: 0.0058910162 | R25: 239 | S25: 203 | T25: 36 | U25: 25.920471 | V25: New | W25: BAZIC Products | Y25: USD | Z25: 4.89 | AA25: 1090.47 | AB25: 223 | AC25: 311 | AD25: 72 | AE25: 232 | AF25: 3 | AG25: 2 | AH25: 2 | AI25: 1 | AJ25: 0 | AK25: 72 | AL25: 0 | AM25: Amazon | AN25: 53 | AO25: 52 | AQ25: 36 | AR25: 46055 | AS25: Create shipping plan | AT25: 0.0187 ft3 | AU25: 0.37260677
A26: US | B26: BAZIC Products Pink Eraser Top, Latex-Free Pencil Top Erasers with Arrowhead Caps, Non-Toxic Erasers for Kids, Students, Teachers, Classroom, Art, Homework & School Supplies, 20/Pack, 1-Pack | C26: FBA_2206-EACH | D26: B07RPR34BJ | E26: X002GAOOB9 | F26: 149 | G26: 661 | H26: 472 | I26: 49 | J26: 122.5 | K26: 661 | L26: 26.5 | M26: 634.5 | N26: 0 | O26: 0 | P26: 634.5 | Q26: 0.71406959 | R26: 512 | S26: 512 | T26: 0 | U26: 9.0166415 | V26: New | W26: BAZIC Products | Y26: USD | Z26: 3.89 | AA26: 272.22 | AB26: 70 | AC26: 106 | AD26: 48 | AE26: 51 | AF26: 6 | AG26: 0 | AH26: 1 | AI26: 0 | AJ26: 48 | AK26: 0 | AL26: 0 | AM26: Amazon | AN26: 69 | AO26: 42 | AQ26: 0 | AR26: none | AS26: No action required | AT26: 0.009 ft3 | AU26: 0.074130106
A27: US | B27: BAZIC Products Neon Highlighter – Yellow Pen Style, Chisel Tip Broad Fine Line, Desk Style Highlighter Pen for Office, School, and Study Use, Fluorescent Yellow Ink, Smooth Marking, 5/Pack, 1-Pack | C27: FBA_2300-EACH | D27: B07QXVJFTP | E27: X0044R3N1J | F27: 95 | G27: 458 | H27: 683 | I27: 13 | J27: 32.5 | K27: 683 | L27: 62.5 | M27: 620.5 | N27: 0 | O27: 0 | P27: 620.5 | Q27: 1.4912664 | R27: 588 | S27: 588 | T27: 0 | U27: 5.5636896 | V27: New | W27: BAZIC Products | Y27: USD | Z27: 4.79 | AA27: 219.79 | AB27: 46 | AC27: 53 | AD27: 48 | AE27: 5 | AF27: 0 | AG27: 0 | AH27: 0 | AI27: 0 | AJ27: 48 | AK27: 0 | AL27: 0 | AM27: Amazon | AN27: 45 | AO27: 4 | AP27: low_stock | AQ27: 48 | AR27: 46055 | AS27: Create shipping plan | AT27: 0.0093 ft3
A28: US | B28: BAZIC Products Glitter Glue Tube – 6 Assorted Classic Color, Non-Toxic Washable Glitter Glue for Art, Crafts, Paints, DIY, and Party Projects, 120ml/Pack, 1-Pack | C28: FBA_3467-EACH-1 | D28: B01HTYG3LE | E28: B01HTYG3LE | F28: 1072 | G28: 852 | H28: 281 | I28: 335 | J28: 837.5 | K28: 852 | L28: 234.5 | M28: 617.5 | N28: 0 | O28: 0 | P28: 617.5 | Q28: 0.32981221 | R28: 0 | S28: 0 | T28: 0 | U28: 50.328638 | V28: New | W28: BAZIC Products | Y28: USD | Z28: 6.23 | AA28: 443.89 | AB28: 62 | AC28: 1430 | AD28: 2 | AE28: 1267 | AF28: 35 | AG28: 120 | AH28: 6 | AI28: 2 | AJ28: 0 | AK28: 0 | AL28: 2 | AM28: Amazon | AN28: 308 | AO28: 302 | AQ28: 0 | AR28: none | AS28: No action required | AT28: 0.0131 ft3 | AU28: 0.39319249
A29: US | B29: BAZIC Ballpoint Pen Spencer Red Retractable Pen Soft Barrel Grip Pens, 1.0 mm Bold Point Smooth Writing, for Office School Teacher (5/Pack), 1-Pack | C29: FBA_17049-EACH | D29: B00FBOMTA4 | E29: B00FBOMTA4 | F29: 445 | G29: 774 | H29: 1037 | I29: 7 | J29: 17.5 | K29: 1037 | L29: 427.5 | M29: 609.5 | N29: 0 | O29: 0 | P29: 609.5 | Q29: 1.3397933 | R29: 592 | S29: 592 | T29: 0 | U29: 17.164899 | V29: New | W29: BAZIC Products | Y29: USD | Z29: 5.59 | AA29: 915.66 | AB29: 235 | AC29: 454 | AD29: 432 | AE29: 0 | AF29: 1 | AG29: 14 | AH29: 7 | AI29: 2 | AJ29: 432 | AK29: 0 | AL29: 0 | AM29: Amazon | AN29: 147 | AO29: 0 | AP29: low_stock | AQ29: 0 | AR29: none | AS29: No action required | AT29: 0.0072 ft3
A30: US | B30: BAZIC Products 8 Pocket Folder Portfolio, Double Loop Wire Binding, Letter Size Paper Organizer for Office, School, Business, Presentations, Projects & Document Storage, 1-Pack | C30: FBA_3161-EACH | D30: B08FK78Z2B | E30: X003BXWZTX | F30: 70 | G30: 449 | H30: 609 | I30: 24 | J30: 60 | K30: 609 | L30: 10 | M30: 599 | N30: 0 | O30: 0 | P30: 599 | Q30: 1.3563474 | R30: 539 | S30: 539 | T30: 0 | U30: 4.5977011 | V30: New | W30: BAZIC Products | Y30: USD | Z30: 8.09 | AA30: 244.63 | AB30: 35 | AC30: 28 | AD30: 24 | AE30: 1 | AF30: 0 | AG30: 1 | AH30: 2 | AI30: 1 | AJ30: 24 | AK30: 0 | AL30: 0 | AM30: Amazon | AN30: 23 | AO30: 0 | AP30: low_stock | AQ30: 48 | AR30: 46055 | AS30: Create shipping plan | AT30: 0.0508 ft3
A31: US | B31: BAZIC Products Highlighter – Yellow Color Chisel Tip Highlighter Set, Desk Style Highlighter Pen for Office, School, and Study Use, Fluorescent Yellow Ink, Smooth Marking, 3 Pcs, 1-Pack | C31: FBA_2320-EACH | D31: B075VWXGFL | E31: B075VWXGFL | F31: 29 | G31: 96 | H31: 593 | I31: 3 | J31: 7.5 | K31: 593 | L31: 21.5 | M31: 571.5 | N31: 0 | O31: 0 | P31: 571.5 | Q31: 6.1770833 | R31: 564 | S31: 564 | T31: 0 | U31: 1.9561551 | V31: New | W31: BAZIC Products | Y31: USD | Z31: 4.83 | AA31: 0 | AB31: 0 | AC31: 48 | AD31: 48 | AE31: 0 | AF31: 0 | AG31: 0 | AH31: 0 | AI31: 0 | AJ31: 24 | AK31: 24 | AL31: 0 | AM31: Amazon | AQ31: 0 | AR31: none | AS31: No action required | AT31: 0.0117 ft3
A32: US | B32: BAZIC Products 3 Ring Binder 1/2" Economy View Binders Organizer - Blue, Round Ring, Hold 175 Sheets Paper, for School Office Home, 1-Count | C32: FBA_3190-EACH | D32: B07Q9PJ727 | E32: X003SBSK1P | F32: 34 | G32: 456 | H32: 563 | I32: 17 | J32: 42.5 | K32: 563 | L32: 0 | M32: 563 | N32: 0 | O32: 0 | P32: 563 | Q32: 1.2346491 | R32: 529 | S32: 529 | T32: 0 | U32: 2.4156306 | V32: New | W32: BAZIC Products | Y32: USD | Z32: 8.48 | AA32: 101.76 | AB32: 12 | AC32: 27 | AD32: 12 | AE32: 14 | AF32: 0 | AG32: 0 | AH32: 1 | AI32: 0 | AJ32: 12 | AK32: 0 | AL32: 0 | AM32: Amazon | AN32: 56 | AO32: 33 | AQ32: 12 | AR32: 46054 | AS32: Create shipping plan | AT32: 0.0805 ft3
A33: US | B33: BAZIC Products Washable Clear School Glue 5 Oz. (147 mL), Liquid Clear Glues Adhesive, for Making Slime Art Crafts at School Home Office, 1-Pack | C33: FBA_2044-EACH | D33: B075VXY8MQ | E33: B075VXY8MQ | F33: 72 | G33: 567 | H33: 342 | I33: 23 | J33: 57.5 | K33: 567 | L33: 14.5 | M33: 552.5 | N33: 0 | O33: 0 | P33: 552.5 | Q33: 0.6031746 | R33: 495 | S33: 495 | T33: 0 | U33: 5.0793651 | V33: New | W33: BAZIC Products | Y33: USD | Z33: 6.3 | AA33: 6.37 | AB33: 1 | AC33: 240 | AD33: 240 | AE33: 0 | AF33: 0 | AG33: 0 | AH33: 0 | AI33: 0 | AJ33: 48 | AK33: 192 | AL33: 0 | AM33: Amazon | AN33: 365+ | AO33: 365+ | AQ33: 0 | AR33: none | AS33: No action required | AT33: 0.0109 ft3 | AU33: 0.040564374
A34: US | B34: BAZIC Products Notebook College Ruled 1 Subject 80 Sheets Wireless Notebooks, Lined Composition Book, Assorted Color, 6-Pack | C34: FBA_581-SET6 | D34: B07S97LHGW | E34: X003L8UNOH | F34: 244 | G34: 537 | H34: 464 | I34: 89 | J34: 222.5 | K34: 537 | L34: 21.5 | M34: 515.5 | N34: 0 | O34: 0 | P34: 515.5 | Q34: 0.86405959 | R34: 293 | S34: 293 | T34: 0 | U34: 18.175047 | V34: New | W34: BAZIC Products | Y34: USD | Z34: 16.89 | AA34: 1560.54 | AB34: 93 | AC34: 93 | AD34: 88 | AE34: 0 | AF34: 0 | AG34: 2 | AH34: 3 | AI34: 0 | AJ34: 76 | AK34: 12 | AL34: 0 | AM34: Amazon | AN34: 41 | AO34: 4 | AP34: low_stock | AQ34: 56 | AR34: 46055 | AS34: Create shipping plan | AT34: 0.0866 ft3
A35: US | B35: BAZIC Products 3 Ring Binder 1/2" Economy View Binders Organizer - Green, Round Ring, Hold 100 Sheets Paper, for School Office Home, 1-Count | C35: FBA_4102-EACH | D35: B07Q8WY4R5 | E35: X003L8UNPL | F35: 117 | G35: 449 | H35: 572 | I35: 16 | J35: 40 | K35: 572 | L35: 77 | M35: 495 | N35: 0 | O35: 0 | P35: 495 | Q35: 1.2739421 | R35: 455 | S35: 455 | T35: 0 | U35: 8.1818182 | V35: New | W35: BAZIC Products | Y35: USD | Z35: 6.99 | AA35: 419.4 | AB35: 60 | AC35: 111 | AD35: 108 | AE35: 1 | AF35: 0 | AG35: 0 | AH35: 2 | AI35: 1 | AJ35: 96 | AK35: 12 | AL35: 0 | AM35: Amazon | AN35: 46 | AO35: 5 | AP35: low_stock | AQ35: 84 | AR35: 46055 | AS35: Create shipping plan | AT35: 0.0818 ft3
A36: US | B36: BAZIC Products Blank Paper Copy & Multipurpose Paper 8.5" x 11" – 25 Sheets Pastel Color Printer Paper for Inkjet, Laser, and Fax Machines – Printing Paper for Office, School, and Crafts, 1-Pack | C36: FBA_5190-EACH | D36: B0BCMBR7L9 | E36: B0BCMBR7L9 | F36: 124 | G36: 325 | H36: 514 | I36: 41 | J36: 102.5 | K36: 514 | L36: 21.5 | M36: 492.5 | N36: 0 | O36: 0 | P36: 492.5 | Q36: 1.5815385 | R36: 390 | S36: 390 | T36: 0 | U36: 9.6498054 | V36: New | W36: BAZIC Products | Y36: USD | Z36: 5.15 | AA36: 267.6 | AB36: 61 | AC36: 9 | AD36: 0 | AE36: 0 | AF36: 0 | AG36: 3 | AH36: 6 | AI36: 0 | AJ36: 0 | AK36: 0 | AL36: 0 | AM36: Amazon | AN36: 2 | AO36: 0 | AP36: out_of_stock | AQ36: 168 | AR36: 46048 | AS36: Create shipping plan | AT36: 0.0159 ft3
A37: US | B37: BAZIC Products Blank Paper Copy & Multipurpose Paper - 8.5" x 11" Pastel Color Printer Paper for Inkjet, Laser, and Fax Machines, Ideal for Office, School, and Crafts, 100 Sheets/Pack, 1-Pack | C37: FBA_5191-EACH | D37: B0BCL6MSMS | E37: B0BCL6MSMS | F37: 55 | G37: 309 | H37: 536 | I37: 2 | J37: 5 | K37: 536 | L37: 50 | M37: 486 | N37: 0 | O37: 0 | P37: 486 | Q37: 1.7346278 | R37: 481 | S37: 481 | T37: 0 | U37: 4.1044776 | V37: New | W37: BAZIC Products | Y37: USD | Z37: 8.6 | AA37: 261.56 | AB37: 35 | AC37: 48 | AD37: 48 | AE37: 0 | AF37: 0 | AG37: 0 | AH37: 0 | AI37: 0 | AJ37: 48 | AK37: 0 | AL37: 0 | AM37: Amazon | AN37: 72 | AO37: 0 | AP37: out_of_stock | AQ37: 24 | AR37: 46053 | AS37: Create shipping plan | AT37: 0.0371 ft3
A38: US | B38: BAZIC Products 3 Ring Binder 1" Economy View Binders Organizer - Pastel Color, Round Ring, Hold 175 Sheets Paper, for School Office Home, 4-Count | C38: FBA_3167-SET4 | D38: B08LP2FGJM | E38: X003BVZHKJ | F38: 463 | G38: 926 | H38: 693 | I38: 8 | J38: 20 | K38: 926 | L38: 443 | M38: 483 | N38: 0 | O38: 0 | P38: 483 | Q38: 0.74838013 | R38: 463 | S38: 463 | T38: 0 | U38: 20 | V38: New | W38: BAZIC Products | Y38: USD | Z38: 19.85 | AA38: 119.1 | AB38: 6 | AC38: 476 | AD38: 0 | AE38: 467 | AF38: 0 | AG38: 9 | AH38: 0 | AI38: 0 | AJ38: 0 | AK38: 0 | AL38: 0 | AM38: Amazon | AN38: 205 | AO38: 205 | AQ38: 0 | AR38: none | AS38: No action required | AT38: 0.2279 ft3 | AU38: 0.0086393089
A39: US | B39: BAZIC Products 3 Ring Binder 1" Economy View Binders Organizer - Purple, Round Ring, Hold 175 Sheets Paper, for School Office Home, 1-Count | C39: FBA_4127-EACH | D39: B07Q8XTMXF | E39: X003SC97MF | F39: 29 | G39: 471 | H39: 389 | I39: 31 | J39: 77.5 | K39: 471 | L39: 0 | M39: 471 | N39: 0 | O39: 0 | P39: 471 | Q39: 0.82590234 | R39: 442 | S39: 442 | T39: 0 | U39: 2.462845 | V39: New | W39: BAZIC Products | Y39: USD | Z39: 9.59 | AA39: 190.79 | AB39: 20 | AC39: 74 | AD39: 0 | AE39: 72 | AF39: 1 | AG39: 0 | AH39: 1 | AI39: 0 | AJ39: 0 | AK39: 0 | AL39: 0 | AM39: Amazon | AN39: 131 | AO39: 129 | AQ39: 0 | AR39: none | AS39: No action required | AT39: 0.1021 ft3
A40: US | B40: BAZIC Products Plastic Pencil Case, Ruler Length Large Utility Storage Box, Multi Purpose Organizer & Supply Holder, Clear Box Design, Ideal for School, Office & Craft Use, 1-Pack | C40: FBA_851-EACH | D40: B093CPW1HK | E40: B093CPW1HK | F40: 0 | G40: 478 | H40: 388 | I40: 3 | J40: 7.5 | K40: 478 | L40: 0 | M40: 478 | N40: 12 | O40: 12 | P40: 466 | Q40: 0.81171548 | R40: 478 | S40: 466 | T40: 12 | U40: 0 | V40: New | W40: BAZIC Products | Y40: USD | Z40: 9.89 | AA40: 126.62 | AB40: 14 | AC40: 1 | AD40: 0 | AE40: 0 | AF40: 0 | AG40: 0 | AH40: 1 | AI40: 0 | AJ40: 0 | AK40: 0 | AL40: 0 | AM40: Amazon | AN40: 2 | AO40: 0 | AP40: out_of_stock | AQ40: 24 | AR40: 46048 | AS40: Create shipping plan | AT40: 0.1189 ft3
...

Sheet all asins
A1: (Child) ASIN
A2: B0BG14KCKZ | B2: =VLOOKUP(A2,'FBA Inventory'!E:E,1,FALSE) -> B0BG14KCKZ
A3: B0018MN4RA | B3: =VLOOKUP(A3,'FBA Inventory'!E:E,1,FALSE) -> B0018MN4RA
A4: B003BMWZ48 | B4: =VLOOKUP(A4,'FBA Inventory'!E:E,1,FALSE) -> B003BMWZ48
A5: B09BBP343Q | B5: =VLOOKUP(A5,'FBA Inventory'!E:E,1,FALSE) -> B09BBP343Q
A6: B076F13SG5 | B6: =VLOOKUP(A6,'FBA Inventory'!E:E,1,FALSE) -> B076F13SG5
A7: B09DP3TR4F | B7: =VLOOKUP(A7,'FBA Inventory'!E:E,1,FALSE) -> B09DP3TR4F
A8: B00H9Z198Q | B8: =VLOOKUP(A8,'FBA Inventory'!E:E,1,FALSE) -> B00H9Z198Q
A9: B09GD5961M | B9: =VLOOKUP(A9,'FBA Inventory'!E:E,1,FALSE) -> B09GD5961M
A10: B00ZPRYV0I | B10: =VLOOKUP(A10,'FBA Inventory'!E:E,1,FALSE) -> B00ZPRYV0I
A11: B08P3W6YN6 | B11: =VLOOKUP(A11,'FBA Inventory'!E:E,1,FALSE) -> B08P3W6YN6
A12: B001BNW7QA | B12: =VLOOKUP(A12,'FBA Inventory'!E:E,1,FALSE) -> B001BNW7QA
A13: B07S64FRBG | B13: =VLOOKUP(A13,'FBA Inventory'!E:E,1,FALSE) -> B07S64FRBG
... A4935: B0FCHT1WZ9 | B4935: =VLOOKUP(A4935,'FBA Inventory'!E:E,1,FALSE) -> B0FCHT1WZ9

Sheet InventoryUnits Column Check
A2: Sheet | B2: Actual Header | C2: Correct Header | D2: Column Check
A3: 14 Day SC Report | B3: =VLOOKUP('14 day SC Report'!A1,'14 day SC Report'!A1:O1,10,FALSE) -> Units Ordered | C3: Units Ordered | D3: =IF(B3=C3,"Ok","Error") -> Ok
A4: 45 Day SC Report | B4: =VLOOKUP('2025'!A1,'2025'!A1:O1,10,FALSE) -> Units Ordered | C4: Units Ordered | D4: =IF(B4=C4,"Ok","Error") -> Ok
A5: 12 Month SC Report | B5: =VLOOKUP('2024'!A1,'2024'!A1:O1,10,FALSE) -> Units Ordered | C5: Units Ordered | D5: =IF(B5=C5,"Ok","Error") -> Ok
A6: - | B6: =VLOOKUP('[1]VHC Inventory'!A1,'[1]VHC Inventory'!A1:D1,4,FALSE) -> #REF! | C6: Qty On Hand | D6: =IF(B6=C6,"Ok","Error") -> #REF!
A7: FBA Inventory | B7: =VLOOKUP( 'FBA Inventory'!A1,'FBA Inventory'!A1:Q1,14,FALSE) -> Inbound | C7: Inbound | D7: =IF(B7=C7,"Ok","Error") -> Ok
B8: =VLOOKUP( 'FBA Inventory'!A1,'FBA Inventory'!A1:Q1,15,FALSE) -> Available | C8: Available | D8: =IF(B8=C8,"Ok","Error") -> Ok
B9: =VLOOKUP( 'FBA Inventory'!A1,'FBA Inventory'!A1:Q1,16,FALSE) -> FC transfer | C9: FC transfer | D9: =IF(B9=C9,"Ok","Error") -> Ok
B10: =VLOOKUP( 'FBA Inventory'!A1,'FBA Inventory'!A1:Q1,17,FALSE) -> FC Processing | C10: FC Processing | D10: =IF(B10=C10,"Ok","Error") -> Ok
A11: Duplicate Asins in FBA Inventory | D11: =IF(SUMPRODUCT(--(COUNTIF('FBA Inventory'!E:E,'FBA Inventory'!E:E)>1))>0=FALSE,"OK","Error") -> OK

Sheet AWD
A1: Timestamp | B1: 46079.56
A2: Merchant ID | B2: A2J9CB3QL3LKD1
A4: Product Name | B4: SKU | C4: FNSKU | D4: ASIN | E4: Inbound to AWD (units) | F4: Inbound to AWD (cases) | G4: Available in AWD (units) | H4: Available in AWD (cases) | I4: Available Units in AWD (US) | J4: Available Cartons in AWD (US) | K4: Reserved in AWD (units) | L4: Reserved in AWD (cases) | M4: Outbound Order (units) | N4: Outbound Order (cases) | O4: Researching (units) | P4: Researching (cases) | Q4: Outbound to FBA (units) | R4: Available in FBA (units) | S4: Available in FBA (days) | T4: Reserved in FBA (units) | U4: Customer Order (units) | V4: FC Processing (units) | W4: FC Transfer (units) | X4: Days of Supply (days) | Y4: Auto Replenishment Ratio (percent)
A5: BAZIC 3/4" X 500" Double Sided Permanent Tape w/Dispenser | B5: FBA_930-EACH | C5: B003BMWQYC | D5: B003BMWQYC | E5: 0 | F5: 0 | G5: 48 | H5: 2 | I5: 48 | J5: 2 | K5: 0 | L5: 0 | M5: 0 | N5: 0 | O5: 0 | P5: 0 | Q5: 0 | R5: 41 | S5: 366 | T5: 0 | U5: 0 | V5: 0 | W5: 0 | X5: -- | Y5: 0
A6: BAZIC Products Plastic Pencil Case, Ruler Length Large Utility Storage Box, Multi Purpose Organizer & Supply Holder, Clear Box Design, Ideal for School, Office & Craft Use, 1-Pack | B6: FBA_851-EACH | C6: B093CPW1HK | D6: B093CPW1HK | E6: 0 | F6: 0 | G6: 12 | H6: 1 | I6: 12 | J6: 1 | K6: 0 | L6: 0 | M6: 0 | N6: 0 | O6: 0 | P6: 0 | Q6: 0 | R6: 0 | S6: 0 | T6: 0 | U6: 0 | V6: 0 | W6: 0 | X6: 360.4 | Y6: SC_FBA_GIM_infinite
A7: BAZIC PRODUCTS Plastic Pencil Case, Ruler Length Utility Storage Box, Multi Purpose Organizer & Supply Holder, Transparent Box Design, Assorted Color, Ideal for School, Office & Craft Use, 4-Pack | B7: FBA_841-SET4 | C7: X003SC38J3 | D7: B07RBC11NP | E7: 0 | F7: 0 | G7: 72 | H7: 6 | I7: 72 | J7: 6 | K7: 0 | L7: 0 | M7: 0 | N7: 0 | O7: 0 | P7: 0 | Q7: 0 | R7: 27 | S7: 50 | T7: 4 | U7: 1 | V7: 0 | W7: 3 | X7: 222.9 | Y7: 0
A8: BAZIC Products Plastic Pencil Case Utility Storage Box, Glitter Bright Color, Multi Purpose Organizer for Pens Pencils, 4-Pack | B8: FBA_839-SET4 | C8: B01LZ4HWFD | D8: B01LZ4HWFD | E8: 0 | F8: 0 | G8: 36 | H8: 3 | I8: 36 | J8: 3 | K8: 0 | L8: 0 | M8: 0 | N8: 0 | O8: 0 | P8: 0 | Q8: 0 | R8: 9 | S8: 23 | T8: 3 | U8: 0 | V8: 0 | W8: 3 | X8: 492.1 | Y8: 1
A9: BAZIC Products Pencil Pouch 3 Ring Binder Pouch w/Rivet Enforced Rings Holes, Pastel Color Mesh Window Zipper Pouchesr, 6-Pack | B9: FBA_810-SET6 | C9: X003S83OA5 | D9: B09DPBCNJW | E9: 0 | F9: 0 | G9: 264 | H9: 11 | I9: 264 | J9: 11 | K9: 0 | L9: 0 | M9: 0 | N9: 0 | O9: 0 | P9: 0 | Q9: 0 | R9: 251 | S9: 366 | T9: 0 | U9: 0 | V9: 0 | W9: 0 | X9: -- | Y9: 0
A10: BAZIC Products Pencil Pouch 3 Ring Binder Pouch, Rivet Enforced Ring Hole, Mesh Window Zipper Case, Pastel Purple, 2-Pack | B10: FBA_810-PP-PACK2 | C10: X003KDRU53 | D10: B0BPJTBHZN | E10: 0 | F10: 0 | G10: 72 | H10: 1 | I10: 72 | J10: 1 | K10: 0 | L10: 0 | M10: 0 | N10: 0 | O10: 0 | P10: 0 | Q10: 0 | R10: 75 | S10: 366 | T10: 1 | U10: 0 | V10: 1 | W10: 0 | X10: -- | Y10: 0
A11: BAZIC Products Pencil Pouch 3 Ring Binder Pouch, Rivet Enforced Ring Hole, Mesh Window Zipper Case, Pastel Pink, 2-Pack | B11: FBA_810-PNK-PACK2 | C11: X003KDW1BV | D11: B0BPJPD5QX | E11: 0 | F11: 0 | G11: 72 | H11: 1 | I11: 72 | J11: 1 | K11: 0 | L11: 0 | M11: 0 | N11: 0 | O11: 0 | P11: 0 | Q11: 0 | R11: 104 | S11: 366 | T11: 1 | U11: 0 | V11: 1 | W11: 0 | X11: -- | Y11: 0
A12: BAZIC Products Pencil Pouch 3 Ring Binder Pouch, Rivet Enforced Ring Hole, Mesh Window Zipper Case, Pastel Orange, 2-Pack | B12: FBA_810-OR-PACK2 | C12: X003KDRU5D | D12: B0BPJW18HP | E12: 0 | F12: 0 | G12: 72 | H12: 1 | I12: 72 | J12: 1 | K12: 0 | L12: 0 | M12: 0 | N12: 0 | O12: 0 | P12: 0 | Q12: 0 | R12: 114 | S12: 366 | T12: 0 | U12: 0 | V12: 0 | W12: 0 | X12: -- | Y12: 0
A13: BAZIC Products Pencil Pouch 3 Ring Binder Pouch, Rivet Enforced Ring Hole, Mesh Window Zipper Case, Pastel Grey, 2-Pack | B13: FBA_810-GY-PACK2 | C13: X003KDQIZV | D13: B0BPJLZLLW | E13: 0 | F13: 0 | G13: 72 | H13: 1 | I13: 72 | J13: 1 | K13: 0 | L13: 0 | M13: 0 | N13: 0 | O13: 0 | P13: 0 | Q13: 0 | R13: 60 | S13: 366 | T13: 0 | U13: 0 | V13: 0 | W13: 0 | X13: -- | Y13: 0
A14: BAZIC Products Pencil Pouch 3 Ring Binder Pouch w/Rivet Enforced Rings Holes, Neon Black Color Mesh Window Zipper Pouches, 6-Pack | B14: FBA_809-SETOF6 | C14: X0031MTKF1 | D14: B09HL5JHLT | E14: 0 | F14: 0 | G14: 120 | H14: 5 | I14: 120 | J14: 5 | K14: 0 | L14: 0 | M14: 0 | N14: 0 | O14: 0 | P14: 0 | Q14: 0 | R14: 50 | S14: 151 | T14: 0 | U14: 0 | V14: 0 | W14: 0 | X14: -- | Y14: 0
A15: BAZIC PRODUCTS Pencil Pouch for 3 Ring Binder, Zippered Mesh Window Pencil Case with Reinforced Grommets, Durable Binder Organizer for School Supplies or Office Supplies Storage, 2-Pack | B15: FBA_808-PACK2 | C15: X0039GZAX5 | D15: B09GD5961M | E15: 0 | F15: 0 | G15: 432 | H15: 6 | I15: 432 | J15: 6 | K15: 0 | L15: 0 | M15: 0 | N15: 0 | O15: 0 | P15: 0 | Q15: 0 | R15: 670 | S15: 366 | T15: 20 | U15: 1 | V15: 2 | W15: 17 | X15: 870.1 | Y15: 0
A16: BAZIC PRODUCTS Pencil Pouch 3 Ring Binder Pouch w/Rivet Enforced Rings Holes, Assorted Color Mesh Window, Double Zipper Pouches 6-Pack | B16: FBA_807-SET6 | C16: X003BSZ6JT | D16: B07T9NZN1N | E16: 0 | F16: 0 | G16: 48 | H16: 2 | I16: 48 | J16: 2 | K16: 0 | L16: 0 | M16: 0 | N16: 0 | O16: 0 | P16: 0 | Q16: 0 | R16: 20 | S16: 366 | T16: 0 | U16: 0 | V16: 0 | W16: 0 | X16: -- | Y16: 0
A17: BAZIC Products Pencil Pouch 3 Ring Binder Pouch w/Rivet Enforced Rings Holes, Assorted Color Mesh Window Zipper Pouches, 4-Pack | B17: FBA_803-SET4 | C17: X003SCCWW7 | D17: B07RC79KYS | E17: 0 | F17: 0 | G17: 324 | H17: 9 | I17: 324 | J17: 9 | K17: 0 | L17: 0 | M17: 0 | N17: 0 | O17: 0 | P17: 0 | Q17: 0 | R17: 139 | S17: 136 | T17: 3 | U17: 1 | V17: 2 | W17: 0 | X17: -- | Y17: 0
A18: BAZIC Products School Kit Pack 60 Count, School Supply Box for Elementary Student K-6, Ruler Composition Book Pencil Eraser Crayon, 1-Pack | B18: FBA_8010-EACH | C18: B0B3C4XXJ5 | D18: B0B3C4XXJ5 | E18: 0 | F18: 0 | G18: 420 | H18: 42 | I18: 420 | J18: 42 | K18: 0 | L18: 0 | M18: 0 | N18: 0 | O18: 0 | P18: 0 | Q18: 0 | R18: 65 | S18: 999 | T18: 11 | U18: 1 | V18: 0 | W18: 10 | X18: -- | Y18: 0
A19: BAZIC Products Pencil Wood Pre-Sharpened Pencil #2 HB, Latex Free Eraser Yellow Pre Sharpened Pencils for Exam Sketching School Office (12/Pack), 2-Packs | B19: FBA_761-PACK2 | C19: X003WOIKTF | D19: B08F759LCW | E19: 0 | F19: 0 | G19: 792 | H19: 11 | I19: 792 | J19: 11 | K19: 0 | L19: 0 | M19: 0 | N19: 0 | O19: 0 | P19: 0 | Q19: 0 | R19: 209 | S19: 999 | T19: 0 | U19: 0 | V19: 0 | W19: 0 | X19: -- | Y19: 0
A20: BAZIC Products Black Rubber Bands – Assorted Sizes, Heavy Duty Elastic Bands For Money, Office, School, Home Organization, Crafts, Durable Stretch Rubber Bands, 2 Oz (56.7 g), 1-Pack | B20: FBA_6120-EACH | C20: B09DJVP3DS | D20: B09DJVP3DS | E20: 0 | F20: 0 | G20: 36 | H20: 1 | I20: 36 | J20: 1 | K20: 0 | L20: 0 | M20: 0 | N20: 0 | O20: 0 | P20: 0 | Q20: 37 | R20: 225 | S20: 83 | T20: 69 | U20: 0 | V20: 0 | W20: 69 | X20: 101.4 | Y20: 0.78
A21: BAZIC Products Rubber Bands – Assorted Color & Sizes, Heavy Duty Elastic Bands For Money, Office, School, Home Organization, Crafts, Durable Stretch Rubber Bands, 2 Oz (56.70 g), 1-Pack | B21: FBA_6110-EACH | C21: X002GASSMF | D21: B07SC668W8 | E21: 0 | F21: 0 | G21: 504 | H21: 14 | I21: 504 | J21: 14 | K21: 0 | L21: 0 | M21: 0 | N21: 0 | O21: 0 | P21: 0 | Q21: 1 | R21: 194 | S21: 48 | T21: 11 | U21: 1 | V21: 2 | W21: 8 | X21: 303.7 | Y21: 1
A22: BAZIC Rubber Bands, Assorted Size 2 Oz./ 56.70 g, Made in USA Elastic Stretchable Bands for Bank Paper Bills Money Dollars File Folders, 1-Pack | B22: FBA_6100-EACH | C22: B00GSSDLMM | D22: B00GSSDLMM | E22: 0 | F22: 0 | G22: 936 | H22: 26 | I22: 936 | J22: 26 | K22: 0 | L22: 0 | M22: 0 | N22: 0 | O22: 0 | P22: 0 | Q22: 0 | R22: 354 | S22: 134 | T22: 0 | U22: 0 | V22: 0 | W22: 0 | X22: 511.7 | Y22: 1
A23: BAZIC Staples Standard (26/6) 5000/Pack, Stapler Refill Standard Size Staple, Silver Colors, 1-Pack | B23: FBA_608-EACH | C23: X003EGFQKR | D23: B003BMWZ48 | E23: 0 | F23: 0 | G23: 936 | H23: 13 | I23: 936 | J23: 13 | K23: 72 | L23: 1 | M23: 0 | N23: 0 | O23: 72 | P23: 1 | Q23: 0 | R23: 424 | S23: 30 | T23: 50 | U23: 21 | V23: 16 | W23: 13 | X23: 240.1 | Y23: 1
A24: BAZIC Felt Chalkboard Eraser, Wood Blackboard Eraser Cleaner Dustless, Teacher Kids Office Classroom, 1-Pack | B24: FBA_6003-EACH | C24: B002URU9G6 | D24: B002URU9G6 | E24: 0 | F24: 0 | G24: 144 | H24: 1 | I24: 144 | J24: 1 | K24: 0 | L24: 0 | M24: 0 | N24: 0 | O24: 0 | P24: 0 | Q24: 0 | R24: 149 | S24: 75 | T24: 7 | U24: 1 | V24: 2 | W24: 4 | X24: 124.6 | Y24: 1
A25: BAZIC 100 Ct. 4-1" Quad-Ruled Filler Paper | B25: FBA_569-EACH | C25: B003BLQHZM | D25: B003BLQHZM | E25: 0 | F25: 0 | G25: 432 | H25: 12 | I25: 432 | J25: 12 | K25: 0 | L25: 0 | M25: 0 | N25: 0 | O25: 0 | P25: 0 | Q25: 0 | R25: 84 | S25: 119 | T25: 0 | U25: 0 | V25: 0 | W25: 0 | X25: -- | Y25: 0
A26: BAZIC Products Poster Board Glitter Frame Color - Assorted Glitter Color, Sparkling Frame Colored Poster Board Paper for Crafts, Decorations, & Vision Board Projects, 11” x 14”, 5/Pack, 1-Pack | B26: FBA_5414-EACH | C26: B07TCRK63W | D26: B07TCRK63W | E26: 0 | F26: 0 | G26: 0 | H26: 0 | I26: 0 | J26: 0 | K26: 0 | L26: 0 | M26: 0 | N26: 0 | O26: 0 | P26: 0 | Q26: 48 | R26: 11 | S26: 32 | T26: 88 | U26: 0 | V26: 2 | W26: 86 | X26: 94.3 | Y26: 0.7
A27: BAZIC Products Poster Board Glitter Color 11" X 14", Sparkling Colored Poster Board Paper for Christmas Wedding Birthday Craft Project (3 Color/Pack) COLOR SENT RANDOM | B27: FBA_5413-EACH | C27: B075VXLS9F | D27: B075VXLS9F | E27: 0 | F27: 0 | G27: 48 | H27: 1 | I27: 48 | J27: 1 | K27: 0 | L27: 0 | M27: 0 | N27: 0 | O27: 0 | P27: 0 | Q27: 0 | R27: 23 | S27: 98 | T27: 3 | U27: 0 | V27: 0 | W27: 3 | X27: 267.9 | Y27: 0
A28: BAZIC Division Flash Cards, Numbers Elementary Math Flashcards Game at School, Problem Solving for Ages 8+ 3rd Grade 4th Grade (36/Pack), 1-Pack | B28: FBA_535-EACH | C28: B003BOUX9A | D28: B003BOUX9A | E28: 0 | F28: 0 | G28: 216 | H28: 3 | I28: 216 | J28: 3 | K28: 0 | L28: 0 | M28: 0 | N28: 0 | O28: 0 | P28: 0 | Q28: 0 | R28: 162 | S28: 185 | T28: 8 | U28: 1 | V28: 0 | W28: 7 | X28: 708.3 | Y28: 0
A29: BAZIC Products Poster Board 11" X 14" Assorted Colored Poster Board Paper for School Craft Project Presentation Drawing Graphic Display (5/Pack), 1-Pack | B29: FBA_529-EACH | C29: X003UID51L | D29: B07S9HP4W5 | E29: 0 | F29: 0 | G29: 48 | H29: 1 | I29: 48 | J29: 1 | K29: 0 | L29: 0 | M29: 0 | N29: 0 | O29: 0 | P29: 0 | Q29: 0 | R29: 76 | S29: 31 | T29: 52 | U29: 0 | V29: 48 | W29: 4 | X29: 183.9 | Y29: 1
A30: BAZIC Products Blank Index Cards 3" X 5" 100 Count, White Unruled Flashcards, Flash Card for Learning Memory Reminder (100/Pack), 1-Pack | B30: FBA_520-EACH | C30: X0044RLTFV | D30: B07S962L7Q | E30: 0 | F30: 0 | G30: 0 | H30: 0 | I30: 0 | J30: 0 | K30: 0 | L30: 0 | M30: 0 | N30: 0 | O30: 0 | P30: 0 | Q30: 72 | R30: 54 | S30: 56 | T30: 8 | U30: 0 | V30: 1 | W30: 7 | X30: 171.7 | Y30: 1
