Workbook

Sheet For WH
A1: SKU | B1: ASIN | C1: FNSKU | D1: Item # | E1: Total EA (Transfer to WH06) | F1: Sellable Unit/Set/box to ship | G1: Box to pull | H1: Case to pull | I1: Sets per Box/Case | J1: Label | K1: Packing Instructions | L1: Supplies | M1: UoM | N1: BOX | O1: CASE | P1: Recommended Replenishment Qty | Q1: Actual Qty Replenished | R1: Current WH Inventory | S1: Pack Unit
A2: 8006-CASE | B2: B0BG14KCKZ | C2: X003XE2C7F | D2: =IFERROR(VLOOKUP(A2,Data1!A:B,2,0),"") -> 8006 | E2: =M2*Q2 -> 5235 | F2: =E2/M2 -> 5235 | G2: =IFERROR(ROUNDUP(E2/N2,0),"") | H2: =IFERROR(ROUNDUP(E2/O2,0),"") -> 1047 | I2: =IFERROR(IF(S2="CASE",F2/H2,F2/G2),"") -> 5 | J2: =IF(ISNUMBER(SEARCH("FNSKU",C2)),"Labeling","") | K2: =IFERROR(VLOOKUP(A2,Instruction!A:F,6,0),"") -> • Prepack. Seal box. Apply FNSKU label on box. • Pack in BX-191313 • Apply outer case label (Cover all existing barcodes on case) | L2: =IFERROR(VLOOKUP(A2,Instruction!A:J,10,0),"No Supplies") -> BX-12123, Seal w/ White sticker. BX191313 | M2: =IFERROR(VLOOKUP(A2,Data1!A:C,3,0),1) -> 1 | N2: =IFERROR(VLOOKUP(D2,Data2!$A:$D,4,0),"") -> 0 | O2: =IFERROR(VLOOKUP(D2,Data2!$A:$C,3,0),"") -> 5 | P2: 5235 | Q2: 5235 | S2: CASE
A3: 2227-EACH-UPC | B3: B001BNW7QA | C3: B001BNW7QA | D3: =IFERROR(VLOOKUP(A3,Data1!A:B,2,0),"") -> 2227 | E3: =M3*Q3 -> 3024 | F3: =E3/M3 -> 3024 | G3: =IFERROR(ROUNDUP(E3/N3,0),"") -> 126 | H3: =IFERROR(ROUNDUP(E3/O3,0),"") -> 42 | I3: =IFERROR(IF(S3="CASE",F3/H3,F3/G3),"") -> 72 | J3: =IF(ISNUMBER(SEARCH("FNSKU",C3)),"Labeling","") | K3: =IFERROR(VLOOKUP(A3,Instruction!A:F,6,0),"") -> Apply outer box/case label accordingly to match item# (Cover all existing barcodes on the box/case) | L3: =IFERROR(VLOOKUP(A3,Instruction!A:J,10,0),"No Supplies") -> No Supplies | M3: =IFERROR(VLOOKUP(A3,Data1!A:C,3,0),1) -> 1 | N3: =IFERROR(VLOOKUP(D3,Data2!$A:$D,4,0),"") -> 24 | O3: =IFERROR(VLOOKUP(D3,Data2!$A:$C,3,0),"") -> 72 | P3: 3058 | Q3: 3024 | S3: CASE
A4: 2202-EACH | B4: B003BNZVI4 | C4: B003BNZVI4 | D4: =IFERROR(VLOOKUP(A4,Data1!A:B,2,0),"") -> 2202 | E4: =M4*Q4 -> 1584 | F4: =E4/M4 -> 1584 | G4: =IFERROR(ROUNDUP(E4/N4,0),"") -> 66 | H4: =IFERROR(ROUNDUP(E4/O4,0),"") -> 11 | I4: =IFERROR(IF(S4="CASE",F4/H4,F4/G4),"") -> 144 | J4: =IF(ISNUMBER(SEARCH("FNSKU",C4)),"Labeling","") | K4: =IFERROR(VLOOKUP(A4,Instruction!A:F,6,0),"") -> Apply outer box/case label accordingly to match item# (Cover all existing barcodes on the box/case) | L4: =IFERROR(VLOOKUP(A4,Instruction!A:J,10,0),"No Supplies") -> No Supplies | M4: =IFERROR(VLOOKUP(A4,Data1!A:C,3,0),1) -> 1 | N4: =IFERROR(VLOOKUP(D4,Data2!$A:$D,4,0),"") -> 24 | O4: =IFERROR(VLOOKUP(D4,Data2!$A:$C,3,0),"") -> 144 | P4: 1594 | Q4: 1584 | S4: CASE
A5: 808-EACH | B5: B09DP3TR4F | C5: B09DP3TR4F | D5: =IFERROR(VLOOKUP(A5,Data1!A:B,2,0),"") -> 808 | E5: =M5*Q5 -> 1440 | F5: =E5/M5 -> 1440 | G5: =IFERROR(ROUNDUP(E5/N5,0),"") -> 60 | H5: =IFERROR(ROUNDUP(E5/O5,0),"") -> 10 | I5: =IFERROR(IF(S5="CASE",F5/H5,F5/G5),"") -> 144 | J5: =IF(ISNUMBER(SEARCH("FNSKU",C5)),"Labeling","") | K5: =IFERROR(VLOOKUP(A5,Instruction!A:F,6,0),"") -> Apply outer box/case label accordingly to match item# (Cover all existing barcodes on the box/case) | L5: =IFERROR(VLOOKUP(A5,Instruction!A:J,10,0),"No Supplies") -> No Supplies | M5: =IFERROR(VLOOKUP(A5,Data1!A:C,3,0),1) -> 1 | N5: =IFERROR(VLOOKUP(D5,Data2!$A:$D,4,0),"") -> 24 | O5: =IFERROR(VLOOKUP(D5,Data2!$A:$C,3,0),"") -> 144 | P5: 1509 | Q5: 1440 | S5: CASE
A6: 5043-EACH | B6: B00H9Z198Q | C6: B00H9Z198Q | D6: =IFERROR(VLOOKUP(A6,Data1!A:B,2,0),"") -> 5043 | E6: =M6*Q6 -> 1296 | F6: =E6/M6 -> 1296 | G6: =IFERROR(ROUNDUP(E6/N6,0),"") | H6: =IFERROR(ROUNDUP(E6/O6,0),"") -> 27 | I6: =IFERROR(IF(S6="CASE",F6/H6,F6/G6),"") -> 48 | J6: =IF(ISNUMBER(SEARCH("FNSKU",C6)),"Labeling","") | K6: =IFERROR(VLOOKUP(A6,Instruction!A:F,6,0),"") -> Apply outer box/case label accordingly to match item# (Cover all existing barcodes on the box/case) | L6: =IFERROR(VLOOKUP(A6,Instruction!A:J,10,0),"No Supplies") -> No Supplies | M6: =IFERROR(VLOOKUP(A6,Data1!A:C,3,0),1) -> 1 | N6: =IFERROR(VLOOKUP(D6,Data2!$A:$D,4,0),"") -> 0 | O6: =IFERROR(VLOOKUP(D6,Data2!$A:$C,3,0),"") -> 48 | P6: 1314 | Q6: 1296 | S6: CASE
A7: 510-EACH-B | B7: B0018MN4RA | D7: =IFERROR(VLOOKUP(A7,Data1!A:B,2,0),"") -> 510 | E7: =M7*Q7 -> 1300 | F7: =E7/M7 -> 1300 | G7: =IFERROR(ROUNDUP(E7/N7,0),"") | H7: =IFERROR(ROUNDUP(E7/O7,0),"") -> 26 | I7: =IFERROR(IF(S7="CASE",F7/H7,F7/G7),"") -> 50 | J7: =IF(ISNUMBER(SEARCH("FNSKU",C7)),"Labeling","") | K7: =IFERROR(VLOOKUP(A7,Instruction!A:F,6,0),"") -> Apply outer case label accordingly to match item# (Cover all existing barcodes on the case) | L7: =IFERROR(VLOOKUP(A7,Instruction!A:J,10,0),"No Supplies") -> No Supplies | M7: =IFERROR(VLOOKUP(A7,Data1!A:C,3,0),1) -> 1 | N7: =IFERROR(VLOOKUP(D7,Data2!$A:$D,4,0),"") -> 0 | O7: =IFERROR(VLOOKUP(D7,Data2!$A:$C,3,0),"") -> 50 | P7: 1280 | Q7: 1300 | S7: CASE
A8: 3107-EACH | B8: B07S4GZW7L | C8: X003BBR0T5 | D8: =IFERROR(VLOOKUP(A8,Data1!A:B,2,0),"") -> 3107 | E8: =M8*Q8 -> 1296 | F8: =E8/M8 -> 1296 | G8: =IFERROR(ROUNDUP(E8/N8,0),"") -> 54 | H8: =IFERROR(ROUNDUP(E8/O8,0),"") -> 9 | I8: =IFERROR(IF(S8="CASE",F8/H8,F8/G8),"") -> 144 | J8: =IF(ISNUMBER(SEARCH("FNSKU",C8)),"Labeling","") | K8: =IFERROR(VLOOKUP(A8,Instruction!A:F,6,0),"") -> • Use FNSKU to label each item (cover barcode). Apply outer box/case label accordingly to match item# (Cover all existing barcodes on the box/case) | L8: =IFERROR(VLOOKUP(A8,Instruction!A:J,10,0),"No Supplies") -> No Supplies | M8: =IFERROR(VLOOKUP(A8,Data1!A:C,3,0),1) -> 1 | N8: =IFERROR(VLOOKUP(D8,Data2!$A:$D,4,0),"") -> 24 | O8: =IFERROR(VLOOKUP(D8,Data2!$A:$C,3,0),"") -> 144 | P8: 1277 | Q8: 1296 | S8: CASE
A9: 3100-EACH | B9: B00ZPRYV0I | C9: B00ZPRYV0I | D9: =IFERROR(VLOOKUP(A9,Data1!A:B,2,0),"") -> 3100 | E9: =M9*Q9 -> 1248 | F9: =E9/M9 -> 1248 | G9: =IFERROR(ROUNDUP(E9/N9,0),"") | H9: =IFERROR(ROUNDUP(E9/O9,0),"") -> 26 | I9: =IFERROR(IF(S9="CASE",F9/H9,F9/G9),"") -> 48 | J9: =IF(ISNUMBER(SEARCH("FNSKU",C9)),"Labeling","") | K9: =IFERROR(VLOOKUP(A9,Instruction!A:F,6,0),"") -> Apply outer box/case label accordingly to match item# (Cover all existing barcodes on the box/case) | L9: =IFERROR(VLOOKUP(A9,Instruction!A:J,10,0),"No Supplies") -> No Supplies | M9: =IFERROR(VLOOKUP(A9,Data1!A:C,3,0),1) -> 1 | N9: =IFERROR(VLOOKUP(D9,Data2!$A:$D,4,0),"") -> 0 | O9: =IFERROR(VLOOKUP(D9,Data2!$A:$C,3,0),"") -> 48 | P9: 1245 | Q9: 1248 | S9: CASE
A10: 5053-SET2 | B10: B07S64FRBG | C10: X003AUSTNN | D10: =IFERROR(VLOOKUP(A10,Data1!A:B,2,0),"") -> 5053 | E10: =M10*Q10 -> 2352 | F10: =E10/M10 -> 1176 | G10: =IFERROR(ROUNDUP(E10/N10,0),"") | H10: =IFERROR(ROUNDUP(E10/O10,0),"") -> 49 | I10: =IFERROR(IF(S10="CASE",F10/H10,F10/G10),"") -> 24 | J10: =IF(ISNUMBER(SEARCH("FNSKU",C10)),"Labeling","") | K10: =IFERROR(VLOOKUP(A10,Instruction!A:F,6,0),"") -> • Insert 2 pcs per poly bag (Blue & Red). Apply FNSKU labels on each of the poly bags. • Insert the poly-bagged sets back to CASE (Cover all existing barcodes on the box/case) | L10: =IFERROR(VLOOKUP(A10,Instruction!A:J,10,0),"No Supplies") -> Poly Bag 9 x 12 | M10: =IFERROR(VLOOKUP(A10,Data1!A:C,3,0),1) -> 2 | N10: =IFERROR(VLOOKUP(D10,Data2!$A:$D,4,0),"") -> 0 | O10: =IFERROR(VLOOKUP(D10,Data2!$A:$C,3,0),"") -> 48 | P10: 1175 | Q10: 1176 | S10: CASE
A11: 8005-CASE-B | B11: B0BB8R9HGQ | C11: B0BB8R9HGQ | D11: =IFERROR(VLOOKUP(A11,Data1!A:B,2,0),"") -> 8005 | E11: =M11*Q11 -> 1085 | F11: =E11/M11 -> 1085 | G11: =IFERROR(ROUNDUP(E11/N11,0),"") | H11: =IFERROR(ROUNDUP(E11/O11,0),"") -> 217 | I11: =IFERROR(IF(S11="CASE",F11/H11,F11/G11),"") -> 5 | J11: =IF(ISNUMBER(SEARCH("FNSKU",C11)),"Labeling","") | K11: =IFERROR(VLOOKUP(A11,Instruction!A:F,6,0),"") -> • Prepack. Seal box. Apply FNSKU label on box. • Pack in BX-191313 • Apply outer case label (Cover all existing barcodes on case) | L11: =IFERROR(VLOOKUP(A11,Instruction!A:J,10,0),"No Supplies") -> 0 | M11: =IFERROR(VLOOKUP(A11,Data1!A:C,3,0),1) -> 1 | N11: =IFERROR(VLOOKUP(D11,Data2!$A:$D,4,0),"") -> 0 | O11: =IFERROR(VLOOKUP(D11,Data2!$A:$C,3,0),"") -> 5 | P11: 1087 | Q11: 1085 | S11: CASE
A12: 2306-EACH-1 | B12: B008ZHNN68 | C12: B008ZHNN68 | D12: =IFERROR(VLOOKUP(A12,Data1!A:B,2,0),"") -> 2306 | E12: =M12*Q12 -> 1152 | F12: =E12/M12 -> 1152 | G12: =IFERROR(ROUNDUP(E12/N12,0),"") -> 48 | H12: =IFERROR(ROUNDUP(E12/O12,0),"") -> 8 | I12: =IFERROR(IF(S12="CASE",F12/H12,F12/G12),"") -> 144 | J12: =IF(ISNUMBER(SEARCH("FNSKU",C12)),"Labeling","") | K12: =IFERROR(VLOOKUP(A12,Instruction!A:F,6,0),"") -> Cover inner box barcode. Apply outer case label accordingly to match item# (Cover barcodes on the case) | L12: =IFERROR(VLOOKUP(A12,Instruction!A:J,10,0),"No Supplies") -> No Supplies | M12: =IFERROR(VLOOKUP(A12,Data1!A:C,3,0),1) -> 1 | N12: =IFERROR(VLOOKUP(D12,Data2!$A:$D,4,0),"") -> 24 | O12: =IFERROR(VLOOKUP(D12,Data2!$A:$C,3,0),"") -> 144 | P12: 1087 | Q12: 1152 | S12: CASE
A13: 4106-EACH | B13: B07Q5VPWCP | C13: X003SC97LL | D13: =IFERROR(VLOOKUP(A13,Data1!A:B,2,0),"") -> 4106 | E13: =M13*Q13 -> 1068 | F13: =E13/M13 -> 1068 | G13: =IFERROR(ROUNDUP(E13/N13,0),"") | H13: =IFERROR(ROUNDUP(E13/O13,0),"") -> 89 | I13: =IFERROR(IF(S13="CASE",F13/H13,F13/G13),"") -> 12 | J13: =IF(ISNUMBER(SEARCH("FNSKU",C13)),"Labeling","") | K13: =IFERROR(VLOOKUP(A13,Instruction!A:F,6,0),"") -> • Use FNSKU to label each item (cover barcode). Apply outer box/case label accordingly to match item# (Cover all existing barcodes on the box/case) | L13: =IFERROR(VLOOKUP(A13,Instruction!A:J,10,0),"No Supplies") -> No Supplies | M13: =IFERROR(VLOOKUP(A13,Data1!A:C,3,0),1) -> 1 | N13: =IFERROR(VLOOKUP(D13,Data2!$A:$D,4,0),"") -> 0 | O13: =IFERROR(VLOOKUP(D13,Data2!$A:$C,3,0),"") -> 12 | P13: 1068 | Q13: 1068 | S13: CASE
A14: 582-SET6 | B14: B07S964BMT | C14: X003SC1YG7 | D14: =IFERROR(VLOOKUP(A14,Data1!A:B,2,0),"") -> 582 | E14: =M14*Q14 -> 6288 | F14: =E14/M14 -> 1048 | G14: =IFERROR(ROUNDUP(E14/N14,0),"") | H14: =IFERROR(ROUNDUP(E14/O14,0),"") -> 262 | I14: =IFERROR(IF(S14="CASE",F14/H14,F14/G14),"") -> 4 | J14: =IF(ISNUMBER(SEARCH("FNSKU",C14)),"Labeling","") | K14: =IFERROR(VLOOKUP(A14,Instruction!A:F,6,0),"") -> • Insert 6 pcs per poly bag (6 different color). Apply FNSKU labels on each of the poly bags. • Insert the poly-bagged sets back to CASE (Cover all existing barcodes on the box/case) • New box size BX- 13.25 x 10.75 x 12.75 | L14: =IFERROR(VLOOKUP(A14,Instruction!A:J,10,0),"No Supplies") -> Poly Bag 12 x 15.5 | M14: =IFERROR(VLOOKUP(A14,Data1!A:C,3,0),1) -> 6 | N14: =IFERROR(VLOOKUP(D14,Data2!$A:$D,4,0),"") -> 0 | O14: =IFERROR(VLOOKUP(D14,Data2!$A:$C,3,0),"") -> 24 | P14: 1047 | Q14: 1048 | S14: CASE
A15: 336-EACH | B15: B003BMX65A | C15: X003TIPAXN | D15: =IFERROR(VLOOKUP(A15,Data1!A:B,2,0),"") -> 336 | E15: =M15*Q15 -> 1008 | F15: =E15/M15 -> 1008 | G15: =IFERROR(ROUNDUP(E15/N15,0),"") -> 42 | H15: =IFERROR(ROUNDUP(E15/O15,0),"") -> 7 | I15: =IFERROR(IF(S15="CASE",F15/H15,F15/G15),"") -> 144 | J15: =IF(ISNUMBER(SEARCH("FNSKU",C15)),"Labeling","") | K15: =IFERROR(VLOOKUP(A15,Instruction!A:F,6,0),"") -> • Use FNSKU to label each item (cover barcode). Apply outer box/case label accordingly to match item# (Cover all existing barcodes on the box/case) | L15: =IFERROR(VLOOKUP(A15,Instruction!A:J,10,0),"No Supplies") -> No Supplies | M15: =IFERROR(VLOOKUP(A15,Data1!A:C,3,0),1) -> 1 | N15: =IFERROR(VLOOKUP(D15,Data2!$A:$D,4,0),"") -> 24 | O15: =IFERROR(VLOOKUP(D15,Data2!$A:$C,3,0),"") -> 144 | P15: 1000 | Q15: 1008 | S15: CASE
A16: 4146-EACH | B16: B07Q97RZJC | C16: X003L8UNND | D16: =IFERROR(VLOOKUP(A16,Data1!A:B,2,0),"") -> 4146 | E16: =M16*Q16 -> 984 | F16: =E16/M16 -> 984 | G16: =IFERROR(ROUNDUP(E16/N16,0),"") | H16: =IFERROR(ROUNDUP(E16/O16,0),"") -> 82 | I16: =IFERROR(IF(S16="CASE",F16/H16,F16/G16),"") -> 12 | J16: =IF(ISNUMBER(SEARCH("FNSKU",C16)),"Labeling","") | K16: =IFERROR(VLOOKUP(A16,Instruction!A:F,6,0),"") -> • Use FNSKU to label each item (cover barcode). Apply outer box/case label accordingly to match item# (Cover all existing barcodes on the box/case) | L16: =IFERROR(VLOOKUP(A16,Instruction!A:J,10,0),"No Supplies") -> No Supplies | M16: =IFERROR(VLOOKUP(A16,Data1!A:C,3,0),1) -> 1 | N16: =IFERROR(VLOOKUP(D16,Data2!$A:$D,4,0),"") -> 0 | O16: =IFERROR(VLOOKUP(D16,Data2!$A:$C,3,0),"") -> 12 | P16: 983 | Q16: 984 | S16: CASE
A17: 5045-EACH | B17: B07S94M6P6 | C17: X003DE6G1X | D17: =IFERROR(VLOOKUP(A17,Data1!A:B,2,0),"") -> 5045 | E17: =M17*Q17 -> 960 | F17: =E17/M17 -> 960 | G17: =IFERROR(ROUNDUP(E17/N17,0),"") | H17: =IFERROR(ROUNDUP(E17/O17,0),"") -> 20 | I17: =IFERROR(IF(S17="CASE",F17/H17,F17/G17),"") -> 48 | J17: =IF(ISNUMBER(SEARCH("FNSKU",C17)),"Labeling","") | K17: =IFERROR(VLOOKUP(A17,Instruction!A:F,6,0),"") -> • Use FNSKU to label each item (cover barcode). Apply outer box/case label accordingly to match item# (Cover all existing barcodes on the box/case) | L17: =IFERROR(VLOOKUP(A17,Instruction!A:J,10,0),"No Supplies") -> No Supplies | M17: =IFERROR(VLOOKUP(A17,Data1!A:C,3,0),1) -> 1 | N17: =IFERROR(VLOOKUP(D17,Data2!$A:$D,4,0),"") -> 0 | O17: =IFERROR(VLOOKUP(D17,Data2!$A:$C,3,0),"") -> 48 | P17: 957 | Q17: 960 | S17: CASE
A18: 4107-EACH | B18: B07Q84RJLP | C18: X003L8W44J | D18: =IFERROR(VLOOKUP(A18,Data1!A:B,2,0),"") -> 4107 | E18: =M18*Q18 -> 852 | F18: =E18/M18 -> 852 | G18: =IFERROR(ROUNDUP(E18/N18,0),"") | H18: =IFERROR(ROUNDUP(E18/O18,0),"") -> 71 | I18: =IFERROR(IF(S18="CASE",F18/H18,F18/G18),"") -> 12 | J18: =IF(ISNUMBER(SEARCH("FNSKU",C18)),"Labeling","") | K18: =IFERROR(VLOOKUP(A18,Instruction!A:F,6,0),"") -> • Use FNSKU to label each item (cover barcode). Apply outer box/case label accordingly to match item# (Cover all existing barcodes on the box/case) | L18: =IFERROR(VLOOKUP(A18,Instruction!A:J,10,0),"No Supplies") -> No Supplies | M18: =IFERROR(VLOOKUP(A18,Data1!A:C,3,0),1) -> 1 | N18: =IFERROR(VLOOKUP(D18,Data2!$A:$D,4,0),"") -> 0 | O18: =IFERROR(VLOOKUP(D18,Data2!$A:$C,3,0),"") -> 12 | P18: 857 | Q18: 852 | S18: CASE
A19: 2170-SET6 | B19: B07S165T2T | C19: X003SBSK1F | D19: =IFERROR(VLOOKUP(A19,Data1!A:B,2,0),"") -> 2170 | E19: =M19*Q19 -> 4896 | F19: =E19/M19 -> 816 | G19: =IFERROR(ROUNDUP(E19/N19,0),"") | H19: =IFERROR(ROUNDUP(E19/O19,0),"") -> 102 | I19: =IFERROR(IF(S19="CASE",F19/H19,F19/G19),"") -> 8 | J19: =IF(ISNUMBER(SEARCH("FNSKU",C19)),"Labeling","") | K19: =IFERROR(VLOOKUP(A19,Instruction!A:F,6,0),"") -> • Insert 6 pcs per poly bag (6 different color). Apply FNSKU labels on each of the poly bags. • Insert the poly-bagged sets back to CASE (Cover all existing barcodes on the box/case) | L19: =IFERROR(VLOOKUP(A19,Instruction!A:J,10,0),"No Supplies") -> Poly Bag 12 x 15.5 | M19: =IFERROR(VLOOKUP(A19,Data1!A:C,3,0),1) -> 6 | N19: =IFERROR(VLOOKUP(D19,Data2!$A:$D,4,0),"") -> 0 | O19: =IFERROR(VLOOKUP(D19,Data2!$A:$C,3,0),"") -> 48 | P19: 812 | Q19: 816 | S19: CASE
... A89: 543-PACK2 | B89: B08DFHV95M | C89: X0040DZIND | D89: =IFERROR(VLOOKUP(A89,Data1!A:B,2,0),"") -> 543 | E89: =M89*Q89 -> 432 | F89: =E89/M89 -> 216 | G89: =IFERROR(ROUNDUP(E89/N89,0),"") | H89: =IFERROR(ROUNDUP(E89/O89,0),"") -> 9 | I89: =IFERROR(IF(S89="CASE",F89/H89,F89/G89),"") -> 24 | J89: =IF(ISNUMBER(SEARCH("FNSKU",C89)),"Labeling","") | K89: =IFERROR(VLOOKUP(A89,Instruction!A:F,6,0),"") -> • Put 2 pcs into poly bag, apply FNSKU label. • Put back to CASE (Cover all existing barcodes on the box/case) | L89: =IFERROR(VLOOKUP(A89,Instruction!A:J,10,0),"No Supplies") -> Poly Bag 9 x 12 | M89: =IFERROR(VLOOKUP(A89,Data1!A:C,3,0),1) -> 2 | N89: =IFERROR(VLOOKUP(D89,Data2!$A:$D,4,0),"") -> 0 | O89: =IFERROR(VLOOKUP(D89,Data2!$A:$C,3,0),"") -> 48 | P89: 211 | Q89: 216 | S89: CASE
A90: 1621-EACH | B90: B07RFTSF59 | D90: =IFERROR(VLOOKUP(A90,Data1!A:B,2,0),"") -> 1621 | E90: =M90*Q90 -> 144 | F90: =E90/M90 -> 144 | G90: =IFERROR(ROUNDUP(E90/N90,0),"") -> 6 | H90: =IFERROR(ROUNDUP(E90/O90,0),"") -> 1 | I90: =IFERROR(IF(S90="CASE",F90/H90,F90/G90),"") -> 144 | J90: =IF(ISNUMBER(SEARCH("FNSKU",C90)),"Labeling","") | K90: • Use FNSKU to label each item (cover barcode). • Put item back to CASE. Discard inner box • Apply outer case label accordingly to match item# (Cover all existing barcodes on the case) | L90: =IFERROR(VLOOKUP(A90,Instruction!A:J,10,0),"No Supplies") -> No Supplies | M90: =IFERROR(VLOOKUP(A90,Data1!A:C,3,0),1) -> 1 | N90: =IFERROR(VLOOKUP(D90,Data2!$A:$D,4,0),"") -> 24 | O90: =IFERROR(VLOOKUP(D90,Data2!$A:$C,3,0),"") -> 144 | P90: 209 | Q90: 144 | S90: CASE
A91: 5011-PACK2 | B91: B0127E8W0Q | C91: B0127E8W0Q | D91: =IFERROR(VLOOKUP(A91,Data1!A:B,2,0),"") -> 5011 | E91: =M91*Q91 -> 400 | F91: =E91/M91 -> 200 | G91: =IFERROR(ROUNDUP(E91/N91,0),"") | H91: =IFERROR(ROUNDUP(E91/O91,0),"") -> 8 | I91: =IFERROR(IF(S91="CASE",F91/H91,F91/G91),"") -> 25 | J91: =IF(ISNUMBER(SEARCH("FNSKU",C91)),"Labeling","") | K91: =IFERROR(VLOOKUP(A91,Instruction!A:F,6,0),"") -> • Insert 2 pcs into poly bag, apply FNSKU label. • Put back to CASE (Cover all existing barcodes on the box/case) | L91: =IFERROR(VLOOKUP(A91,Instruction!A:J,10,0),"No Supplies") -> Poly Bag 12 x 15.5 | M91: =IFERROR(VLOOKUP(A91,Data1!A:C,3,0),1) -> 2 | N91: =IFERROR(VLOOKUP(D91,Data2!$A:$D,4,0),"") -> 0 | O91: =IFERROR(VLOOKUP(D91,Data2!$A:$C,3,0),"") -> 50 | P91: 208 | Q91: 200 | S91: CASE
A92: 4126-PACK2 | B92: B08DQHV4BN | C92: X0044R3MG5 | D92: =IFERROR(VLOOKUP(A92,Data1!A:B,2,0),"") -> 4126 | E92: =M92*Q92 -> 408 | F92: =E92/M92 -> 204 | G92: =IFERROR(ROUNDUP(E92/N92,0),"") | H92: =IFERROR(ROUNDUP(E92/O92,0),"") -> 34 | I92: =IFERROR(IF(S92="CASE",F92/H92,F92/G92),"") -> 6 | J92: =IF(ISNUMBER(SEARCH("FNSKU",C92)),"Labeling","") | K92: =IFERROR(VLOOKUP(A92,Instruction!A:F,6,0),"") -> • Put 2 pcs into polybag and apply FNSKU labels on each of the poly bags. • Insert the poly-bagged sets back to CASE (Cover all existing barcodes on the box/case) | L92: =IFERROR(VLOOKUP(A92,Instruction!A:J,10,0),"No Supplies") -> Poly Bag 14.5 x 19 | M92: =IFERROR(VLOOKUP(A92,Data1!A:C,3,0),1) -> 2 | N92: =IFERROR(VLOOKUP(D92,Data2!$A:$D,4,0),"") -> 0 | O92: =IFERROR(VLOOKUP(D92,Data2!$A:$C,3,0),"") -> 12 | P92: 206 | Q92: 204 | S92: CASE
A93: 609-PACK2 | B93: B09C2RFDFH | C93: X0044R3MO7 | D93: =IFERROR(VLOOKUP(A93,Data1!A:B,2,0),"") -> 609 | E93: =M93*Q93 -> 432 | F93: =E93/M93 -> 216 | G93: =IFERROR(ROUNDUP(E93/N93,0),"") -> 18 | H93: =IFERROR(ROUNDUP(E93/O93,0),"") -> 6 | I93: =IFERROR(IF(S93="CASE",F93/H93,F93/G93),"") -> 36 | J93: =IF(ISNUMBER(SEARCH("FNSKU",C93)),"Labeling","") | K93: =IFERROR(VLOOKUP(A93,Instruction!A:F,6,0),"") -> • Put 2 pcs into polybag and apply FNSKU labels on each of the poly bags. • Insert the poly-bagged sets back to CASE (Cover all existing barcodes on the box/case) | L93: =IFERROR(VLOOKUP(A93,Instruction!A:J,10,0),"No Supplies") -> Poly Bag 6 x 9 | M93: =IFERROR(VLOOKUP(A93,Data1!A:C,3,0),1) -> 2 | N93: =IFERROR(VLOOKUP(D93,Data2!$A:$D,4,0),"") -> 24 | O93: =IFERROR(VLOOKUP(D93,Data2!$A:$C,3,0),"") -> 72 | P93: 204 | Q93: 216 | S93: CASE
A94: 3171-EACH | B94: B0BP5Q88DW | C94: X0040DP2BL | D94: =IFERROR(VLOOKUP(A94,Data1!A:B,2,0),"") -> 3171 | E94: =M94*Q94 -> 204 | F94: =E94/M94 -> 204 | G94: =IFERROR(ROUNDUP(E94/N94,0),"") | H94: =IFERROR(ROUNDUP(E94/O94,0),"") -> 17 | I94: =IFERROR(IF(S94="CASE",F94/H94,F94/G94),"") -> 12 | J94: =IF(ISNUMBER(SEARCH("FNSKU",C94)),"Labeling","") | K94: =IFERROR(VLOOKUP(A94,Instruction!A:F,6,0),"") -> • Use FNSKU to label each item (cover barcode). Apply outer case label accordingly to match item# (Cover all existing barcodes on the case) | L94: =IFERROR(VLOOKUP(A94,Instruction!A:J,10,0),"No Supplies") -> No Supplies | M94: =IFERROR(VLOOKUP(A94,Data1!A:C,3,0),1) -> 1 | N94: =IFERROR(VLOOKUP(D94,Data2!$A:$D,4,0),"") -> 0 | O94: =IFERROR(VLOOKUP(D94,Data2!$A:$C,3,0),"") -> 12 | P94: 203 | Q94: 204 | S94: CASE
A95: 5472-SET8 | B95: B096BNMBLN | C95: X003EGLP2Z | D95: =IFERROR(VLOOKUP(A95,Data1!A:B,2,0),"") -> 5472 | E95: =M95*Q95 -> 1632 | F95: =E95/M95 -> 204 | G95: =IFERROR(ROUNDUP(E95/N95,0),"") | H95: =IFERROR(ROUNDUP(E95/O95,0),"") -> 34 | I95: =IFERROR(IF(S95="CASE",F95/H95,F95/G95),"") -> 6 | J95: =IF(ISNUMBER(SEARCH("FNSKU",C95)),"Labeling","") | K95: =IFERROR(VLOOKUP(A95,Instruction!A:F,6,0),"") -> • Insert 8 pcs per poly bag (8 different color). Apply FNSKU labels on each of the poly bags. • Insert the poly-bagged sets back to CASE (Cover all existing barcodes on the box/case) • New box size BX- 13.25 x 10.75 x 12.75 | L95: =IFERROR(VLOOKUP(A95,Instruction!A:J,10,0),"No Supplies") -> Poly Bag 9 x 12 | M95: =IFERROR(VLOOKUP(A95,Data1!A:C,3,0),1) -> 8 | N95: =IFERROR(VLOOKUP(D95,Data2!$A:$D,4,0),"") -> 0 | O95: =IFERROR(VLOOKUP(D95,Data2!$A:$C,3,0),"") -> 48 | P95: 202 | Q95: 204 | S95: CASE
A96: 4122-EACH | B96: B07Q97RHBH | C96: X003SBSJEN | D96: =IFERROR(VLOOKUP(A96,Data1!A:B,2,0),"") -> 4122 | E96: =M96*Q96 -> 204 | F96: =E96/M96 -> 204 | G96: =IFERROR(ROUNDUP(E96/N96,0),"") | H96: =IFERROR(ROUNDUP(E96/O96,0),"") -> 17 | I96: =IFERROR(IF(S96="CASE",F96/H96,F96/G96),"") -> 12 | J96: =IF(ISNUMBER(SEARCH("FNSKU",C96)),"Labeling","") | K96: =IFERROR(VLOOKUP(A96,Instruction!A:F,6,0),"") -> • Use FNSKU to label each item (cover barcode). Apply outer box/case label accordingly to match item# (Cover all existing barcodes on the box/case) | L96: =IFERROR(VLOOKUP(A96,Instruction!A:J,10,0),"No Supplies") -> No Supplies | M96: =IFERROR(VLOOKUP(A96,Data1!A:C,3,0),1) -> 1 | N96: =IFERROR(VLOOKUP(D96,Data2!$A:$D,4,0),"") -> 0 | O96: =IFERROR(VLOOKUP(D96,Data2!$A:$C,3,0),"") -> 12 | P96: 200 | Q96: 204 | S96: CASE
A97: 520-EACH | B97: B07S962L7Q | C97: X0044RLTFV | D97: =IFERROR(VLOOKUP(A97,Data1!A:B,2,0),"") -> 520 | E97: =M97*Q97 -> 216 | F97: =E97/M97 -> 216 | G97: =IFERROR(ROUNDUP(E97/N97,0),"") | H97: =IFERROR(ROUNDUP(E97/O97,0),"") -> 6 | I97: =IFERROR(IF(S97="CASE",F97/H97,F97/G97),"") -> 36 | J97: =IF(ISNUMBER(SEARCH("FNSKU",C97)),"Labeling","") | K97: =IFERROR(VLOOKUP(A97,Instruction!A:F,6,0),"") -> • Use FNSKU to label each item (cover barcode). Apply outer case label accordingly to match item# (Cover all existing barcodes on the case) | L97: =IFERROR(VLOOKUP(A97,Instruction!A:J,10,0),"No Supplies") -> No Supplies | M97: =IFERROR(VLOOKUP(A97,Data1!A:C,3,0),1) -> 1 | N97: =IFERROR(VLOOKUP(D97,Data2!$A:$D,4,0),"") -> 0 | O97: =IFERROR(VLOOKUP(D97,Data2!$A:$C,3,0),"") -> 36 | P97: 199 | Q97: 216 | S97: CASE
A98: 2309-EACH | B98: B0BP5FBZKF | C98: X003TDI6Z7 | D98: =IFERROR(VLOOKUP(A98,Data1!A:B,2,0),"") -> 2309 | E98: =M98*Q98 -> 144 | F98: =E98/M98 -> 144 | G98: =IFERROR(ROUNDUP(E98/N98,0),"") -> 6 | H98: =IFERROR(ROUNDUP(E98/O98,0),"") -> 1 | I98: =IFERROR(IF(S98="CASE",F98/H98,F98/G98),"") -> 144 | J98: =IF(ISNUMBER(SEARCH("FNSKU",C98)),"Labeling","") | K98: =IFERROR(VLOOKUP(A98,Instruction!A:F,6,0),"") -> • Use FNSKU to label each item (cover barcode). • Put item back to CASE. Discard inner box • Apply outer case label accordingly to match item# (Cover all existing barcodes on the case) | L98: =IFERROR(VLOOKUP(A98,Instruction!A:J,10,0),"No Supplies") -> No Supplies | M98: =IFERROR(VLOOKUP(A98,Data1!A:C,3,0),1) -> 1 | N98: =IFERROR(VLOOKUP(D98,Data2!$A:$D,4,0),"") -> 24 | O98: =IFERROR(VLOOKUP(D98,Data2!$A:$C,3,0),"") -> 144 | P98: 197 | Q98: 144 | S98: CASE
A99: 4104-EACH | B99: B07Q97R8X9 | C99: X003SC1YCL | D99: =IFERROR(VLOOKUP(A99,Data1!A:B,2,0),"") -> 4104 | E99: =M99*Q99 -> 192 | F99: =E99/M99 -> 192 | G99: =IFERROR(ROUNDUP(E99/N99,0),"") | H99: =IFERROR(ROUNDUP(E99/O99,0),"") -> 16 | I99: =IFERROR(IF(S99="CASE",F99/H99,F99/G99),"") -> 12 | J99: =IF(ISNUMBER(SEARCH("FNSKU",C99)),"Labeling","") | K99: =IFERROR(VLOOKUP(A99,Instruction!A:F,6,0),"") -> • Use FNSKU to label each item (cover barcode). Apply outer box/case label accordingly to match item# (Cover all existing barcodes on the box/case) | L99: =IFERROR(VLOOKUP(A99,Instruction!A:J,10,0),"No Supplies") -> No Supplies | M99: =IFERROR(VLOOKUP(A99,Data1!A:C,3,0),1) -> 1 | N99: =IFERROR(VLOOKUP(D99,Data2!$A:$D,4,0),"") -> 0 | O99: =IFERROR(VLOOKUP(D99,Data2!$A:$C,3,0),"") -> 12 | P99: 189 | Q99: 192 | S99: CASE
A100: 2010-EACH | B100: B07RZMG648 | D100: =IFERROR(VLOOKUP(A100,Data1!A:B,2,0),"") -> 2010 | E100: =M100*Q100 -> 144 | F100: =E100/M100 -> 144 | G100: =IFERROR(ROUNDUP(E100/N100,0),"") -> 6 | H100: =IFERROR(ROUNDUP(E100/O100,0),"") -> 1 | I100: =IFERROR(IF(S100="CASE",F100/H100,F100/G100),"") -> 144 | J100: =IF(ISNUMBER(SEARCH("FNSKU",C100)),"Labeling","") | K100: • Use FNSKU to label each item (cover barcode). • Put item back to CASE. Discard inner box • Apply outer case label accordingly to match item# (Cover all existing barcodes on the case) | L100: =IFERROR(VLOOKUP(A100,Instruction!A:J,10,0),"No Supplies") -> No Supplies | M100: =IFERROR(VLOOKUP(A100,Data1!A:C,3,0),1) -> 1 | N100: =IFERROR(VLOOKUP(D100,Data2!$A:$D,4,0),"") -> 24 | O100: =IFERROR(VLOOKUP(D100,Data2!$A:$C,3,0),"") -> 144 | P100: 188 | Q100: 144 | S100: CASE
A101: 847-CASE | B101: B08QRLYMJ4 | C101: X003SCCXUD | D101: =IFERROR(VLOOKUP(A101,Data1!A:B,2,0),"") -> 847 | E101: =M101*Q101 -> 4464 | F101: =E101/M101 -> 186 | G101: =IFERROR(ROUNDUP(E101/N101,0),"") | H101: =IFERROR(ROUNDUP(E101/O101,0),"") -> 186 | I101: =IFERROR(IF(S101="CASE",F101/H101,F101/G101),"") -> 1 | J101: =IF(ISNUMBER(SEARCH("FNSKU",C101)),"Labeling","") | K101: =IFERROR(VLOOKUP(A101,Instruction!A:F,6,0),"") -> • Apply label “THIS IS A SET”. Apply FNSKU to each case. • *Make sure all labels stick securely on the case*. Apply outer case label. Cover all visible barcodes on case | L101: =IFERROR(VLOOKUP(A101,Instruction!A:J,10,0),"No Supplies") -> No Supplies | M101: =IFERROR(VLOOKUP(A101,Data1!A:C,3,0),1) -> 24 | N101: =IFERROR(VLOOKUP(D101,Data2!$A:$D,4,0),"") -> 0 | O101: =IFERROR(VLOOKUP(D101,Data2!$A:$C,3,0),"") -> 24 | P101: 186 | Q101: 186 | S101: CASE
A102: 3451-SET6 | B102: B08579RYRM | C102: X003UI8KTN | D102: =IFERROR(VLOOKUP(A102,Data1!A:B,2,0),"") -> 3451 | E102: =M102*Q102 -> 1128 | F102: =E102/M102 -> 188 | G102: =IFERROR(ROUNDUP(E102/N102,0),"") | H102: =IFERROR(ROUNDUP(E102/O102,0),"") -> 47 | I102: =IFERROR(IF(S102="CASE",F102/H102,F102/G102),"") -> 4 | J102: =IF(ISNUMBER(SEARCH("FNSKU",C102)),"Labeling","") | K102: =IFERROR(VLOOKUP(A102,Instruction!A:F,6,0),"") -> • Insert 6 pcs per poly bag (different color). Apply FNSKU labels on each of the poly bags. • Insert the poly-bagged sets back to BX-191313 • New box size BX- 14 x 13.75 x 16.75 | L102: =IFERROR(VLOOKUP(A102,Instruction!A:J,10,0),"No Supplies") -> Poly Bag 10 x 13 | M102: =IFERROR(VLOOKUP(A102,Data1!A:C,3,0),1) -> 6 | N102: =IFERROR(VLOOKUP(D102,Data2!$A:$D,4,0),"") -> 0 | O102: =IFERROR(VLOOKUP(D102,Data2!$A:$C,3,0),"") -> 24 | P102: 186 | Q102: 188 | S102: CASE
A103: 5096-BOX | B103: B07XL4V3N1 | C103: X003GHJQB9 | D103: =IFERROR(VLOOKUP(A103,Data1!A:B,2,0),"") -> 5096 | E103: =M103*Q103 -> 4608 | F103: =E103/M103 -> 192 | G103: =IFERROR(ROUNDUP(E103/N103,0),"") -> 192 | H103: =IFERROR(ROUNDUP(E103/O103,0),"") -> 16 | I103: =IFERROR(IF(S103="CASE",F103/H103,F103/G103),"") -> 12 | J103: =IF(ISNUMBER(SEARCH("FNSKU",C103)),"Labeling","") | K103: =IFERROR(VLOOKUP(A103,Instruction!A:F,6,0),"") -> • For inner box: apply FNSKU label and “THIS IS A SET” label • Cover all visible barcodes on the box/case • Place all the inner boxes back into the CASE. • Apply outer case label (Cover barcodes on the CASE) | L103: =IFERROR(VLOOKUP(A103,Instruction!A:J,10,0),"No Supplies") -> No Supplies | M103: =IFERROR(VLOOKUP(A103,Data1!A:C,3,0),1) -> 24 | N103: =IFERROR(VLOOKUP(D103,Data2!$A:$D,4,0),"") -> 24 | O103: =IFERROR(VLOOKUP(D103,Data2!$A:$C,3,0),"") -> 288 | P103: 186 | Q103: 192 | S103: CASE
A104: 842-SET4 | B104: B07R95PGYJ | C104: X003SCCWXL | D104: =IFERROR(VLOOKUP(A104,Data1!A:B,2,0),"") -> 842 | E104: =M104*Q104 -> 744 | F104: =E104/M104 -> 186 | G104: =IFERROR(ROUNDUP(E104/N104,0),"") | H104: =IFERROR(ROUNDUP(E104/O104,0),"") -> 31 | I104: =IFERROR(IF(S104="CASE",F104/H104,F104/G104),"") -> 6 | J104: =IF(ISNUMBER(SEARCH("FNSKU",C104)),"Labeling","") | K104: =IFERROR(VLOOKUP(A104,Instruction!A:F,6,0),"") -> • Insert 4 pcs per poly bag (different color). Apply FNSKU on the poly bags. • Insert the poly-bagged sets back to CASE (Cover all existing barcodes on the box/case) • Buddle box size BX- 17 x 16.5 x 22 | L104: =IFERROR(VLOOKUP(A104,Instruction!A:J,10,0),"No Supplies") -> Poly Bag 14.5 x 19 | M104: =IFERROR(VLOOKUP(A104,Data1!A:C,3,0),1) -> 4 | N104: =IFERROR(VLOOKUP(D104,Data2!$A:$D,4,0),"") -> 0 | O104: =IFERROR(VLOOKUP(D104,Data2!$A:$C,3,0),"") -> 24 | P104: 183 | Q104: 186 | S104: CASE
A105: 835-SET4-b | B105: B0D98ZL8R2 | C105: X004HPCH5V | D105: =IFERROR(VLOOKUP(A105,Data1!A:B,2,0),"") -> 835 | E105: =M105*Q105 -> 720 | F105: =E105/M105 -> 180 | G105: =IFERROR(ROUNDUP(E105/N105,0),"") | H105: =IFERROR(ROUNDUP(E105/O105,0),"") -> 30 | I105: =IFERROR(IF(S105="CASE",F105/H105,F105/G105),"") -> 6 | J105: =IF(ISNUMBER(SEARCH("FNSKU",C105)),"Labeling","") | K105: =IFERROR(VLOOKUP(A105,Instruction!A:F,6,0),"") -> • Insert 4 pcs (different color) per poly bag. Apply FNSKU labels on each of the poly bags. Cover all existing barcode. • Insert the poly-bagged sets back to CASE. (Cover all existing barcodes on the box/case) | L105: =IFERROR(VLOOKUP(A105,Instruction!A:J,10,0),"No Supplies") -> 0 | M105: =IFERROR(VLOOKUP(A105,Data1!A:C,3,0),1) -> 4 | N105: =IFERROR(VLOOKUP(D105,Data2!$A:$D,4,0),"") -> 0 | O105: =IFERROR(VLOOKUP(D105,Data2!$A:$C,3,0),"") -> 24 | P105: 182 | Q105: 180 | S105: CASE
A106: 4145-EACH | B106: B07Q8WM9D9 | C106: X003SBSK33 | D106: =IFERROR(VLOOKUP(A106,Data1!A:B,2,0),"") -> 4145 | E106: =M106*Q106 -> 180 | F106: =E106/M106 -> 180 | G106: =IFERROR(ROUNDUP(E106/N106,0),"") | H106: =IFERROR(ROUNDUP(E106/O106,0),"") -> 15 | I106: =IFERROR(IF(S106="CASE",F106/H106,F106/G106),"") -> 12 | J106: =IF(ISNUMBER(SEARCH("FNSKU",C106)),"Labeling","") | K106: =IFERROR(VLOOKUP(A106,Instruction!A:F,6,0),"") -> • Use FNSKU to label each item (cover barcode). Apply outer box/case label accordingly to match item# (Cover all existing barcodes on the box/case) | L106: =IFERROR(VLOOKUP(A106,Instruction!A:J,10,0),"No Supplies") -> No Supplies | M106: =IFERROR(VLOOKUP(A106,Data1!A:C,3,0),1) -> 1 | N106: =IFERROR(VLOOKUP(D106,Data2!$A:$D,4,0),"") -> 0 | O106: =IFERROR(VLOOKUP(D106,Data2!$A:$C,3,0),"") -> 12 | P106: 177 | Q106: 180 | S106: CASE
A107: 608-EACH | B107: B003BMWZ48 | C107: X003EGFQKR | D107: =IFERROR(VLOOKUP(A107,Data1!A:B,2,0),"") -> 608 | E107: =M107*Q107 -> 144 | F107: =E107/M107 -> 144 | G107: =IFERROR(ROUNDUP(E107/N107,0),"") -> 6 | H107: =IFERROR(ROUNDUP(E107/O107,0),"") -> 2 | I107: =IFERROR(IF(S107="CASE",F107/H107,F107/G107),"") -> 72 | J107: =IF(ISNUMBER(SEARCH("FNSKU",C107)),"Labeling","") | K107: =IFERROR(VLOOKUP(A107,Instruction!A:F,6,0),"") -> • Use FNSKU to label each item (cover barcode). Apply outer box/case label accordingly to match item# (Cover all existing barcodes on the box/case) | L107: =IFERROR(VLOOKUP(A107,Instruction!A:J,10,0),"No Supplies") -> No Supplies | M107: =IFERROR(VLOOKUP(A107,Data1!A:C,3,0),1) -> 1 | N107: =IFERROR(VLOOKUP(D107,Data2!$A:$D,4,0),"") -> 24 | O107: =IFERROR(VLOOKUP(D107,Data2!$A:$C,3,0),"") -> 72 | P107: 176 | Q107: 144 | S107: CASE
A108: 804-SET6 | B108: B07R81PNF1 | C108: X003SCIA87 | D108: =IFERROR(VLOOKUP(A108,Data1!A:B,2,0),"") -> 804 | E108: =M108*Q108 -> 1008 | F108: =E108/M108 -> 168 | G108: =IFERROR(ROUNDUP(E108/N108,0),"") -> 42 | H108: =IFERROR(ROUNDUP(E108/O108,0),"") -> 7 | I108: =IFERROR(IF(S108="CASE",F108/H108,F108/G108),"") -> 24 | J108: =IF(ISNUMBER(SEARCH("FNSKU",C108)),"Labeling","") | K108: =IFERROR(VLOOKUP(A108,Instruction!A:F,6,0),"") -> • Put 6 pcs per poly bag (6 different color). Apply FNSKU labels on each of the poly bags. • Put the poly-bagged sets back to CASE (discard inner box) (Cover all existing barcodes on the box/case) | L108: =IFERROR(VLOOKUP(A108,Instruction!A:J,10,0),"No Supplies") -> Poly Bag 9 x 12 | M108: =IFERROR(VLOOKUP(A108,Data1!A:C,3,0),1) -> 6 | N108: =IFERROR(VLOOKUP(D108,Data2!$A:$D,4,0),"") -> 24 | O108: =IFERROR(VLOOKUP(D108,Data2!$A:$C,3,0),"") -> 144 | P108: 173 | Q108: 168 | S108: CASE
A109: 2022-PACK2 | B109: B08GWYQ4S5 | C109: X0044R3MPB | D109: =IFERROR(VLOOKUP(A109,Data1!A:B,2,0),"") -> 2022 | E109: =M109*Q109 -> 288 | F109: =E109/M109 -> 144 | G109: =IFERROR(ROUNDUP(E109/N109,0),"") -> 12 | H109: =IFERROR(ROUNDUP(E109/O109,0),"") -> 2 | I109: =IFERROR(IF(S109="CASE",F109/H109,F109/G109),"") -> 72 | J109: =IF(ISNUMBER(SEARCH("FNSKU",C109)),"Labeling","") | K109: =IFERROR(VLOOKUP(A109,Instruction!A:F,6,0),"") -> • Put 2 pcs into polybag and apply FNSKU labels on each of the poly bags. • Insert the poly-bagged sets back to BOX (Cover all existing barcodes on the box/case) | L109: =IFERROR(VLOOKUP(A109,Instruction!A:J,10,0),"No Supplies") -> Poly Bag 6 x 9 | M109: =IFERROR(VLOOKUP(A109,Data1!A:C,3,0),1) -> 2 | N109: =IFERROR(VLOOKUP(D109,Data2!$A:$D,4,0),"") -> 24 | O109: =IFERROR(VLOOKUP(D109,Data2!$A:$C,3,0),"") -> 144 | P109: 165 | Q109: 144 | S109: CASE
...

Sheet SO
F1: ATTENTION: AWD removal | G1: Qty | H1: Used
B2: Item# | C2: BOX | D2: CASE | F2: 5027-CASE | G2: 10 | H2: 1
B3: 203 | C3: 1
B4: 534 | C4: 1
B5: 713 | C5: 1
B6: 2012 | C6: 1
B7: 2225 | C7: 1
B8: 609 | C8: 2
B9: 767 | C9: 2
B10: 1293 | C10: 2
B11: 2204 | C11: 2
B12: 2043 | C12: 3
B13: 5074 | C13: 3
B14: S-2 | C14: 4
B15: 837 | C15: 5
B16: 508 | D16: 1
B17: 530 | D17: 1
B18: 569 | D18: 1
B19: 1286 | D19: 1
B20: 2405 | D20: 1
B21: 4151 | D21: 1
B22: 5053 | D22: 1
B23: 5087 | D23: 1
B24: 5173 | D24: 1
B25: 6303 | D25: 1
B26: 533 | D26: 2
B27: 608 | D27: 2
... B46: 4122 | D46: 4
B47: 942-A | D47: 4
B48: 560 | D48: 5
B49: 609 | D49: 5
B50: 5027 | D50: 5
B51: 5043 | D51: 5
B52: 4576436 | D52: 5
B53: 3459-A | D53: 5
B54: 532 | D54: 6
B55: 39200 | D55: 6
B56: 3451 | D56: 8
B57: 3191 | D57: 9
B58: 3467 | D58: 9
...

Sheet Sheet1
A1: Workflow name | B1: wf9547a679-894d-4f41-afc0-a2dbe4aa3f05
A2: Shipment ID | B2: STAR-VKFAPNKKS6S4A
A3: Shipment name | B3: To be assigned
A4: Ship to | B4: NORTH EAST, MD
A5: Boxes | B5: 241
A6: SKUs | B6: 72
A7: Units | B7: 4352
A9: Case packed (241 boxes)
A10: SKU | B10: Title | C10: ASIN | D10: FNSKU | E10: Case pack template name | F10: Condition | G10: Who preps units? | H10: Who labels units? | I10: Prep type | J10: Box weight (lb) | K10: Box length (inch) | L10: Box width (inch) | M10: Box height (inch) | N10: Units per box | O10: Total boxes | P10: Total units | Q10: Box ID
A11: FBA_533-BOX | B11: BAZIC Subtraction Flash Cards, Numbers Math Flashcards Game at School Home, Problem Solving (36/Pack), 24-Packs | C11: B07XQLGMSV | D11: X0044RLXAR | E11: Case (3 boxes) | F11: New | G11: By seller | H11: By seller | I11: No prep needed | J11: 16.4 | K11: 7 | L11: 12 | M11: 11 | N11: 3 | O11: 2 | P11: 6 | Q11: To be assigned
A12: FBA_508-EACH | B12: BAZIC Composition Book Wide Ruled 100 Sheet Black Marble Notebook, Writing Journal Comp Lined Notebooks for School, 1-Pack | C12: B001E75OY0 | D12: B001E75OY0 | E12: ASDN_DEFAULT_CONFIG | F12: New | G12: By seller | H12: - | I12: No prep needed | J12: 31.8 | K12: 15.5 | L12: 10 | M12: 8.5 | N12: 48 | O12: 1 | P12: 48 | Q12: To be assigned
A13: FBA_3107-BOX | B13: BAZIC Binder Dividers w/ 10 Color Tabs 8. 5" x 11", 11 Hole Punch Plastic Index Divider with Tab for 3 Ring Binders, (10/Pack), 24-Packs | C13: B07XQJZL28 | D13: X0045A6VWX | E13: Case (6 boxes) | F13: New | G13: By seller | H13: By seller | I13: No prep needed | J13: 37.6 | K13: 10 | L13: 15 | M13: 13 | N13: 6 | O13: 2 | P13: 12 | Q13: To be assigned
A14: FBA_942-A-EA-BL | B14: BAZIC Desktop Tape Dispenser w/Tape Refill 3/4" x 250", 1" Core Weighted Non-Skid Base, Sharpe Blade Tapes Holder, Blue Color, 1-Pack | C14: B0CV2WM9FJ | D14: X0044KCA65 | E14: Case (12) | F14: New | G14: By seller | H14: By seller | I14: No prep needed | J14: 20 | K14: 8 | L14: 12 | M14: 11 | N14: 12 | O14: 1 | P14: 12 | Q14: To be assigned
A15: FBA_3191-CASE | B15: BAZIC 3 Ring Binder 1" Economy View Binders Organizer - Blue, Round Ring, Hold 175 Sheets Paper, for School Office Home, 12-Count | C15: B07QF5ZS6P | D15: X003SBSJJN | E15: 1 Case | F15: New | G15: By seller | H15: By seller | I15: No prep needed | J15: 8.64 | K15: 6 | L15: 13.25 | M15: 12.25 | N15: 1 | O15: 9 | P15: 9 | Q15: To be assigned
A16: FBA_3467-EACH | B16: BAZIC Glitter Glue Tube Classic Color, Non-Toxic Washable Glitter Glue for Slime Paints DIY Art Crafts Party (120ml/Pack), 1-Pack | C16: B01HDJMKBM | D16: B01HDJMKBM | E16: Case (72) | F16: New | G16: By seller | H16: - | I16: No prep needed | J16: 30.58 | K16: 12 | L16: 13.5 | M16: 13.25 | N16: 72 | O16: 4 | P16: 288 | Q16: To be assigned
A17: FBA_3167-SET4 | B17: BAZIC 3 Ring Binder 1" Economy View Binders Organizer - Pastel Color, Round Ring, Hold 175 Sheets Paper, for School Office Home, 4-Count | C17: B08LP2FGJM | D17: X003BVZHKJ | E17: Case Pack (10 Sets) | F17: New | G17: - | H17: By seller | I17: No prep needed | J17: 28 | K17: 13 | L17: 19 | M17: 13 | N17: 10 | O17: 10 | P17: 100 | Q17: To be assigned
A18: FBA_609-PACK4 | B18: BAZIC Staples Standard (26/6) Metallic Color 3000/Pack, Stapler Refill Standard Size Staple, Assorted Colors, 4-Packs | C18: B09C2QNFTV | D18: X0044RLX89 | E18: Case (18) | F18: New | G18: By seller | H18: By seller | I18: No prep needed | J18: 17.08 | K18: 5 | L18: 14 | M18: 8 | N18: 18 | O18: 3 | P18: 54 | Q18: To be assigned
A19: FBA_5414-PACK3 | B19: BAZIC Poster Board Glitter Color 11" X 14", Sparkling Frame Colored Poster Board Paper for Christmas Wedding Birthday Craft Project (5/Pack), 3-Packs | C19: B08FZR2GLR | D19: X00468H3EJ | E19: ASDN_DEFAULT_CONFIG | F19: New | G19: By seller | H19: By seller | I19: No prep needed | J19: 19 | K19: 16 | L19: 15 | M19: 6 | N19: 16 | O19: 2 | P19: 32 | Q19: To be assigned
A20: FBA_4577036-SET2 | B20: Disney Princess Coloring Book 2 Titles, Fun Game Workbook for Learning Drawing Coloring, Gift for Kids Toddler Activity at Classroom Home, 80 Pages, 2-Pack | C20: B0897CBHTZ | D20: X004BHUY9L | E20: Case (18 Sets) | F20: New | G20: - | H20: By seller | I20: No prep needed | J20: 10.6 | K20: 4 | L20: 16 | M20: 11 | N20: 18 | O20: 2 | P20: 36 | Q20: To be assigned
A21: FBA_5043-PACK2 | B21: BAZIC Sketch Pad 50 Sheet 6" X 8", Top Bound Spiral Sketchbook Drawing Pads, Sketching Paper Coloring Book for Artist School, 2-Pack | C21: B08DFJW6V4 | D21: X0040DSNM1 | E21: Case (24) | F21: New | G21: By seller | H21: By seller | I21: No prep needed | J21: 22 | K21: 9.75 | L21: 12.75 | M21: 10 | N21: 24 | O21: 3 | P21: 72 | Q21: To be assigned
A22: FBA_2405-EACH | B22: BAZIC White Chalk, Standard Size Blackboard Chalkboard Chalks, Great Game Activity for Kids, Art Teacher Office School Home (24/Pack), 1-Pack | C22: B003BUK0UG | D22: B003BUK0UG | E22: ASDN_DEFAULT_CONFIG | F22: New | G22: By seller | H22: - | I22: No prep needed | J22: 15 | K22: 8 | L22: 6 | M22: 4 | N22: 24 | O22: 1 | P22: 24 | Q22: To be assigned
... A82: FBA_560-PACK6 | B82: BAZIC Writing Pad 100 Sheets 6" X 9", Lined Ruled Memo Writing Notebook, Easy Tear Note Paper for Office School Home, 6-Pack [unknown_binding] | C82: B08FBQM8VF | D82: X003SFDOWB | E82: ASDN_DEFAULT_CONFIG | F82: New | G82: By seller | H82: By seller | I82: No prep needed | J82: 30 | K82: 12 | L82: 13 | M82: 16 | N82: 8 | O82: 5 | P82: 40 | Q82: To be assigned

Sheet AWD Return
A1: SKU | B1: Item | C1: Qty (EA)
A2: 5027-EACH | B2: 5027 | C2: 480
A3: 560-EACH | B3: 560 | C3: =263-96 -> 167
A4: 3001-EACH | B4: 3001 | C4: 24

Sheet For WH Single
A1: SKU | B1: ASIN | C1: FNSKU | D1: Item | E1: Total EA (Transfer to WH06) | F1: Sellable Unit/Set/box to ship | G1: Box 1 units | H1: Box 2 units | I1: Label | J1: Packing Instructions | K1: Supplies | L1: UoM | M1: -- | N1: --2 | O1: Recommended Replenishment Qty | P1: Current WH Inventory
A2: 4403-SET6 | B2: B0BRNSWP12 | C2: X0043V3DCZ | D2: =VLOOKUP(A2,Data1!A:B,2,0) -> 4403 | E2: =L2*O2 -> 12 | F2: =O2 -> 2 | G2: 2 | I2: Labeling | J2: =VLOOKUP(A2,Instruction!A:F,7,0) -> #REF! | L2: =VLOOKUP(A2,Data1!A:C,3,0) -> 6 | O2: 2 | P2: =VLOOKUP(D2,[1]Sheet1!$B:$D,3,0) -> 10343
A3: 4400-SET2 | B3: B07SFT7P7X | C3: X0043UN7EF | D3: =VLOOKUP(A3,Data1!A:B,2,0) -> 4400 | E3: =L3*O3 -> 8 | F3: =O3 -> 4 | G3: 4 | I3: Labeling | J3: =VLOOKUP(A3,Instruction!A:F,7,0) -> #REF! | L3: =VLOOKUP(A3,Data1!A:C,3,0) -> 2 | O3: 4 | P3: =VLOOKUP(D3,[1]Sheet1!$B:$D,3,0) -> 28720
A4: 17036-EACH | B4: B0CQ66C7RL | C4: X0043UNGZ5 | D4: =VLOOKUP(A4,Data1!A:B,2,0) -> 17036 | E4: =L4*O4 -> 6 | F4: =O4 -> 6 | G4: 6 | I4: Labeling | J4: =VLOOKUP(A4,Instruction!A:F,7,0) -> #REF! | L4: =VLOOKUP(A4,Data1!A:C,3,0) -> 1 | O4: 6 | P4: =VLOOKUP(D4,[1]Sheet1!$B:$D,3,0) -> 19554
A5: 709-EACH | B5: B0CGW5J3SV | C5: X0043V3OBP | D5: =VLOOKUP(A5,Data1!A:B,2,0) -> 709 | E5: =L5*O5 -> 6 | F5: =O5 -> 6 | G5: 6 | I5: Labeling | J5: =VLOOKUP(A5,Instruction!A:F,7,0) -> #REF! | L5: =VLOOKUP(A5,Data1!A:C,3,0) -> 1 | O5: 6 | P5: =VLOOKUP(D5,[1]Sheet1!$B:$D,3,0) -> 2396
A6: 17035-EACH | B6: B0CQ67CVM7 | C6: X0043UZRXT | D6: =VLOOKUP(A6,Data1!A:B,2,0) -> 17035 | E6: =L6*O6 -> 6 | F6: =O6 -> 6 | G6: 6 | I6: Labeling | J6: =VLOOKUP(A6,Instruction!A:F,7,0) -> #REF! | L6: =VLOOKUP(A6,Data1!A:C,3,0) -> 1 | O6: 6 | P6: =VLOOKUP(D6,[1]Sheet1!$B:$D,3,0) -> 33166
A7: 914-EACH | B7: B07SKF1B25 | C7: X00446K72N | D7: =VLOOKUP(A7,Data1!A:B,2,0) -> 914 | E7: =L7*O7 -> 4 | F7: =O7 -> 4 | H7: 4 | I7: Labeling | J7: =VLOOKUP(A7,Instruction!A:F,7,0) -> #REF! | L7: =VLOOKUP(A7,Data1!A:C,3,0) -> 1 | O7: 4 | P7: =VLOOKUP(D7,[1]Sheet1!$B:$D,3,0) -> 32063
A8: 905-EACH | B8: B07SKD994F | C8: X0043UN5TH | D8: =VLOOKUP(A8,Data1!A:B,2,0) -> 905 | E8: =L8*O8 -> 4 | F8: =O8 -> 4 | H8: 4 | I8: Labeling | J8: =VLOOKUP(A8,Instruction!A:F,7,0) -> #REF! | L8: =VLOOKUP(A8,Data1!A:C,3,0) -> 1 | O8: 4 | P8: =VLOOKUP(D8,[1]Sheet1!$B:$D,3,0) -> 86003
A9: 1215-EACH | B9: B0CJMRSK5J | C9: X0043UN4H5 | D9: =VLOOKUP(A9,Data1!A:B,2,0) -> 1215 | E9: =L9*O9 -> 6 | F9: =O9 -> 6 | H9: 6 | I9: Labeling | J9: =VLOOKUP(A9,Instruction!A:F,7,0) -> #REF! | L9: =VLOOKUP(A9,Data1!A:C,3,0) -> 1 | O9: 6 | P9: =VLOOKUP(D9,[1]Sheet1!$B:$D,3,0) -> 10438
A10: 1227-EACH | B10: B08WPW8T92 | C10: X0043V3IBL | D10: =VLOOKUP(A10,Data1!A:B,2,0) -> 1227 | E10: =L10*O10 -> 6 | F10: =O10 -> 6 | H10: 6 | I10: Labeling | J10: =VLOOKUP(A10,Instruction!A:F,7,0) -> #REF! | L10: =VLOOKUP(A10,Data1!A:C,3,0) -> 1 | O10: 6 | P10: =VLOOKUP(D10,[1]Sheet1!$B:$D,3,0) -> 4391
A11: 992-EACH | B11: B08R6JJP2L | C11: X0043V3CT9 | D11: =VLOOKUP(A11,Data1!A:B,2,0) -> 992 | E11: =L11*O11 -> 4 | F11: =O11 -> 4 | H11: 4 | I11: Labeling | J11: =VLOOKUP(A11,Instruction!A:F,7,0) -> #REF! | L11: =VLOOKUP(A11,Data1!A:C,3,0) -> 1 | O11: 4 | P11: =VLOOKUP(D11,[1]Sheet1!$B:$D,3,0) -> 3003
A12: 6041-EACH | B12: B072LP49MC | C12: B072LP49MC | D12: =VLOOKUP(A12,Data1!A:B,2,0) -> 6041 | E12: =L12*O12 -> 4 | F12: =O12 -> 4 | G12: 4 | J12: =VLOOKUP(A12,Instruction!A:F,7,0) -> #REF! | L12: =VLOOKUP(A12,Data1!A:C,3,0) -> 1 | O12: 4 | P12: =VLOOKUP(D12,[1]Sheet1!$B:$D,3,0) -> 4235
A13: 2561-EACH | B13: B09QD62R6R | C13: B09QD62R6R | D13: =VLOOKUP(A13,Data1!A:B,2,0) -> 2561 | E13: =L13*O13 -> 6 | F13: =O13 -> 6 | G13: 6 | J13: =VLOOKUP(A13,Instruction!A:F,7,0) -> #REF! | L13: =VLOOKUP(A13,Data1!A:C,3,0) -> 1 | O13: 6 | P13: =VLOOKUP(D13,[1]Sheet1!$B:$D,3,0) -> 30774
A14: 768-EACH | B14: B005KQ9316 | C14: B005KQ9316 | D14: =VLOOKUP(A14,Data1!A:B,2,0) -> 768 | E14: =L14*O14 -> 4 | F14: =O14 -> 4 | G14: 4 | J14: =VLOOKUP(A14,Instruction!A:F,7,0) -> #REF! | L14: =VLOOKUP(A14,Data1!A:C,3,0) -> 1 | O14: 4 | P14: =VLOOKUP(D14,[1]Sheet1!$B:$D,3,0) -> 22194
A15: 1277-EACH | B15: B0B9P3TD4K | C15: B0B9P3TD4K | D15: =VLOOKUP(A15,Data1!A:B,2,0) -> 1277 | E15: =L15*O15 -> 6 | F15: =O15 -> 6 | G15: 6 | J15: =VLOOKUP(A15,Instruction!A:F,7,0) -> #REF! | L15: =VLOOKUP(A15,Data1!A:C,3,0) -> 1 | O15: 6 | P15: =VLOOKUP(D15,[1]Sheet1!$B:$D,3,0) -> 10417
A16: 120-EACH | B16: B003BS9G44 | C16: B003BS9G44 | D16: =VLOOKUP(A16,Data1!A:B,2,0) -> 120 | E16: =L16*O16 -> 6 | F16: =O16 -> 6 | H16: 6 | J16: =VLOOKUP(A16,Instruction!A:F,7,0) -> #REF! | L16: =VLOOKUP(A16,Data1!A:C,3,0) -> 1 | O16: 6 | P16: =VLOOKUP(D16,[1]Sheet1!$B:$D,3,0) -> 22529
A17: 3301-EACH | B17: B0CPRBHWH9 | C17: B0CPRBHWH9 | D17: =VLOOKUP(A17,Data1!A:B,2,0) -> 3301 | E17: =L17*O17 -> 4 | F17: =O17 -> 4 | H17: 4 | J17: =VLOOKUP(A17,Instruction!A:F,7,0) -> #REF! | L17: =VLOOKUP(A17,Data1!A:C,3,0) -> 1 | O17: 4 | P17: =VLOOKUP(D17,[1]Sheet1!$B:$D,3,0) -> 281
A18: 715-EACH | B18: B07S6D1VMB | C18: B07S6D1VMB | D18: =VLOOKUP(A18,Data1!A:B,2,0) -> 715 | E18: =L18*O18 -> 3 | F18: =O18 -> 3 | H18: 3 | J18: =VLOOKUP(A18,Instruction!A:F,7,0) -> #REF! | L18: =VLOOKUP(A18,Data1!A:C,3,0) -> 1 | O18: 3 | P18: =VLOOKUP(D18,[1]Sheet1!$B:$D,3,0) -> 1789
A19: 3300-EACH | B19: B0CPRPLLFH | C19: B0CPRPLLFH | D19: =VLOOKUP(A19,Data1!A:B,2,0) -> 3300 | E19: =L19*O19 -> 4 | F19: =O19 -> 4 | H19: 4 | J19: =VLOOKUP(A19,Instruction!A:F,7,0) -> #REF! | L19: =VLOOKUP(A19,Data1!A:C,3,0) -> 1 | O19: 4 | P19: =VLOOKUP(D19,[1]Sheet1!$B:$D,3,0) -> 832

Sheet Bundles
B1: SKU | C1: Sellable Set to ship | D1: Item# | E1: Total EA (Transfer to WH07) | F1: Box | G1: Case | H1: Box Uom | I1: Case Uom | J1: Inventory
B2: 532-EA+533-EA+534-EA+535-EA | C2: 24 | D2: 532 | E2: =$C$2 -> 24 | F2: 1 | H2: =VLOOKUP(D2,[2]Data2!A:D,4,0) -> 24 | I2: =VLOOKUP(D2,[2]Data2!A:D,3,0) -> 72 | J2: =VLOOKUP(Table33[[#This Row],[Item'#]],[3]Sheet1!$B:$D,3,0) -> 14369
D3: 533 | E3: =$C$2 -> 24 | F3: 1 | H3: =VLOOKUP(D3,[2]Data2!A:D,4,0) -> 24 | I3: =VLOOKUP(D3,[2]Data2!A:D,3,0) -> 72 | J3: =VLOOKUP(Table33[[#This Row],[Item'#]],[3]Sheet1!$B:$D,3,0) -> 25958
D4: 534 | E4: =$C$2 -> 24 | F4: 1 | H4: =VLOOKUP(D4,[2]Data2!A:D,4,0) -> 24 | I4: =VLOOKUP(D4,[2]Data2!A:D,3,0) -> 72 | J4: =VLOOKUP(Table33[[#This Row],[Item'#]],[3]Sheet1!$B:$D,3,0) -> 35701
D5: 535 | E5: =$C$2 -> 24 | F5: 1 | H5: =VLOOKUP(D5,[2]Data2!A:D,4,0) -> 24 | I5: =VLOOKUP(D5,[2]Data2!A:D,3,0) -> 72 | J5: =VLOOKUP(Table33[[#This Row],[Item'#]],[3]Sheet1!$B:$D,3,0) -> 3669
B7: SKU | C7: Sellable Set to ship | D7: Item# | E7: Total EA (Transfer to WH07) | F7: Box | G7: Case | H7: Box Uom | I7: Case Uom | J7: Inventory
B8: 544-EA+548-EA+549-EA | C8: 24 | D8: 544 | E8: =$C$8 -> 24 | F8: 1 | H8: =VLOOKUP(D8,[2]Data2!A:D,4,0) -> 24 | I8: =VLOOKUP(D8,[2]Data2!A:D,3,0) -> 72 | J8: =VLOOKUP(Table415[[#This Row],[Item'#]],[3]Sheet1!$B:$D,3,0) -> 24437
D9: 548 | E9: =$C$8 -> 24 | F9: 1 | H9: =VLOOKUP(D9,[2]Data2!A:D,4,0) -> 24 | I9: =VLOOKUP(D9,[2]Data2!A:D,3,0) -> 72 | J9: =VLOOKUP(Table415[[#This Row],[Item'#]],[3]Sheet1!$B:$D,3,0) -> 26224
D10: 549 | E10: =$C$8 -> 24 | F10: 1 | H10: =VLOOKUP(D10,[2]Data2!A:D,4,0) -> 24 | I10: =VLOOKUP(D10,[2]Data2!A:D,3,0) -> 72 | J10: =VLOOKUP(Table415[[#This Row],[Item'#]],[3]Sheet1!$B:$D,3,0) -> 2697
B12: SKU | C12: Sellable Set to ship | D12: Item# | E12: Total EA (Transfer to WH07) | F12: Box | G12: Case | H12: Box Uom | I12: Case Uom | J12: Inventory
B13: 534-EA+535-EA | C13: 48 | D13: 534 | E13: 48 | F13: 2 | H13: =VLOOKUP(D13,[2]Data2!A:D,4,0) -> 24 | I13: =VLOOKUP(D13,[2]Data2!A:D,3,0) -> 72 | J13: =VLOOKUP(Table516[[#This Row],[Item'#]],[3]Sheet1!$B:$D,3,0) -> 35701
D14: 535 | E14: 48 | F14: 2 | H14: =VLOOKUP(D14,[2]Data2!A:D,4,0) -> 24 | I14: =VLOOKUP(D14,[2]Data2!A:D,3,0) -> 72 | J14: =VLOOKUP(Table516[[#This Row],[Item'#]],[3]Sheet1!$B:$D,3,0) -> 3669
B16: SKU | C16: Sellable Set to ship | D16: Item# | E16: Total EA (Transfer to WH07) | F16: Box | G16: Case | H16: Box Uom | I16: Case Uom | J16: Inventory
B17: 5600-EA+5601-EA+5602-EA | C17: 24 | D17: 5600 | E17: =$C$8 -> 24 | F17: 1 | H17: =VLOOKUP(D17,[2]Data2!A:D,4,0) -> #N/A | I17: =VLOOKUP(D17,[2]Data2!A:D,3,0) -> #N/A | J17: =VLOOKUP(Table4159[[#This Row],[Item'#]],[3]Sheet1!$B:$D,3,0) -> 8088
D18: 5601 | E18: =$C$8 -> 24 | F18: 1 | H18: =VLOOKUP(D18,[2]Data2!A:D,4,0) -> #N/A | I18: =VLOOKUP(D18,[2]Data2!A:D,3,0) -> #N/A | J18: =VLOOKUP(Table4159[[#This Row],[Item'#]],[3]Sheet1!$B:$D,3,0) -> 6773
D19: 5602 | E19: =$C$8 -> 24 | F19: 1 | H19: =VLOOKUP(D19,[2]Data2!A:D,4,0) -> #N/A | I19: =VLOOKUP(D19,[2]Data2!A:D,3,0) -> #N/A | J19: =VLOOKUP(Table4159[[#This Row],[Item'#]],[3]Sheet1!$B:$D,3,0) -> 7538
B21: SKU | C21: Sellable Set to ship | D21: Item# | E21: Total EA (Transfer to WH07) | F21: Box | G21: Case | H21: Box Uom | I21: Case Uom | J21: Inventory
B22: 6018-EA+1201-EA | C22: 24 | D22: 6018 | E22: 24 | F22: 1 | H22: =VLOOKUP(D22,[2]Data2!A:D,4,0) -> #REF! | I22: =VLOOKUP(D22,[2]Data2!A:D,3,0) -> 24 | J22: =VLOOKUP(Table5165[[#This Row],[Item'#]],[3]Sheet1!$B:$D,3,0) -> 14836
D23: 1201 | E23: 24 | F23: 1 | H23: =VLOOKUP(D23,[2]Data2!A:D,4,0) -> 24 | I23: =VLOOKUP(D23,[2]Data2!A:D,3,0) -> 144 | J23: =VLOOKUP(Table5165[[#This Row],[Item'#]],[3]Sheet1!$B:$D,3,0) -> 65392
B25: SKU | C25: Sellable Set to ship | D25: Item# | E25: Total EA (Transfer to WH07) | F25: Box | G25: Case | H25: Box Uom | I25: Case Uom | J25: Inventory
B26: 4575936-SET2+765-EA+3860-EA | C26: 36 | D26: 4575936 | E26: 72 | G26: 2 | H26: =VLOOKUP(D26,[2]Data2!A:D,4,0) -> #REF! | I26: =VLOOKUP(D26,[2]Data2!A:D,3,0) -> 36 | J26: =VLOOKUP(Table617[[#This Row],[Item'#]],[3]Sheet1!$B:$D,3,0) -> 3475
D27: 765 | E27: 36 | F27: 1.5 | H27: =VLOOKUP(D27,[2]Data2!A:D,4,0) -> 24 | I27: =VLOOKUP(D27,[2]Data2!A:D,3,0) -> 144 | J27: =VLOOKUP(Table617[[#This Row],[Item'#]],[3]Sheet1!$B:$D,3,0) -> 218604
D28: 3860 | E28: 36 | G28: 1.5 | H28: =VLOOKUP(D28,[2]Data2!A:D,4,0) -> #REF! | I28: =VLOOKUP(D28,[2]Data2!A:D,3,0) -> 24 | J28: =VLOOKUP(Table617[[#This Row],[Item'#]],[3]Sheet1!$B:$D,3,0) -> 1204
B30: SKU | C30: Sellable Set to ship | D30: Item# | E30: Total EA (Transfer to WH07) | F30: Box | G30: Case | H30: Box Uom | I30: Case Uom | J30: Inventory
B31: 4577036-SET2+4881536-EA+765-EA+3863-EA | C31: 36 | D31: 4577036 | E31: 72 | G31: 2 | H31: =VLOOKUP(D31,[2]Data2!A:D,4,0) -> #REF! | I31: =VLOOKUP(D31,[2]Data2!A:D,3,0) -> 36 | J31: =VLOOKUP(Table6176[[#This Row],[Item'#]],[3]Sheet1!$B:$D,3,0) -> 2
D32: 4881536 | E32: 36 | G32: 1 | H32: =VLOOKUP(D32,[2]Data2!A:D,4,0) -> #REF! | I32: =VLOOKUP(D32,[2]Data2!A:D,3,0) -> 36 | J32: =VLOOKUP(Table6176[[#This Row],[Item'#]],[3]Sheet1!$B:$D,3,0) -> 9
D33: 3863 | E33: 36 | F33: 1.5 | H33: =VLOOKUP(D33,[2]Data2!A:D,4,0) -> #REF! | I33: =VLOOKUP(D33,[2]Data2!A:D,3,0) -> 24 | J33: =VLOOKUP(Table6176[[#This Row],[Item'#]],[3]Sheet1!$B:$D,3,0) -> 1450
D34: 765 | E34: 36 | F34: 1.5 | H34: =VLOOKUP(D34,[2]Data2!A:D,4,0) -> 24 | I34: =VLOOKUP(D34,[2]Data2!A:D,3,0) -> 144 | J34: =VLOOKUP(Table6176[[#This Row],[Item'#]],[3]Sheet1!$B:$D,3,0) -> 218604
B36: SKU | C36: Sellable Set to ship | D36: Item# | E36: Total EA (Transfer to WH07) | F36: Box | G36: Case | H36: Box Uom | I36: Case Uom | J36: Inventory
B37: 4569945741-SET2+2520-EA | C37: 72 | D37: 4569945741 | E37: 144 | G37: 4 | H37: =VLOOKUP(D37,[2]Data2!A:D,4,0) -> #N/A | I37: =VLOOKUP(D37,[2]Data2!A:D,3,0) -> #N/A | J37: =VLOOKUP(Table61767[[#This Row],[Item'#]],[3]Sheet1!$B:$D,3,0) -> 420 | K37: On Create Inbound Order template use this SKU:
D38: 2520 | E38: 72 | G38: 1 | H38: =VLOOKUP(D38,[2]Data2!A:D,4,0) -> 24 | I38: =VLOOKUP(D38,[2]Data2!A:D,3,0) -> 72 | J38: =VLOOKUP(Table61767[[#This Row],[Item'#]],[3]Sheet1!$B:$D,3,0) -> 16383 | K38: 4576336-SET2+2520-EA
B40: SKU | C40: Sellable Set to ship | D40: Item# | E40: Total EA (Transfer to WH07) | F40: Box | G40: Case | H40: Box Uom | I40: Case Uom | J40: Inventory
B41: 60756-SET2+1224-EA | C41: 36 | D41: 60756 | E41: 72 | G41: 2 | H41: =VLOOKUP(D41,[2]Data2!A:D,4,0) -> #REF! | I41: =VLOOKUP(D41,[2]Data2!A:D,3,0) -> 36 | J41: =VLOOKUP(Table718[[#This Row],[Item'#]],[3]Sheet1!$B:$D,3,0) -> 2022
D42: 1224 | E42: 36 | F42: 1 | H42: =VLOOKUP(D42,[2]Data2!A:D,4,0) -> 24 | I42: =VLOOKUP(D42,[2]Data2!A:D,3,0) -> 144 | J42: =VLOOKUP(Table718[[#This Row],[Item'#]],[3]Sheet1!$B:$D,3,0) -> 68267
B44: SKU | C44: Sellable Set to ship | D44: Item# | E44: Total EA (Transfer to WH07) | F44: Box | G44: Case | H44: Box Uom | I44: Case Uom | J44: Inventory
B45: 49923-EA+734-SET2+2520-EA | C45: 36 | D45: 49923 | E45: 36 | G45: 1 | H45: =VLOOKUP(D45,[2]Data2!A:D,4,0) -> #REF! | I45: =VLOOKUP(D45,[2]Data2!A:D,3,0) -> 36 | J45: =VLOOKUP(Table1223[[#This Row],[Item'#]],[3]Sheet1!$B:$D,3,0) -> 168
D46: 734 | E46: 72 | G46: 2 | H46: =VLOOKUP(D46,[2]Data2!A:D,4,0) -> #REF! | I46: =VLOOKUP(D46,[2]Data2!A:D,3,0) -> 48 | J46: =VLOOKUP(Table1223[[#This Row],[Item'#]],[3]Sheet1!$B:$D,3,0) -> #N/A
D47: 2520 | E47: 36 | F47: 1.5 | H47: =VLOOKUP(D47,[2]Data2!A:D,4,0) -> 24 | I47: =VLOOKUP(D47,[2]Data2!A:D,3,0) -> 72 | J47: =VLOOKUP(Table1223[[#This Row],[Item'#]],[3]Sheet1!$B:$D,3,0) -> 16383
B49: SKU | C49: Sellable Set to ship | D49: Item# | E49: Total EA (Transfer to WH07) | F49: Box | G49: Case | H49: Box Uom | I49: Case Uom | J49: Inventory
B50: 4577036-EA+4881536-EA+765-EA+3863-EA | C50: 36 | D50: 4577036 | E50: 36 | G50: 1 | H50: =VLOOKUP(D50,[2]Data2!A:D,4,0) -> #REF! | I50: =VLOOKUP(D50,[2]Data2!A:D,3,0) -> 36 | J50: =VLOOKUP(Table1122[[#This Row],[Item'#]],[3]Sheet1!$B:$D,3,0) -> 2
...

Sheet AWD
A1: SKU | B1: ASIN | C1: FNSKU | D1: Item # | E1: Total EA (Transfer to WH06) | F1: Sellable Unit/Set/box to ship | G1: Box to pull | H1: Case to pull | I1: Sets per Box/Case | J1: Label | K1: Packing Instructions | L1: AWD Special | M1: Supplies | N1: UoM | O1: BOX | P1: CASE | Q1: Recommended Replenishment Qty | R1: Current WH Inventory
A2: 4147-EACH | B2: B07Q8SQSQF | C2: X003SBSJBL | D2: =VLOOKUP(Table13[[#This Row],[SKU]],Data1!A:B,2,0) -> 4147 | E2: =Table13[[#This Row],[UoM]]*Table13[[#This Row],[Recommended Replenishment Qty]] -> 156 | F2: =Table13[[#This Row],[Total EA (Transfer to WH06)]]/Table13[[#This Row],[UoM]] -> 156 | H2: =Table13[[#This Row],[Total EA (Transfer to WH06)]]/Table13[[#This Row],[CASE]] -> 13 | I2: =Table13[[#This Row],[Sellable Unit/Set/box to ship]]/Table13[[#This Row],[Case to pull]] -> 12 | J2: =IF(ISNUMBER(SEARCH("FNSKU",K2)),"Labeling","") -> Labeling | K2: =VLOOKUP(Table13[[#This Row],[SKU]],Instruction!A:F,6,0) -> • Use FNSKU to label each item (cover barcode). Apply outer box/case label accordingly to match item# (Cover all existing barcodes on the box/case) | L2: =VLOOKUP(Table13[[#This Row],[SKU]],Instruction!A:G,7,0) -> 0 | M2: =VLOOKUP(Table13[[#This Row],[ASIN]],'[4]2024'!$A:$AB,28,0) -> No Supplies | N2: =VLOOKUP(Table13[[#This Row],[SKU]],Data1!A:C,3,0) -> 1 | O2: =VLOOKUP(Table13[[#This Row],[Item '#]],Data2!A:D,4,0) -> 0 | P2: =VLOOKUP(Table13[[#This Row],[Item '#]],Data2!A:D,3,0) -> 12 | Q2: 156 | R2: =VLOOKUP(Table13[[#This Row],[Item '#]],[3]Sheet1!$B:$D,3,0) -> 5414
A3: 2306-EACH-1 | B3: B008ZHNN68 | C3: B008ZHNN68 | D3: =VLOOKUP(Table13[[#This Row],[SKU]],Data1!A:B,2,0) -> 2306 | E3: =Table13[[#This Row],[UoM]]*Table13[[#This Row],[Recommended Replenishment Qty]] -> 1440 | F3: =Table13[[#This Row],[Total EA (Transfer to WH06)]]/Table13[[#This Row],[UoM]] -> 1440 | H3: =Table13[[#This Row],[Total EA (Transfer to WH06)]]/Table13[[#This Row],[CASE]] -> 10 | I3: =Table13[[#This Row],[Sellable Unit/Set/box to ship]]/Table13[[#This Row],[Case to pull]] -> 144 | J3: =IF(ISNUMBER(SEARCH("FNSKU",K3)),"Labeling","") | K3: =VLOOKUP(Table13[[#This Row],[SKU]],Instruction!A:F,6,0) -> Cover inner box barcode. Apply outer case label accordingly to match item# (Cover barcodes on the case) | L3: =VLOOKUP(Table13[[#This Row],[SKU]],Instruction!A:G,7,0) -> 0 | M3: =VLOOKUP(Table13[[#This Row],[ASIN]],'[4]2024'!$A:$AB,28,0) -> No Supplies | N3: =VLOOKUP(Table13[[#This Row],[SKU]],Data1!A:C,3,0) -> 1 | O3: =VLOOKUP(Table13[[#This Row],[Item '#]],Data2!A:D,4,0) -> 24 | P3: =VLOOKUP(Table13[[#This Row],[Item '#]],Data2!A:D,3,0) -> 144 | Q3: 1440 | R3: =VLOOKUP(Table13[[#This Row],[Item '#]],[3]Sheet1!$B:$D,3,0) -> 10791
A4: 6810-EACH | B4: B09DK3BKGB | C4: B09DK3BKGB | D4: =VLOOKUP(Table13[[#This Row],[SKU]],Data1!A:B,2,0) -> 6810 | E4: =Table13[[#This Row],[UoM]]*Table13[[#This Row],[Recommended Replenishment Qty]] -> 144 | F4: =Table13[[#This Row],[Total EA (Transfer to WH06)]]/Table13[[#This Row],[UoM]] -> 144 | H4: =Table13[[#This Row],[Total EA (Transfer to WH06)]]/Table13[[#This Row],[CASE]] -> 1 | I4: =Table13[[#This Row],[Sellable Unit/Set/box to ship]]/Table13[[#This Row],[Case to pull]] -> 144 | J4: =IF(ISNUMBER(SEARCH("FNSKU",K4)),"Labeling","") | K4: =VLOOKUP(Table13[[#This Row],[SKU]],Instruction!A:F,6,0) -> Apply outer box/case label accordingly to match item# (Cover all existing barcodes on the box/case) | L4: =VLOOKUP(Table13[[#This Row],[SKU]],Instruction!A:G,7,0) -> 0 | M4: =VLOOKUP(Table13[[#This Row],[ASIN]],'[4]2024'!$A:$AB,28,0) -> No Supplies | N4: =VLOOKUP(Table13[[#This Row],[SKU]],Data1!A:C,3,0) -> 1 | O4: =VLOOKUP(Table13[[#This Row],[Item '#]],Data2!A:D,4,0) -> 24 | P4: =VLOOKUP(Table13[[#This Row],[Item '#]],Data2!A:D,3,0) -> 144 | Q4: 144 | R4: =VLOOKUP(Table13[[#This Row],[Item '#]],[3]Sheet1!$B:$D,3,0) -> 21276
A5: 5027-EACH-1 | B5: B00KO8DHVC | C5: X004HP06TF | D5: =VLOOKUP(Table13[[#This Row],[SKU]],Data1!A:B,2,0) -> 5027 | E5: =Table13[[#This Row],[UoM]]*Table13[[#This Row],[Recommended Replenishment Qty]] -> 480 | F5: =Table13[[#This Row],[Total EA (Transfer to WH06)]]/Table13[[#This Row],[UoM]] -> 480 | H5: =Table13[[#This Row],[Total EA (Transfer to WH06)]]/Table13[[#This Row],[CASE]] -> 10 | I5: =Table13[[#This Row],[Sellable Unit/Set/box to ship]]/Table13[[#This Row],[Case to pull]] -> 48 | J5: =IF(ISNUMBER(SEARCH("FNSKU",K5)),"Labeling","") -> Labeling | K5: =VLOOKUP(Table13[[#This Row],[SKU]],Instruction!A:F,6,0) -> • Use FNSKU to label each item (cover barcode). Apply outer case label accordingly to match item# (Cover all existing barcodes on the case) | L5: =VLOOKUP(Table13[[#This Row],[SKU]],Instruction!A:G,7,0) -> 0 | M5: =VLOOKUP(Table13[[#This Row],[ASIN]],'[4]2024'!$A:$AB,28,0) -> No Supplies | N5: =VLOOKUP(Table13[[#This Row],[SKU]],Data1!A:C,3,0) -> 1 | O5: =VLOOKUP(Table13[[#This Row],[Item '#]],Data2!A:D,4,0) -> 0 | P5: =VLOOKUP(Table13[[#This Row],[Item '#]],Data2!A:D,3,0) -> 48 | Q5: 480 | R5: =VLOOKUP(Table13[[#This Row],[Item '#]],[3]Sheet1!$B:$D,3,0) -> 4137
A6: 2205-EACH | B6: B003BNZVHK | C6: B003BNZVHK | D6: =VLOOKUP(Table13[[#This Row],[SKU]],Data1!A:B,2,0) -> 2205 | E6: =Table13[[#This Row],[UoM]]*Table13[[#This Row],[Recommended Replenishment Qty]] -> 216 | F6: =Table13[[#This Row],[Total EA (Transfer to WH06)]]/Table13[[#This Row],[UoM]] -> 216 | H6: =Table13[[#This Row],[Total EA (Transfer to WH06)]]/Table13[[#This Row],[CASE]] -> 3 | I6: =Table13[[#This Row],[Sellable Unit/Set/box to ship]]/Table13[[#This Row],[Case to pull]] -> 72 | J6: =IF(ISNUMBER(SEARCH("FNSKU",K6)),"Labeling","") | K6: =VLOOKUP(Table13[[#This Row],[SKU]],Instruction!A:F,6,0) -> Apply outer box/case label accordingly to match item# (Cover all existing barcodes on the box/case) | L6: =VLOOKUP(Table13[[#This Row],[SKU]],Instruction!A:G,7,0) -> 0 | M6: =VLOOKUP(Table13[[#This Row],[ASIN]],'[4]2024'!$A:$AB,28,0) -> No Supplies | N6: =VLOOKUP(Table13[[#This Row],[SKU]],Data1!A:C,3,0) -> 1 | O6: =VLOOKUP(Table13[[#This Row],[Item '#]],Data2!A:D,4,0) -> 24 | P6: =VLOOKUP(Table13[[#This Row],[Item '#]],Data2!A:D,3,0) -> 72 | Q6: 216 | R6: =VLOOKUP(Table13[[#This Row],[Item '#]],[3]Sheet1!$B:$D,3,0) -> 15609
